Workbook

Sheet 요약
A1: 2027 TNH 사업계획 — 요약 (입력·결과 한 장)
A2: 노란 칸(파란 글씨) = 입력값. 여기서 바꾸면 모든 시트가 자동 재계산됩니다. 단위: 억원. 2026 예상 = 실적(RAW_판매펀칭 1/1~기준일) + 잔여 예측.
A3: ="2027 TNH 매출 "&TEXT(사업계획!N11,"0.0")&"억 (2026 예상 "&TEXT(사업계획!N20,"0.0")&"억 대비 "&TEXT(사업계획!N38,"+0.0%;-0.0%")&") · 이익 "&TEXT(사업계획!N83,"0.0")&"억 · 이익률 "&TEXT(사업계획!N119,"0.0%")&" (2026 예상 "&TEXT(사업계획!N128,"0.0%")&")" -> 2027 TNH 매출 173.1억 (2026 예상 199.8억 대비 -13.3%) · 이익 31.7억 · 이익률 18.3% (2026 예상 29.3%)
A4: =사업계획!A3
A6: ① 2027 계획 — 법인 목표·정판율·할인율 입력 → TNH 매출·이익
A7: 구분 | B7: 법인 매출목표 | C7: 정판율 | D7: 할인율 | E7: 정상제품 매출 | F7: 택가 기준 공급액 | G7: TNH 공급가÷택가 | H7: 2027 TNH 매출 | I7: 2027 TNH 원가 | J7: 2027 TNH 이익 | K7: 이익률
A8: 홍콩 | B8: 150 | C8: 0.6 | D8: 0 | E8: =가정!C11 -> 60 | F8: =가정!F11 -> 100 | G8: =가정!G11 -> 0.33 | H8: =가정!H11 -> 33 | I8: =가정!I11 -> 25 | J8: =가정!J11 -> 8 | K8: =가정!K11 -> 0.24242424
A9: 중국 | B9: 300 | C9: 0.6 | D9: 0 | E9: =가정!C12 -> 120 | F9: =가정!F12 -> 200 | G9: =가정!G12 -> 0.2625 | H9: =가정!H12 -> 52.5 | I9: =가정!I12 -> 50 | J9: =가정!J12 -> 2.5 | K9: =가정!K12 -> 0.047619048
A10: 대만 | B10: 262 | C10: 0.6 | D10: 0 | E10: =가정!C13 -> 104.8 | F10: =가정!F13 -> 174.66667 | G10: =가정!G13 -> 0.33 | H10: =가정!H13 -> 57.64 | I10: =가정!I13 -> 43.666667 | J10: =가정!J13 -> 13.973333 | K10: =가정!K13 -> 0.24242424
A11: 법인 소계 | B11: =가정!B14 -> 712 | E11: =가정!C14 -> 284.8 | F11: =가정!F14 -> 474.66667 | G11: =가정!G14 -> 0.30155899 | H11: =가정!H14 -> 143.14 | I11: =가정!I14 -> 118.66667 | J11: =가정!J14 -> 24.473333 | K11: =가정!K14 -> 0.1709748
A12: 홀세일 (TNH 매출 입력) | B12: - | C12: - | D12: - | E12: - | F12: =가정!F15 -> 90.909091 | G12: =가정!G15 -> 0.33 | H12: 30 | I12: =가정!I15 -> 22.727273 | J12: =가정!J15 -> 7.2727273 | K12: =가정!K15 -> 0.24242424
A13: TNH 합계 | B13: - | C13: - | D13: - | E13: - | F13: =가정!F16 -> 565.57576 | G13: - | H13: =가정!H16 -> 173.14 | I13: =가정!I16 -> 141.39394 | J13: =가정!J16 -> 31.746061 | K13: =가정!K16 -> 0.18335486
A15: ② 공통 가정 (입력)
A16: 공통 가정 | B16: 이월제품 비중 | C16: 정상제품 비중 (자동=1−이월) | D16: 공급율 (HK·TW·홀세일) | E16: 택가 배수 | F16: 중국 공급 마진 | G16: 환율 (KRW/USD) | H16: 실적 기준일 | I16: 예측 방식 (1=실적 진도율, 2=ERP 수주) | J16: 환산배수 경고 허용폭
A17: 입력값 | B17: 0.6 | C17: =가정!B8 -> 0.4 | D17: 0.33 | E17: 4 | F17: 0.05 | G17: 1362.78 | H17: 46317 | I17: 1 | J17: 0.3
A19: ③ 2026 예상(실적 + 예측) vs 2027 계획
A20: 구분 | B20: ="2026 실적(1/1~"&TEXT(H17,"m/d")&")" -> 2026 실적(1/1~10/22) | C20: 잔여 예측 | D20: 2026 예상 | E20: 진도율 | F20: 2027 계획 | G20: 증감 | H20: 증감률 | I20: 2026 이익 | J20: 2027 이익 | K20: 2026 이익률 | L20: 2027 이익률 | M20: 이익률 증감(%p)
A21: 홍콩 | B21: =가정!C38 -> 36.889672 | C21: =D21-B21 -> 12.765261 | D21: =사업계획!N15 -> 49.654933 | E21: =가정!D38 -> 0.74292059 | F21: =사업계획!N6 -> 33 | G21: =F21-D21 -> -16.654933 | H21: =IF(D21=0,0,G21/D21) -> -0.33541346 | I21: =사업계획!N87 -> 16.968114 | J21: =사업계획!N78 -> 8 | K21: =사업계획!N123 -> 0.34172062 | L21: =사업계획!N114 -> 0.24242424 | M21: =사업계획!N132 -> -0.099296379
A22: 중국 | B22: =가정!C39 -> 36.112696 | C22: =D22-B22 -> 13.146829 | D22: =사업계획!N16 -> 49.259526 | E22: =가정!D39 -> 0.73311093 | F22: =사업계획!N7 -> 52.5 | G22: =F22-D22 -> 3.2404744 | H22: =IF(D22=0,0,G22/D22) -> 0.06578371 | I22: =사업계획!N88 -> 6.7317451 | J22: =사업계획!N79 -> 2.5 | K22: =사업계획!N124 -> 0.13665875 | L22: =사업계획!N115 -> 0.047619048 | M22: =사업계획!N133 -> -0.089039701
A23: 대만 | B23: =가정!C40 -> 47.294365 | C23: =D23-B23 -> 16.422382 | D23: =사업계획!N17 -> 63.716747 | E23: =가정!D40 -> 0.74225957 | F23: =사업계획!N8 -> 57.64 | G23: =F23-D23 -> -6.0767472 | H23: =IF(D23=0,0,G23/D23) -> -0.095371271 | I23: =사업계획!N89 -> 20.933915 | J23: =사업계획!N80 -> 13.973333 | K23: =사업계획!N125 -> 0.32854651 | L23: =사업계획!N116 -> 0.24242424 | M23: =사업계획!N134 -> -0.086122263
A24: 법인 소계 | B24: =SUM(B21:B23) -> 120.29673 | C24: =D24-B24 -> 42.334472 | D24: =사업계획!N18 -> 162.63121 | E24: =IF(D24=0,0,B24/D24) -> 0.73969035 | F24: =사업계획!N9 -> 143.14 | G24: =F24-D24 -> -19.491206 | H24: =IF(D24=0,0,G24/D24) -> -0.11984911 | I24: =사업계획!N90 -> 44.633774 | J24: =사업계획!N81 -> 24.473333 | K24: =사업계획!N126 -> 0.27444779 | L24: =사업계획!N117 -> 0.1709748 | M24: =사업계획!N135 -> -0.10347298
A25: 홀세일 | B25: =가정!C41 -> 27.51653 | C25: =D25-B25 -> 9.6346248 | D25: =사업계획!N19 -> 37.151155 | E25: =가정!D41 -> 0.74066419 | F25: =사업계획!N10 -> 30 | G25: =F25-D25 -> -7.1511546 | H25: =IF(D25=0,0,G25/D25) -> -0.19248808 | I25: =사업계획!N91 -> 13.825083 | J25: =사업계획!N82 -> 7.2727273 | K25: =사업계획!N127 -> 0.37213063 | L25: =사업계획!N118 -> 0.24242424 | M25: =사업계획!N136 -> -0.12970639
A26: TNH 합계 | B26: =B24+B25 -> 147.81326 | C26: =D26-B26 -> 51.969097 | D26: =사업계획!N20 -> 199.78236 | E26: =IF(D26=0,0,B26/D26) -> 0.73987145 | F26: =사업계획!N11 -> 173.14 | G26: =F26-D26 -> -26.64236 | H26: =IF(D26=0,0,G26/D26) -> -0.13335692 | I26: =사업계획!N92 -> 58.458857 | J26: =사업계획!N83 -> 31.746061 | K26: =사업계획!N128 -> 0.29261271 | L26: =사업계획!N119 -> 0.18335486 | M26: =사업계획!N137 -> -0.10925784
A28: ④ 2027 월별 비중 (입력) — 각 행 합계 100%
A29: 구분 | B29: 1월 | C29: 2월 | D29: 3월 | E29: 4월 | F29: 5월 | G29: 6월 | H29: 7월 | I29: 8월 | J29: 9월 | K29: 10월 | L29: 11월 | M29: 12월 | N29: 합계
A30: 홍콩 | B30: 0.144 | C30: 0.113 | D30: 0.07 | E30: 0.063 | F30: 0.065 | G30: 0.074 | H30: 0.055 | I30: 0.059 | J30: 0.046 | K30: 0.076 | L30: 0.109 | M30: 0.126 | N30: =SUM(B30:M30) -> 1
A31: 중국 | B31: 0.142 | C31: 0.081 | D31: 0.046 | E31: 0.053 | F31: 0.071 | G31: 0.065 | H31: 0.055 | I31: 0.063 | J31: 0.066 | K31: 0.129 | L31: 0.099 | M31: 0.13 | N31: =SUM(B31:M31) -> 1
A32: 대만 | B32: 0.129 | C32: 0.112 | D32: 0.06 | E32: 0.076 | F32: 0.078 | G32: 0.062 | H32: 0.05 | I32: 0.053 | J32: 0.064 | K32: 0.081 | L32: 0.126 | M32: 0.109 | N32: =SUM(B32:M32) -> 1
A33: 홀세일 (3법인 합계 비중 적용) | B33: 0.137 | C33: 0.106 | D33: 0.061 | E33: 0.067 | F33: 0.072 | G33: 0.066 | H33: 0.053 | I33: 0.057 | J33: 0.059 | K33: 0.089 | L33: 0.115 | M33: 0.118 | N33: =SUM(B33:M33) -> 1
A35: ⑤ 월별 TNH 매출 — 2026 예상 vs 2027 계획
A36: 구분 | B36: 1월 | C36: 2월 | D36: 3월 | E36: 4월 | F36: 5월 | G36: 6월 | H36: 7월 | I36: 8월 | J36: 9월 | K36: 10월 | L36: 11월 | M36: 12월 | N36: 합계
A37: 2026 예상 | B37: =사업계획!B20 -> 27.485085 | C37: =사업계획!C20 -> 20.702119 | D37: =사업계획!D20 -> 11.849187 | E37: =사업계획!E20 -> 13.056872 | F37: =사업계획!F20 -> 14.346368 | G37: =사업계획!G20 -> 13.302527 | H37: =사업계획!H20 -> 10.625757 | I37: =사업계획!I20 -> 11.483161 | ... N37: =사업계획!N20 -> 199.78236
A38: 2027 계획 | B38: =사업계획!B11 -> 23.75256 | C38: =사업계획!C11 -> 17.61718 | D38: =사업계획!D11 -> 10.0134 | E38: =사업계획!E11 -> 11.25214 | F38: =사업계획!F11 -> 12.52842 | G38: =사업계획!G11 -> 11.40818 | H38: =사업계획!H11 -> 9.1745 | I38: =사업계획!I11 -> 10.01942 | ... N38: =사업계획!N11 -> 173.14
A39: 증감 | B39: =사업계획!B29 -> -3.7325249 | C39: =사업계획!C29 -> -3.0849393 | D39: =사업계획!D29 -> -1.8357867 | E39: =사업계획!E29 -> -1.8047323 | F39: =사업계획!F29 -> -1.8179481 | G39: =사업계획!G29 -> -1.8943471 | H39: =사업계획!H29 -> -1.4512569 | I39: =사업계획!I29 -> -1.4637406 | ... N39: =사업계획!N29 -> -26.64236
A40: 증감률 | B40: =사업계획!B38 -> -0.13580183 | C40: =사업계획!C38 -> -0.14901563 | D40: =사업계획!D38 -> -0.15492934 | E40: =사업계획!E38 -> -0.13822087 | F40: =사업계획!F38 -> -0.12671835 | G40: =사업계획!G38 -> -0.14240506 | H40: =사업계획!H38 -> -0.13657915 | I40: =사업계획!I38 -> -0.12746845 | ... N40: =사업계획!N38 -> -0.13335692
A56: ⑥ 자동 점검
A57: 점검 항목 | B57: 결과
A58: 2027 월별 비중 합계 100% | B58: =IF(MAX(ABS(N30-1),ABS(N31-1),ABS(N32-1),ABS(N33-1))>0.0005,"⚠ 확인 필요","정상") -> 정상
A59: 월 합계 = 연간 값 (2027) | B59: =IF(ABS(사업계획!N11-H13)<0.001,"정상","⚠ 불일치") -> 정상
A61: 2026 환산배수 점검 | B61: 2026 실적 | C61: 2027 설정 | D61: 괴리 | E61: 판정
...

Sheet 사업계획
A1: 2027 TNH(수출자) 사업계획 — 월별 매출·원가·이익 (2026 예상 대비)
A2: 단위: 억원. 월 배분 = 2026 법인 월 매출 비중. 수식은 가정/월별비중/RAW_2026 시트와 연결. 홀세일은 3법인 합계 비중 적용.
A3: =IF(MAX(ABS(월별비중!N24-1),ABS(월별비중!N25-1),ABS(월별비중!N26-1),ABS(월별비중!N27-1))>0.0005,"⚠ 요약 시트 ④(2027 월별 비중) 합계가 100%가 아닙니다 — 월 합계가 연간 값과 달라집니다","")
A4: ■ 2027 계획 — 매출
A5: 구분 | B5: 1월 | C5: 2월 | D5: 3월 | E5: 4월 | F5: 5월 | G5: 6월 | H5: 7월 | I5: 8월 | J5: 9월 | K5: 10월 | L5: 11월 | M5: 12월 | N5: 합계
A6: 홍콩 | B6: =가정!$H$11*월별비중!B$24 -> 4.752 | C6: =가정!$H$11*월별비중!C$24 -> 3.729 | D6: =가정!$H$11*월별비중!D$24 -> 2.31 | E6: =가정!$H$11*월별비중!E$24 -> 2.079 | F6: =가정!$H$11*월별비중!F$24 -> 2.145 | G6: =가정!$H$11*월별비중!G$24 -> 2.442 | H6: =가정!$H$11*월별비중!H$24 -> 1.815 | I6: =가정!$H$11*월별비중!I$24 -> 1.947 | ... M6: =가정!$H$11*월별비중!M$24 -> 4.158 | N6: =SUM(B6:M6) -> 33
A7: 중국 | B7: =가정!$H$12*월별비중!B$25 -> 7.455 | C7: =가정!$H$12*월별비중!C$25 -> 4.2525 | D7: =가정!$H$12*월별비중!D$25 -> 2.415 | E7: =가정!$H$12*월별비중!E$25 -> 2.7825 | F7: =가정!$H$12*월별비중!F$25 -> 3.7275 | G7: =가정!$H$12*월별비중!G$25 -> 3.4125 | H7: =가정!$H$12*월별비중!H$25 -> 2.8875 | I7: =가정!$H$12*월별비중!I$25 -> 3.3075 | ... M7: =가정!$H$12*월별비중!M$25 -> 6.825 | N7: =SUM(B7:M7) -> 52.5
A8: 대만 | B8: =가정!$H$13*월별비중!B$26 -> 7.43556 | C8: =가정!$H$13*월별비중!C$26 -> 6.45568 | D8: =가정!$H$13*월별비중!D$26 -> 3.4584 | E8: =가정!$H$13*월별비중!E$26 -> 4.38064 | F8: =가정!$H$13*월별비중!F$26 -> 4.49592 | G8: =가정!$H$13*월별비중!G$26 -> 3.57368 | H8: =가정!$H$13*월별비중!H$26 -> 2.882 | I8: =가정!$H$13*월별비중!I$26 -> 3.05492 | ... M8: =가정!$H$13*월별비중!M$26 -> 6.28276 | N8: =SUM(B8:M8) -> 57.64
A9: 법인 소계 | B9: =SUM(B6:B8) -> 19.64256 | C9: =SUM(C6:C8) -> 14.43718 | D9: =SUM(D6:D8) -> 8.1834 | E9: =SUM(E6:E8) -> 9.24214 | F9: =SUM(F6:F8) -> 10.36842 | G9: =SUM(G6:G8) -> 9.42818 | H9: =SUM(H6:H8) -> 7.5845 | I9: =SUM(I6:I8) -> 8.30942 | ... M9: =SUM(M6:M8) -> 17.26576 | N9: =SUM(B9:M9) -> 143.14
A10: 홀세일 | B10: =가정!$H$15*월별비중!B$27 -> 4.11 | C10: =가정!$H$15*월별비중!C$27 -> 3.18 | D10: =가정!$H$15*월별비중!D$27 -> 1.83 | E10: =가정!$H$15*월별비중!E$27 -> 2.01 | F10: =가정!$H$15*월별비중!F$27 -> 2.16 | G10: =가정!$H$15*월별비중!G$27 -> 1.98 | H10: =가정!$H$15*월별비중!H$27 -> 1.59 | I10: =가정!$H$15*월별비중!I$27 -> 1.71 | ... M10: =가정!$H$15*월별비중!M$27 -> 3.54 | N10: =SUM(B10:M10) -> 30
A11: TNH 합계 | B11: =B9+B10 -> 23.75256 | C11: =C9+C10 -> 17.61718 | D11: =D9+D10 -> 10.0134 | E11: =E9+E10 -> 11.25214 | F11: =F9+F10 -> 12.52842 | G11: =G9+G10 -> 11.40818 | H11: =H9+H10 -> 9.1745 | I11: =I9+I10 -> 10.01942 | ... M11: =M9+M10 -> 20.80576 | N11: =SUM(B11:M11) -> 173.14
A13: ■ 2026 예상 — 매출
A14: 구분 | B14: 1월 | C14: 2월 | D14: 3월 | E14: 4월 | F14: 5월 | G14: 6월 | H14: 7월 | I14: 8월 | J14: 9월 | K14: 10월 | L14: 11월 | M14: 12월 | N14: 합계
A15: 홍콩 | B15: =가정!$D$21*월별비중!B$17 -> 7.1056029 | C15: =가정!$D$21*월별비중!C$17 -> 5.6177658 | D15: =가정!$D$21*월별비중!D$17 -> 3.4952363 | E15: =가정!$D$21*월별비중!E$17 -> 3.1144209 | F15: =가정!$D$21*월별비중!F$17 -> 3.2147909 | G15: =가정!$D$21*월별비중!G$17 -> 3.6900722 | H15: =가정!$D$21*월별비중!H$17 -> 2.7454137 | I15: =가정!$D$21*월별비중!I$17 -> 2.9225371 | ... M15: =가정!$D$21*월별비중!M$17 -> 6.2454186 | N15: =SUM(B15:M15) -> 49.654933
A16: 중국 | B16: =가정!$D$22*월별비중!B$18 -> 6.9679264 | C16: =가정!$D$22*월별비중!C$18 -> 4.0080584 | D16: =가정!$D$22*월별비중!D$18 -> 2.257996 | E16: =가정!$D$22*월별비중!E$18 -> 2.6274023 | F16: =가정!$D$22*월별비중!F$18 -> 3.4955071 | G16: =가정!$D$22*월별비중!G$18 -> 3.1861293 | H16: =가정!$D$22*월별비중!H$18 -> 2.7243715 | I16: =가정!$D$22*월별비중!I$18 -> 3.0937778 | ... M16: =가정!$D$22*월별비중!M$18 -> 6.4090792 | N16: =SUM(B16:M16) -> 49.259526
A17: 대만 | B17: =가정!$D$23*월별비중!B$19 -> 8.3328654 | C17: =가정!$D$23*월별비중!C$19 -> 7.1284873 | D17: =가정!$D$23*월별비중!D$19 -> 3.8444702 | E17: =가정!$D$23*월별비중!E$19 -> 4.8175123 | F17: =가정!$D$23*월별비중!F$19 -> 4.9486822 | G17: =가정!$D$23*월별비중!G$19 -> 3.9589458 | H17: =가정!$D$23*월별비중!H$19 -> 3.1957755 | I17: =가정!$D$23*월별비중!I$19 -> 3.362719 | ... M17: =가정!$D$23*월별비중!M$19 -> 6.9272244 | N17: =SUM(B17:M17) -> 63.716747
A18: 법인 소계 | B18: =SUM(B15:B17) -> 22.406395 | C18: =SUM(C15:C17) -> 16.754312 | D18: =SUM(D15:D17) -> 9.5977026 | E18: =SUM(E15:E17) -> 10.559336 | F18: =SUM(F15:F17) -> 11.65898 | G18: =SUM(G15:G17) -> 10.835147 | H18: =SUM(H15:H17) -> 8.6655607 | I18: =SUM(I15:I17) -> 9.3790339 | ... M18: =SUM(M15:M17) -> 19.581722 | N18: =SUM(B18:M18) -> 162.63121
A19: 홀세일 | B19: =가정!$D$25*월별비중!B$20 -> 5.0786902 | C19: =가정!$D$25*월별비중!C$20 -> 3.9478078 | D19: =가정!$D$25*월별비중!D$20 -> 2.2514841 | E19: =가정!$D$25*월별비중!E$20 -> 2.4975367 | F19: =가정!$D$25*월별비중!F$20 -> 2.6873879 | G19: =가정!$D$25*월별비중!G$20 -> 2.4673799 | H19: =가정!$D$25*월별비중!H$20 -> 1.9601962 | I19: =가정!$D$25*월별비중!I$20 -> 2.1041267 | ... M19: =가정!$D$25*월별비중!M$20 -> 4.3920726 | N19: =SUM(B19:M19) -> 37.151155
A20: TNH 합계 | B20: =B18+B19 -> 27.485085 | C20: =C18+C19 -> 20.702119 | D20: =D18+D19 -> 11.849187 | E20: =E18+E19 -> 13.056872 | F20: =F18+F19 -> 14.346368 | G20: =G18+G19 -> 13.302527 | H20: =H18+H19 -> 10.625757 | I20: =I18+I19 -> 11.483161 | ... M20: =M18+M19 -> 23.973795 | N20: =SUM(B20:M20) -> 199.78236
A22: ■ 증감 (2027 − 2026) — 매출
A23: 구분 | B23: 1월 | C23: 2월 | D23: 3월 | E23: 4월 | F23: 5월 | G23: 6월 | H23: 7월 | I23: 8월 | J23: 9월 | K23: 10월 | L23: 11월 | M23: 12월 | N23: 합계
A24: 홍콩 | B24: =B6-B15 -> -2.3536029 | C24: =C6-C15 -> -1.8887658 | D24: =D6-D15 -> -1.1852363 | E24: =E6-E15 -> -1.0354209 | F24: =F6-F15 -> -1.0697909 | G24: =G6-G15 -> -1.2480722 | H24: =H6-H15 -> -0.93041368 | I24: =I6-I15 -> -0.97553715 | ... M24: =M6-M15 -> -2.0874186 | N24: =SUM(B24:M24) -> -16.654933
A25: 중국 | B25: =B7-B16 -> 0.48707364 | C25: =C7-C16 -> 0.24444163 | D25: =D7-D16 -> 0.15700398 | E25: =E7-E16 -> 0.15509768 | F25: =F7-F16 -> 0.23199287 | G25: =G7-G16 -> 0.22637065 | H25: =H7-H16 -> 0.16312853 | I25: =I7-I16 -> 0.21372223 | ... M25: =M7-M16 -> 0.41592077 | N25: =SUM(B25:M25) -> 3.2404744
A26: 대만 | B26: =B8-B17 -> -0.8973054 | C26: =C8-C17 -> -0.67280732 | D26: =D8-D17 -> -0.38607024 | E26: =E8-E17 -> -0.43687234 | F26: =F8-F17 -> -0.45276223 | G26: =G8-G17 -> -0.38526578 | H26: =H8-H17 -> -0.31377551 | I26: =I8-I17 -> -0.30779901 | ... M26: =M8-M17 -> -0.6444644 | N26: =SUM(B26:M26) -> -6.0767472
A27: 법인 소계 | B27: =B9-B18 -> -2.7638347 | C27: =C9-C18 -> -2.3171315 | D27: =D9-D18 -> -1.4143026 | E27: =E9-E18 -> -1.3171956 | F27: =F9-F18 -> -1.2905602 | G27: =G9-G18 -> -1.4069673 | H27: =H9-H18 -> -1.0810607 | I27: =I9-I18 -> -1.0696139 | ... M27: =M9-M18 -> -2.3159622 | N27: =SUM(B27:M27) -> -19.491206
A28: 홀세일 | B28: =B10-B19 -> -0.96869022 | C28: =C10-C19 -> -0.76780778 | D28: =D10-D19 -> -0.42148413 | E28: =E10-E19 -> -0.48753673 | F28: =F10-F19 -> -0.5273879 | G28: =G10-G19 -> -0.48737986 | H28: =H10-H19 -> -0.37019622 | I28: =I10-I19 -> -0.39412672 | ... M28: =M10-M19 -> -0.85207259 | N28: =SUM(B28:M28) -> -7.1511546
A29: TNH 합계 | B29: =B11-B20 -> -3.7325249 | C29: =C11-C20 -> -3.0849393 | D29: =D11-D20 -> -1.8357867 | E29: =E11-E20 -> -1.8047323 | F29: =F11-F20 -> -1.8179481 | G29: =G11-G20 -> -1.8943471 | H29: =H11-H20 -> -1.4512569 | I29: =I11-I20 -> -1.4637406 | ... M29: =M11-M20 -> -3.1680348 | N29: =SUM(B29:M29) -> -26.64236
A31: ■ 증감률 — 매출
A32: 구분 | B32: 1월 | C32: 2월 | D32: 3월 | E32: 4월 | F32: 5월 | G32: 6월 | H32: 7월 | I32: 8월 | J32: 9월 | K32: 10월 | L32: 11월 | M32: 12월 | N32: 합계
A33: 홍콩 | B33: =IF(B15=0,0,B24/B15) -> -0.33123198 | C33: =IF(C15=0,0,C24/C15) -> -0.33621299 | D33: =IF(D15=0,0,D24/D15) -> -0.33910049 | E33: =IF(E15=0,0,E24/E15) -> -0.33246017 | F33: =IF(F15=0,0,F24/F15) -> -0.33277153 | G33: =IF(G15=0,0,G24/G15) -> -0.33822432 | H33: =IF(H15=0,0,H24/H15) -> -0.33889744 | I33: =IF(I15=0,0,I24/I15) -> -0.33379803 | ... N33: =IF(N15=0,0,N24/N15) -> -0.33541346
A34: 중국 | B34: =IF(B16=0,0,B25/B16) -> 0.069902237 | C34: =IF(C16=0,0,C25/C16) -> 0.060987543 | D34: =IF(D16=0,0,D25/D16) -> 0.069532445 | E34: =IF(E16=0,0,E25/E16) -> 0.059030808 | F34: =IF(F16=0,0,F25/F16) -> 0.066368875 | G34: =IF(G16=0,0,G25/G16) -> 0.071048795 | H34: =IF(H16=0,0,H25/H16) -> 0.059877491 | I34: =IF(I16=0,0,I25/I16) -> 0.069081312 | ... N34: =IF(N16=0,0,N25/N16) -> 0.06578371
A35: 대만 | B35: =IF(B17=0,0,B26/B17) -> -0.10768269 | C35: =IF(C17=0,0,C26/C17) -> -0.094382902 | D35: =IF(D17=0,0,D26/D17) -> -0.10042222 | E35: =IF(E17=0,0,E26/E17) -> -0.090684218 | F35: =IF(F17=0,0,F26/F17) -> -0.091491474 | G35: =IF(G17=0,0,G26/G17) -> -0.097315246 | H35: =IF(H17=0,0,H26/H17) -> -0.098184466 | I35: =IF(I17=0,0,I26/I17) -> -0.091532777 | ... N35: =IF(N17=0,0,N26/N17) -> -0.095371271
A36: 법인 소계 | B36: =IF(B18=0,0,B27/B18) -> -0.12335026 | C36: =IF(C18=0,0,C27/C18) -> -0.13830061 | D36: =IF(D18=0,0,D27/D18) -> -0.14735845 | E36: =IF(E18=0,0,E27/E18) -> -0.12474228 | F36: =IF(F18=0,0,F27/F18) -> -0.11069238 | G36: =IF(G18=0,0,G27/G18) -> -0.12985216 | H36: =IF(H18=0,0,H27/H18) -> -0.12475369 | I36: =IF(I18=0,0,I27/I18) -> -0.11404308 | ... N36: =IF(N18=0,0,N27/N18) -> -0.11984911
A37: 홀세일 | B37: =IF(B19=0,0,B28/B19) -> -0.19073623 | C37: =IF(C19=0,0,C28/C19) -> -0.19448966 | D37: =IF(D19=0,0,D28/D19) -> -0.1872028 | E37: =IF(E19=0,0,E28/E19) -> -0.19520703 | F37: =IF(F19=0,0,F28/F19) -> -0.19624554 | G37: =IF(G19=0,0,G28/G19) -> -0.19752932 | H37: =IF(H19=0,0,H28/H19) -> -0.18885672 | I37: =IF(I19=0,0,I28/I19) -> -0.1873113 | ... N37: =IF(N19=0,0,N28/N19) -> -0.19248808
A38: TNH 합계 | B38: =IF(B20=0,0,B29/B20) -> -0.13580183 | C38: =IF(C20=0,0,C29/C20) -> -0.14901563 | D38: =IF(D20=0,0,D29/D20) -> -0.15492934 | E38: =IF(E20=0,0,E29/E20) -> -0.13822087 | F38: =IF(F20=0,0,F29/F20) -> -0.12671835 | G38: =IF(G20=0,0,G29/G20) -> -0.14240506 | H38: =IF(H20=0,0,H29/H20) -> -0.13657915 | I38: =IF(I20=0,0,I29/I20) -> -0.12746845 | ... N38: =IF(N20=0,0,N29/N20) -> -0.13335692
A40: ■ 2027 계획 — 원가
A41: 구분 | B41: 1월 | C41: 2월 | D41: 3월 | E41: 4월 | F41: 5월 | G41: 6월 | H41: 7월 | I41: 8월 | J41: 9월 | K41: 10월 | L41: 11월 | M41: 12월 | N41: 합계
A42: 홍콩 | B42: =가정!$I$11*월별비중!B$24 -> 3.6 | C42: =가정!$I$11*월별비중!C$24 -> 2.825 | D42: =가정!$I$11*월별비중!D$24 -> 1.75 | E42: =가정!$I$11*월별비중!E$24 -> 1.575 | F42: =가정!$I$11*월별비중!F$24 -> 1.625 | G42: =가정!$I$11*월별비중!G$24 -> 1.85 | H42: =가정!$I$11*월별비중!H$24 -> 1.375 | I42: =가정!$I$11*월별비중!I$24 -> 1.475 | ... M42: =가정!$I$11*월별비중!M$24 -> 3.15 | N42: =SUM(B42:M42) -> 25
A43: 중국 | B43: =가정!$I$12*월별비중!B$25 -> 7.1 | C43: =가정!$I$12*월별비중!C$25 -> 4.05 | D43: =가정!$I$12*월별비중!D$25 -> 2.3 | E43: =가정!$I$12*월별비중!E$25 -> 2.65 | F43: =가정!$I$12*월별비중!F$25 -> 3.55 | G43: =가정!$I$12*월별비중!G$25 -> 3.25 | H43: =가정!$I$12*월별비중!H$25 -> 2.75 | I43: =가정!$I$12*월별비중!I$25 -> 3.15 | ... M43: =가정!$I$12*월별비중!M$25 -> 6.5 | N43: =SUM(B43:M43) -> 50
A44: 대만 | B44: =가정!$I$13*월별비중!B$26 -> 5.633 | C44: =가정!$I$13*월별비중!C$26 -> 4.8906667 | D44: =가정!$I$13*월별비중!D$26 -> 2.62 | E44: =가정!$I$13*월별비중!E$26 -> 3.3186667 | F44: =가정!$I$13*월별비중!F$26 -> 3.406 | G44: =가정!$I$13*월별비중!G$26 -> 2.7073333 | H44: =가정!$I$13*월별비중!H$26 -> 2.1833333 | I44: =가정!$I$13*월별비중!I$26 -> 2.3143333 | ... M44: =가정!$I$13*월별비중!M$26 -> 4.7596667 | N44: =SUM(B44:M44) -> 43.666667
...

Sheet 가정
A1: 2027 TNH 사업계획 — 가정(입력) 시트
A2: 계산용 시트입니다. 모든 입력은 [요약] 시트의 노란 칸에서 합니다 (이 시트의 초록 글씨 칸 = 요약 연동, 직접 수정 금지). 단위: 억원(별도 표기 제외)
A3: 환율 (KRW/USD) | B3: =요약!G17 -> 1362.78
A4: 공급율 — 홍콩·대만·홀세일 (택가 대비) | B4: =요약!D17 -> 0.33
A5: 택가 배수 (택가 ÷ 한국원가) | B5: =요약!E17 -> 4
A6: 중국 공급가 마진 (한국원가 + %) | B6: =요약!F17 -> 0.05
A7: 법인 매출 중 이월제품 비중 | B7: =요약!B17 -> 0.6
A8: 법인 매출 중 정상제품 비중 (= TNH가 수출 공급해야 하는 제품) | B8: =1-B7 -> 0.4
A9: ① 2027 계획
A10: 구분 | B10: 2027 법인 매출목표(억) | C10: 정상제품 매출(억) = 목표×정상비중 | D10: 정판율 (공급 물량 중 판매 비율) | E10: 평균 할인율 | F10: 택가 기준 공급액(억) = 정상매출÷(1−할인)÷정판율 | G10: TNH 공급가 ÷ 택가 | H10: 2027 TNH 매출(억) | I10: 2027 TNH 원가(억) | J10: 2027 TNH 이익(억) | K10: 이익률
A11: 홍콩 | B11: =요약!B8 -> 150 | C11: =B11*$B$8 -> 60 | D11: =요약!C8 -> 0.6 | E11: =요약!D8 -> 0 | F11: =C11/(1-E11)/D11 -> 100 | G11: =$B$4 -> 0.33 | H11: =F11*G11 -> 33 | I11: =F11/$B$5 -> 25 | J11: =H11-I11 -> 8 | K11: =IF(H11=0,0,J11/H11) -> 0.24242424
A12: 중국 | B12: =요약!B9 -> 300 | C12: =B12*$B$8 -> 120 | D12: =요약!C9 -> 0.6 | E12: =요약!D9 -> 0 | F12: =C12/(1-E12)/D12 -> 200 | G12: =(1+$B$6)/$B$5 -> 0.2625 | H12: =F12*G12 -> 52.5 | I12: =F12/$B$5 -> 50 | J12: =H12-I12 -> 2.5 | K12: =IF(H12=0,0,J12/H12) -> 0.047619048
A13: 대만 | B13: =요약!B10 -> 262 | C13: =B13*$B$8 -> 104.8 | D13: =요약!C10 -> 0.6 | E13: =요약!D10 -> 0 | F13: =C13/(1-E13)/D13 -> 174.66667 | G13: =$B$4 -> 0.33 | H13: =F13*G13 -> 57.64 | I13: =F13/$B$5 -> 43.666667 | J13: =H13-I13 -> 13.973333 | K13: =IF(H13=0,0,J13/H13) -> 0.24242424
A14: 법인 소계 | B14: =SUM(B11:B13) -> 712 | C14: =SUM(C11:C13) -> 284.8 | F14: =SUM(F11:F13) -> 474.66667 | G14: =H14/F14 -> 0.30155899 | H14: =SUM(H11:H13) -> 143.14 | I14: =SUM(I11:I13) -> 118.66667 | J14: =SUM(J11:J13) -> 24.473333 | K14: =J14/H14 -> 0.1709748
A15: 홀세일 (TNH 매출 기준 입력) | F15: =H15/G15 -> 90.909091 | G15: =$B$4 -> 0.33 | H15: =요약!H12 -> 30 | I15: =F15/$B$5 -> 22.727273 | J15: =H15-I15 -> 7.2727273 | K15: =J15/H15 -> 0.24242424
A16: TNH 합계 | F16: =F14+F15 -> 565.57576 | H16: =H14+H15 -> 173.14 | I16: =I14+I15 -> 141.39394 | J16: =J14+J15 -> 31.746061 | K16: =J16/H16 -> 0.18335486
A19: ② 2026 예상 (방식 1: 실적 1/1~기준일 + 잔여 예측 [기본] / 방식 2: ERP 수주 전량) + 2027 환산배수 비교
A20: 구분 | B20: 택가금액(억) | C20: 원가(억) | D20: TNH 매출(억) | E20: TNH 이익(억) | F20: 이익률 | G20: 2026 법인 예상매출(억) | H20: 정상제품분(억) | I20: 2026 환산배수 (택가공급÷정상매출) | J20: 2027 설정 환산배수
A21: 홍콩 | B21: =IF($B$35=2,B47,E38) -> 139.02201 | C21: =IF($B$35=2,C47,E38*H38) -> 32.686818 | D21: =IF($B$35=2,D47,F38) -> 49.654933 | E21: =D21-C21 -> 16.968114 | F21: =IF(D21=0,0,E21/D21) -> 0.34172062 | G21: =월별비중!N11 -> 168.20448 | H21: =G21*$B$8 -> 67.281791 | I21: =B21/H21 -> 2.0662651 | J21: =F11/C11 -> 1.6666667
A22: 중국 | B22: =IF($B$35=2,B48,E39) -> 167.88182 | C22: =IF($B$35=2,C48,E39*H39) -> 42.527781 | D22: =IF($B$35=2,D48,F39) -> 49.259526 | E22: =D22-C22 -> 6.7317451 | F22: =IF(D22=0,0,E22/D22) -> 0.13665875 | G22: =월별비중!N12 -> 106.67826 | H22: =G22*$B$8 -> 42.671303 | I22: =B22/H22 -> 3.9343028 | J22: =F12/C12 -> 1.6666667
A23: 대만 | B23: =IF($B$35=2,B49,E40) -> 177.82321 | C23: =IF($B$35=2,C49,E40*H40) -> 42.782833 | D23: =IF($B$35=2,D49,F40) -> 63.716747 | E23: =D23-C23 -> 20.933915 | F23: =IF(D23=0,0,E23/D23) -> 0.32854651 | G23: =월별비중!N13 -> 267.16658 | H23: =G23*$B$8 -> 106.86663 | I23: =B23/H23 -> 1.6639732 | J23: =F13/C13 -> 1.6666667
A24: 법인 소계 | B24: =SUM(B21:B23) -> 484.72705 | C24: =SUM(C21:C23) -> 117.99743 | D24: =SUM(D21:D23) -> 162.63121 | E24: =SUM(E21:E23) -> 44.633774 | F24: =E24/D24 -> 0.27444779 | G24: =SUM(G21:G23) -> 542.04931 | H24: =SUM(H21:H23) -> 216.81973 | I24: =B24/H24 -> 2.2356225 | J24: =F14/C14 -> 1.6666667
A25: 홀세일 | B25: =IF($B$35=2,B50,E41) -> 97.43421 | C25: =IF($B$35=2,C50,E41*H41) -> 23.326072 | D25: =IF($B$35=2,D50,F41) -> 37.151155 | E25: =D25-C25 -> 13.825083 | F25: =IF(D25=0,0,E25/D25) -> 0.37213063
A26: TNH 합계 | B26: =B24+B25 -> 582.16126 | C26: =C24+C25 -> 141.3235 | D26: =D24+D25 -> 199.78236 | E26: =E24+E25 -> 58.458857 | F26: =E26/D26 -> 0.29261271
A28: ※ 환산배수 = 법인 정상제품 매출 1원을 만들기 위해 TNH가 공급한 택가 금액. 2026은 실제 수주 기준, 2027은 위 정판율·할인율로 역산한 값입니다. 두 값이 크게 다르면 정판율·할인율 입력을 조정하세요.
A31: 요약 시트 경고 기준 — 2026 환산배수 대비 2027 설정 환산배수 괴리 허용폭 | B31: =요약!J17 -> 0.3
A33: ③ 2026 예상 산출 — 실적(판매펀칭 1/1~기준일) + 잔여기간 예측
A34: 실적 기준일 | B34: =요약!H17 -> 46317
A35: 2026 예측 방식 (1 = 실적 진도율 환산, 2 = ERP 수주 전량) | B35: =요약!I17 -> 1
A36: ※ 방식 1: 연간 예상 = 실적 ÷ 진도율. 진도율 = 2026 법인 월 매출 비중(월별비중 ③)을 기준일까지 누계한 값. 잔여 예측 = 연간 예상 − 실적. 원가 = 택가 × ERP 원가율.
A37: 구분 | B37: 실적 택가(억) (보정 반영) | C37: 실적 TNH 매출(억) | D37: 진도율 (매출 비중 누계) | E37: 연간 예상 택가(억) | F37: 연간 예상 TNH 매출(억) | G37: 잔여기간 예측 매출(억) | H37: 원가율 (원가÷택가, ERP) | I37: ERP 수주 기준 매출(억) | J37: 예상 vs ERP
A38: 홍콩 | B38: =SUMIFS(RAW_판매펀칭!$N:$N,RAW_판매펀칭!$A:$A,"HK")/10^8 -> 103.28232 | C38: =SUMIFS(RAW_판매펀칭!$M:$M,RAW_판매펀칭!$A:$A,"HK")/10^8 -> 36.889672 | D38: =SUMPRODUCT(월별비중!$B$17:$M$17,월별비중!$B$32:$M$32) -> 0.74292059 | E38: =IF(D38=0,B38,B38/D38) -> 139.02201 | F38: =IF(D38=0,C38,C38/D38) -> 49.654933 | G38: =F38-C38 -> 12.765261 | H38: =IF(B47=0,1/$B$5,C47/B47) -> 0.23511973 | I38: =D47 -> 45.60094 | J38: =IF(I38=0,0,F38/I38-1) -> 0.088901507
A39: 중국 | B39: =SUMIFS(RAW_판매펀칭!$N:$N,RAW_판매펀칭!$A:$A,"CN")/10^8 -> 123.076 | C39: =SUMIFS(RAW_판매펀칭!$M:$M,RAW_판매펀칭!$A:$A,"CN")/10^8 -> 36.112696 | D39: =SUMPRODUCT(월별비중!$B$18:$M$18,월별비중!$B$32:$M$32) -> 0.73311093 | E39: =IF(D39=0,B39,B39/D39) -> 167.88182 | F39: =IF(D39=0,C39,C39/D39) -> 49.259526 | G39: =F39-C39 -> 13.146829 | H39: =IF(B48=0,1/$B$5,C48/B48) -> 0.25331974 | I39: =D48 -> 60.201222 | J39: =IF(I39=0,0,F39/I39-1) -> -0.18175206
A40: 대만 | B40: =SUMIFS(RAW_판매펀칭!$N:$N,RAW_판매펀칭!$A:$A,"TW")/10^8 -> 131.99098 | C40: =SUMIFS(RAW_판매펀칭!$M:$M,RAW_판매펀칭!$A:$A,"TW")/10^8 -> 47.294365 | D40: =SUMPRODUCT(월별비중!$B$19:$M$19,월별비중!$B$32:$M$32) -> 0.74225957 | E40: =IF(D40=0,B40,B40/D40) -> 177.82321 | F40: =IF(D40=0,C40,C40/D40) -> 63.716747 | G40: =F40-C40 -> 16.422382 | H40: =IF(B49=0,1/$B$5,C49/B49) -> 0.24059195 | I40: =D49 -> 64.103868 | J40: =IF(I40=0,0,F40/I40-1) -> -0.0060389599
A41: 홀세일 | B41: =SUMIFS(RAW_판매펀칭!$N:$N,RAW_판매펀칭!$A:$A,"홀세일")/10^8 -> 72.16603 | C41: =SUMIFS(RAW_판매펀칭!$M:$M,RAW_판매펀칭!$A:$A,"홀세일")/10^8 -> 27.51653 | D41: =SUMPRODUCT(월별비중!$B$20:$M$20,월별비중!$B$32:$M$32) -> 0.74066419 | E41: =IF(D41=0,B41,B41/D41) -> 97.43421 | F41: =IF(D41=0,C41,C41/D41) -> 37.151155 | G41: =F41-C41 -> 9.6346248 | H41: =IF(B50=0,1/$B$5,C50/B50) -> 0.23940331 | I41: =D50 -> 37.517189 | J41: =IF(I41=0,0,F41/I41-1) -> -0.0097564571
A42: TNH 합계 | B42: =SUM(B38:B41) -> 430.51533 | C42: =SUM(C38:C41) -> 147.81326 | D42: =IF(F42=0,0,C42/F42) -> 0.73987145 | E42: =SUM(E38:E41) -> 582.16126 | F42: =SUM(F38:F41) -> 199.78236 | G42: =SUM(G38:G41) -> 51.969097 | H42: =IF(E42=0,0,SUMPRODUCT(E38:E41,H38:H41)/E42) -> 0.24275663 | I42: =SUM(I38:I41) -> 207.42322 | J42: =IF(I42=0,0,F42/I42-1) -> -0.036837048
A43: ※ 월별 실적은 판매펀칭이 기간 합계라 연간 배분은 기존대로 2026 월별 비중을 사용합니다. 월별 판매펀칭을 받으면 월 실적으로 교체 가능합니다.
A45: ④ 참고: ERP 수주 전량 집계 (기존 방식, RAW_2026) — 예측 방식 2 선택 시 ②에 사용
A46: 구분 | B46: 택가금액(억) | C46: 원가(억) | D46: TNH 매출(억) | E46: TNH 이익(억)
A47: 홍콩 | B47: =SUMIFS(RAW_2026!$M:$M,RAW_2026!$B:$B,"HK")/10^8 -> 131.50004 | C47: =SUMIFS(RAW_2026!$N:$N,RAW_2026!$B:$B,"HK")/10^8 -> 30.918255 | D47: =SUMIFS(RAW_2026!$O:$O,RAW_2026!$B:$B,"HK")/10^8 -> 45.60094 | E47: =D47-C47 -> 14.682686
...

Sheet 월별비중
A1: 월별 비중 (2026 법인 월 매출 기준 → 2026 월 배분 / ④ 2027 입력 비중 → 2027 월 배분)
A2: 단위: 억원. 출처: monthly_sales.json (2025 실적, 2026 1~9월 실적). 2026 10~12월은 "2025 같은 달 × (2026 1~9월 ÷ 2025 1~9월)"로 추정(수식).
A3: ① 2025 실적 (억원)
A4: 구분 | B4: 1월 | C4: 2월 | D4: 3월 | E4: 4월 | F4: 5월 | G4: 6월 | H4: 7월 | I4: 8월 | J4: 9월 | K4: 10월 | L4: 11월 | M4: 12월 | N4: 합계
A5: 홍콩 | B5: 31.7 | C5: 18.2 | D5: 12.1 | E5: 13 | F5: 11.9 | G5: 12.5 | H5: 12.7 | I5: 12.3 | J5: 8.7 | K5: 14.7 | L5: 21.1 | M5: 24.3 | N5: =SUM(B5:M5) -> 193.2
A6: 중국 | B6: 15.8 | C6: 6.5 | D6: 7.4 | E6: 9.4 | F6: 9.6 | G6: 8.6 | H6: 7.1 | I6: 6.7 | J6: 5.8 | K6: 15.5 | L6: 11.9 | M6: 15.6 | N6: =SUM(B6:M6) -> 119.9
A7: 대만 | B7: 39.8 | C7: 20.9 | D7: 19 | E7: 21.2 | F7: 21 | G7: 16.6 | H7: 16.2 | I7: 19.7 | J7: 16.5 | K7: 22.5 | L7: 35 | M7: 30.3 | N7: =SUM(B7:M7) -> 278.7
A8: 3법인 합계 | B8: =SUM(B5:B7) -> 87.3 | C8: =SUM(C5:C7) -> 45.6 | D8: =SUM(D5:D7) -> 38.5 | E8: =SUM(E5:E7) -> 43.6 | F8: =SUM(F5:F7) -> 42.5 | G8: =SUM(G5:G7) -> 37.7 | H8: =SUM(H5:H7) -> 36 | I8: =SUM(I5:I7) -> 38.7 | ... N8: =SUM(N5:N7) -> 591.8
A9: ② 2026 실적 + 추정 (억원) — 파란색 = 입력(1~9월 실적), 검정 = 수식
A10: 구분 | B10: 1월 | C10: 2월 | D10: 3월 | E10: 4월 | F10: 5월 | G10: 6월 | H10: 7월 | I10: 8월 | J10: 9월 | K10: 10월 | L10: 11월 | M10: 12월 | N10: 합계
A11: 홍콩 | B11: 24.07 | C11: 19.03 | D11: 11.84 | E11: 10.55 | F11: 10.89 | G11: 12.5 | H11: 9.3 | I11: 9.9 | J11: 7.8 | K11: =K5*SUM($B11:$J11)/SUM($B5:$J5) -> 12.798167 | L11: =L5*SUM($B11:$J11)/SUM($B5:$J5) -> 18.370158 | M11: =M5*SUM($B11:$J11)/SUM($B5:$J5) -> 21.156153 | N11: =SUM(B11:M11) -> 168.20448
A12: 중국 | B12: 15.09 | C12: 8.68 | D12: 4.89 | E12: 5.69 | F12: 7.57 | G12: 6.9 | H12: 5.9 | I12: 6.7 | J12: 7 | K12: =K6*SUM($B12:$J12)/SUM($B6:$J6) -> 13.790767 | L12: =L6*SUM($B12:$J12)/SUM($B6:$J6) -> 10.58775 | M12: =M6*SUM($B12:$J12)/SUM($B6:$J6) -> 13.87974 | N12: =SUM(B12:M12) -> 106.67826
A13: 대만 | B13: 34.94 | C13: 29.89 | D13: 16.12 | E13: 20.2 | F13: 20.75 | G13: 16.6 | H13: 13.4 | I13: 14.1 | J13: 17 | K13: =K7*SUM($B13:$J13)/SUM($B7:$J7) -> 21.568884 | L13: =L7*SUM($B13:$J13)/SUM($B7:$J7) -> 33.551598 | M13: =M7*SUM($B13:$J13)/SUM($B7:$J7) -> 29.046097 | N13: =SUM(B13:M13) -> 267.16658
A14: 3법인 합계 | B14: =SUM(B11:B13) -> 74.1 | C14: =SUM(C11:C13) -> 57.6 | D14: =SUM(D11:D13) -> 32.85 | E14: =SUM(E11:E13) -> 36.44 | F14: =SUM(F11:F13) -> 39.21 | G14: =SUM(G11:G13) -> 36 | H14: =SUM(H11:H13) -> 28.6 | I14: =SUM(I11:I13) -> 30.7 | ... N14: =SUM(N11:N13) -> 542.04931
A15: ③ 2026 월별 비중
A16: 구분 | B16: 1월 | C16: 2월 | D16: 3월 | E16: 4월 | F16: 5월 | G16: 6월 | H16: 7월 | I16: 8월 | J16: 9월 | K16: 10월 | L16: 11월 | M16: 12월 | N16: 합계
A17: 홍콩 | B17: =B11/$N11 -> 0.14309964 | C17: =C11/$N11 -> 0.11313611 | D17: =D11/$N11 -> 0.070390516 | E17: =E11/$N11 -> 0.062721279 | F17: =F11/$N11 -> 0.064742628 | G17: =G11/$N11 -> 0.074314312 | H17: =H11/$N11 -> 0.055289848 | I17: =I11/$N11 -> 0.058856935 | ... M17: =M11/$N11 -> 0.1257764 | N17: =SUM(B17:M17) -> 1
A18: 중국 | B18: =B12/$N12 -> 0.14145338 | C18: =C12/$N12 -> 0.081366158 | D18: =D12/$N12 -> 0.045838769 | E18: =E12/$N12 -> 0.053337954 | F18: =F12/$N12 -> 0.070961039 | G18: =G12/$N12 -> 0.064680472 | H18: =H12/$N12 -> 0.05530649 | I18: =I12/$N12 -> 0.062805675 | ... M18: =M12/$N12 -> 0.13010842 | N18: =SUM(B18:M18) -> 1
A19: 대만 | B19: =B13/$N13 -> 0.13077983 | C19: =C13/$N13 -> 0.11187777 | D19: =D13/$N13 -> 0.060336888 | E19: =E13/$N13 -> 0.075608259 | F19: =F13/$N13 -> 0.0776669 | G19: =G13/$N13 -> 0.06213352 | H19: =H13/$N13 -> 0.050155974 | I19: =I13/$N13 -> 0.052776062 | ... M19: =M13/$N13 -> 0.10871905 | N19: =SUM(B19:M19) -> 1
A20: 3법인 합계 (홀세일 적용) | B20: =B14/$N14 -> 0.13670343 | C20: =C14/$N14 -> 0.10626339 | D20: =D14/$N14 -> 0.060603342 | E20: =E14/$N14 -> 0.067226356 | F20: =F14/$N14 -> 0.072336592 | G20: =G14/$N14 -> 0.066414621 | H20: =H14/$N14 -> 0.052762727 | I20: =I14/$N14 -> 0.056636913 | ... N20: =N14/$N14 -> 1
A22: ④ 2027 월별 비중 — [요약] 시트 ④에서 입력한 값이 연동됩니다 (초록 글씨). 합계 100% 유지
A23: 구분 | B23: 1월 | C23: 2월 | D23: 3월 | E23: 4월 | F23: 5월 | G23: 6월 | H23: 7월 | I23: 8월 | J23: 9월 | K23: 10월 | L23: 11월 | M23: 12월 | N23: 합계
A24: 홍콩 | B24: =요약!B30 -> 0.144 | C24: =요약!C30 -> 0.113 | D24: =요약!D30 -> 0.07 | E24: =요약!E30 -> 0.063 | F24: =요약!F30 -> 0.065 | G24: =요약!G30 -> 0.074 | H24: =요약!H30 -> 0.055 | I24: =요약!I30 -> 0.059 | ... M24: =요약!M30 -> 0.126 | N24: =SUM(B24:M24) -> 1
A25: 중국 | B25: =요약!B31 -> 0.142 | C25: =요약!C31 -> 0.081 | D25: =요약!D31 -> 0.046 | E25: =요약!E31 -> 0.053 | F25: =요약!F31 -> 0.071 | G25: =요약!G31 -> 0.065 | H25: =요약!H31 -> 0.055 | I25: =요약!I31 -> 0.063 | ... M25: =요약!M31 -> 0.13 | N25: =SUM(B25:M25) -> 1
A26: 대만 | B26: =요약!B32 -> 0.129 | C26: =요약!C32 -> 0.112 | D26: =요약!D32 -> 0.06 | E26: =요약!E32 -> 0.076 | F26: =요약!F32 -> 0.078 | G26: =요약!G32 -> 0.062 | H26: =요약!H32 -> 0.05 | I26: =요약!I32 -> 0.053 | ... M26: =요약!M32 -> 0.109 | N26: =SUM(B26:M26) -> 1
A27: 홀세일 (3법인 합계 비중 적용) | B27: =요약!B33 -> 0.137 | C27: =요약!C33 -> 0.106 | D27: =요약!D33 -> 0.061 | E27: =요약!E33 -> 0.067 | F27: =요약!F33 -> 0.072 | G27: =요약!G33 -> 0.066 | H27: =요약!H33 -> 0.053 | I27: =요약!I33 -> 0.057 | ... M27: =요약!M33 -> 0.118 | N27: =SUM(B27:M27) -> 1
A28: ※ 초기값 = 2026 월별 비중(③)을 0.1% 단위로 반올림한 값. 합계가 100%가 아니면 빨간색으로 표시되고 요약·사업계획 상단에 경고가 뜹니다.
A30: ⑤ 2026 실적 반영 경과율 — 가정!B34 실적 기준일까지 각 월이 경과한 비율 (1 = 해당 월 전체 경과)
A31: 구분 | B31: 1월 | C31: 2월 | D31: 3월 | E31: 4월 | F31: 5월 | G31: 6월 | H31: 7월 | I31: 8월 | J31: 9월 | K31: 10월 | L31: 11월 | M31: 12월
A32: 경과율 | B32: =IF(1<MONTH(가정!$B$34),1,IF(1=MONTH(가정!$B$34),DAY(가정!$B$34)/DAY(EOMONTH(DATE(YEAR(가정!$B$34),1,1),0)),0)) -> 1 | C32: =IF(2<MONTH(가정!$B$34),1,IF(2=MONTH(가정!$B$34),DAY(가정!$B$34)/DAY(EOMONTH(DATE(YEAR(가정!$B$34),2,1),0)),0)) -> 1 | D32: =IF(3<MONTH(가정!$B$34),1,IF(3=MONTH(가정!$B$34),DAY(가정!$B$34)/DAY(EOMONTH(DATE(YEAR(가정!$B$34),3,1),0)),0)) -> 1 | E32: =IF(4<MONTH(가정!$B$34),1,IF(4=MONTH(가정!$B$34),DAY(가정!$B$34)/DAY(EOMONTH(DATE(YEAR(가정!$B$34),4,1),0)),0)) -> 1 | F32: =IF(5<MONTH(가정!$B$34),1,IF(5=MONTH(가정!$B$34),DAY(가정!$B$34)/DAY(EOMONTH(DATE(YEAR(가정!$B$34),5,1),0)),0)) -> 1 | G32: =IF(6<MONTH(가정!$B$34),1,IF(6=MONTH(가정!$B$34),DAY(가정!$B$34)/DAY(EOMONTH(DATE(YEAR(가정!$B$34),6,1),0)),0)) -> 1 | H32: =IF(7<MONTH(가정!$B$34),1,IF(7=MONTH(가정!$B$34),DAY(가정!$B$34)/DAY(EOMONTH(DATE(YEAR(가정!$B$34),7,1),0)),0)) -> 1 | I32: =IF(8<MONTH(가정!$B$34),1,IF(8=MONTH(가정!$B$34),DAY(가정!$B$34)/DAY(EOMONTH(DATE(YEAR(가정!$B$34),8,1),0)),0)) -> 1 | J32: =IF(9<MONTH(가정!$B$34),1,IF(9=MONTH(가정!$B$34),DAY(가정!$B$34)/DAY(EOMONTH(DATE(YEAR(가정!$B$34),9,1),0)),0)) -> 1 | K32: =IF(10<MONTH(가정!$B$34),1,IF(10=MONTH(가정!$B$34),DAY(가정!$B$34)/DAY(EOMONTH(DATE(YEAR(가정!$B$34),10,1),0)),0)) -> 0.70967742 | L32: =IF(11<MONTH(가정!$B$34),1,IF(11=MONTH(가정!$B$34),DAY(가정!$B$34)/DAY(EOMONTH(DATE(YEAR(가정!$B$34),11,1),0)),0)) -> 0 | M32: =IF(12<MONTH(가정!$B$34),1,IF(12=MONTH(가정!$B$34),DAY(가정!$B$34)/DAY(EOMONTH(DATE(YEAR(가정!$B$34),12,1),0)),0)) -> 0

Sheet RAW_판매펀칭
A1: 구분 | B1: 매장코드 | C1: 매장명 | D1: 브랜드 | E1: 년도 | F1: 시즌 | G1: 품목 | H1: 라인 | I1: 스타일 | J1: 스타일명 | K1: 수량 | L1: TAG금액(KRW) | M1: 판매금액(KRW) | N1: TAG(보정) | O1: 보정내역 | Q1: 판매펀칭 리스트(1/1~기준일, 본사판매 = TNH → 법인/홀세일 공급). 소계행은 구분 열에서 "제외" 처리되므로 원본을 그대로 붙여넣어도 됩니다.
A2: =IF(OR(TRIM(C2)="",SUBSTITUTE(C2," ","")="소계"),"제외",IF(ISNUMBER(SEARCH("홍콩",C2)),"HK",IF(ISNUMBER(SEARCH("상해",C2)),"CN",IF(ISNUMBER(SEARCH("대만",C2)),"TW","홀세일")))) -> TW | B2: W9002 | C2: W대만 | D2: 내셔널지오그래픽 | E2: 2025 | F2: 봄 | G2: 의류 | H2: Urban | I2: N251UJP260 | J2: 아틀라스 윈드스토퍼 BY GORE-TEX LABS 2L 블록 자켓 | K2: 67 | L2: 20033000 | M2: 7088533 | N2: =IF(A2="제외",0,IF(OR(N(L2)<=0,N(M2)>N(L2)),N(M2)/가정!$B$4,N(L2))) -> 20033000 | O2: =IF(A2="제외","",IF(OR(N(L2)<=0,N(M2)>N(L2)),"택가보정(판매금액÷공급율)","")) | Q2: 택가 오류행(택가≤0 또는 판매금액>택가)은 TAG(보정) = 판매금액÷공급율(가정!B4)로 보정하고 O열에 표시합니다.
A3: =IF(OR(TRIM(C3)="",SUBSTITUTE(C3," ","")="소계"),"제외",IF(ISNUMBER(SEARCH("홍콩",C3)),"HK",IF(ISNUMBER(SEARCH("상해",C3)),"CN",IF(ISNUMBER(SEARCH("대만",C3)),"TW","홀세일")))) -> TW | B3: W9002 | C3: W대만 | D3: 내셔널지오그래픽 | E3: 2025 | F3: 봄 | G3: 의류 | H3: 온라인 | I3: N251UJP860 | J3: (온) 아틀라스 윈드스토퍼 BY GORE-TEX LABS 2L 블록 자켓 | K3: 20 | L3: 5980000 | M3: 2115980 | N3: =IF(A3="제외",0,IF(OR(N(L3)<=0,N(M3)>N(L3)),N(M3)/가정!$B$4,N(L3))) -> 5980000 | O3: =IF(A3="제외","",IF(OR(N(L3)<=0,N(M3)>N(L3)),"택가보정(판매금액÷공급율)",""))
A4: =IF(OR(TRIM(C4)="",SUBSTITUTE(C4," ","")="소계"),"제외",IF(ISNUMBER(SEARCH("홍콩",C4)),"HK",IF(ISNUMBER(SEARCH("상해",C4)),"CN",IF(ISNUMBER(SEARCH("대만",C4)),"TW","홀세일")))) -> TW | B4: W9002 | C4: W대만 | D4: 내셔널지오그래픽 | E4: 2026 | F4: 봄 | G4: 용품 | H4: Original | I4: N261ABG010 | J4: 파치백팩 | K4: 150 | L4: 25350000 | M4: 9736800 | N4: =IF(A4="제외",0,IF(OR(N(L4)<=0,N(M4)>N(L4)),N(M4)/가정!$B$4,N(L4))) -> 25350000 | O4: =IF(A4="제외","",IF(OR(N(L4)<=0,N(M4)>N(L4)),"택가보정(판매금액÷공급율)",""))
A5: =IF(OR(TRIM(C5)="",SUBSTITUTE(C5," ","")="소계"),"제외",IF(ISNUMBER(SEARCH("홍콩",C5)),"HK",IF(ISNUMBER(SEARCH("상해",C5)),"CN",IF(ISNUMBER(SEARCH("대만",C5)),"TW","홀세일")))) -> TW | B5: W9002 | C5: W대만 | D5: 내셔널지오그래픽 | E5: 2026 | F5: 봄 | G5: 용품 | H5: Original | I5: N261ABG020 | J5: 파치+백팩 | K5: 250 | L5: 44750000 | M5: 17203750 | N5: =IF(A5="제외",0,IF(OR(N(L5)<=0,N(M5)>N(L5)),N(M5)/가정!$B$4,N(L5))) -> 44750000 | O5: =IF(A5="제외","",IF(OR(N(L5)<=0,N(M5)>N(L5)),"택가보정(판매금액÷공급율)",""))
A6: =IF(OR(TRIM(C6)="",SUBSTITUTE(C6," ","")="소계"),"제외",IF(ISNUMBER(SEARCH("홍콩",C6)),"HK",IF(ISNUMBER(SEARCH("상해",C6)),"CN",IF(ISNUMBER(SEARCH("대만",C6)),"TW","홀세일")))) -> TW | B6: W9002 | C6: W대만 | D6: 내셔널지오그래픽 | E6: 2026 | F6: 봄 | G6: 용품 | H6: Original | I6: N261ABG030 | J6: 라코백팩 | K6: 130 | L6: 21970000 | M6: 8438560 | N6: =IF(A6="제외",0,IF(OR(N(L6)<=0,N(M6)>N(L6)),N(M6)/가정!$B$4,N(L6))) -> 21970000 | O6: =IF(A6="제외","",IF(OR(N(L6)<=0,N(M6)>N(L6)),"택가보정(판매금액÷공급율)",""))
A7: =IF(OR(TRIM(C7)="",SUBSTITUTE(C7," ","")="소계"),"제외",IF(ISNUMBER(SEARCH("홍콩",C7)),"HK",IF(ISNUMBER(SEARCH("상해",C7)),"CN",IF(ISNUMBER(SEARCH("대만",C7)),"TW","홀세일")))) -> TW | B7: W9002 | C7: W대만 | D7: 내셔널지오그래픽 | E7: 2026 | F7: 봄 | G7: 용품 | H7: Original | I7: N261ABG040 | J7: 버디백팩 | K7: 180 | L7: 26820000 | M7: 10305000 | N7: =IF(A7="제외",0,IF(OR(N(L7)<=0,N(M7)>N(L7)),N(M7)/가정!$B$4,N(L7))) -> 26820000 | O7: =IF(A7="제외","",IF(OR(N(L7)<=0,N(M7)>N(L7)),"택가보정(판매금액÷공급율)",""))
A8: =IF(OR(TRIM(C8)="",SUBSTITUTE(C8," ","")="소계"),"제외",IF(ISNUMBER(SEARCH("홍콩",C8)),"HK",IF(ISNUMBER(SEARCH("상해",C8)),"CN",IF(ISNUMBER(SEARCH("대만",C8)),"TW","홀세일")))) -> TW | B8: W9002 | C8: W대만 | D8: 내셔널지오그래픽 | E8: 2026 | F8: 봄 | G8: 용품 | H8: Original | I8: N261ABG050 | J8: 타이니백팩 | K8: 280 | L8: 41720000 | M8: 15693200 | N8: =IF(A8="제외",0,IF(OR(N(L8)<=0,N(M8)>N(L8)),N(M8)/가정!$B$4,N(L8))) -> 41720000 | O8: =IF(A8="제외","",IF(OR(N(L8)<=0,N(M8)>N(L8)),"택가보정(판매금액÷공급율)",""))
A9: =IF(OR(TRIM(C9)="",SUBSTITUTE(C9," ","")="소계"),"제외",IF(ISNUMBER(SEARCH("홍콩",C9)),"HK",IF(ISNUMBER(SEARCH("상해",C9)),"CN",IF(ISNUMBER(SEARCH("대만",C9)),"TW","홀세일")))) -> TW | B9: W9002 | C9: W대만 | D9: 내셔널지오그래픽 | E9: 2026 | F9: 봄 | G9: 용품 | H9: Original | I9: N261ABG060 | J9: 마일드백팩 | K9: 150 | L9: 25350000 | M9: 9736800 | N9: =IF(A9="제외",0,IF(OR(N(L9)<=0,N(M9)>N(L9)),N(M9)/가정!$B$4,N(L9))) -> 25350000 | O9: =IF(A9="제외","",IF(OR(N(L9)<=0,N(M9)>N(L9)),"택가보정(판매금액÷공급율)",""))
A10: =IF(OR(TRIM(C10)="",SUBSTITUTE(C10," ","")="소계"),"제외",IF(ISNUMBER(SEARCH("홍콩",C10)),"HK",IF(ISNUMBER(SEARCH("상해",C10)),"CN",IF(ISNUMBER(SEARCH("대만",C10)),"TW","홀세일")))) -> TW | B10: W9002 | C10: W대만 | D10: 내셔널지오그래픽 | E10: 2026 | F10: 봄 | G10: 용품 | H10: Original | I10: N261ABG070 | J10: 유니티백팩 | K10: 230 | L10: 38870000 | M10: 15003260 | N10: =IF(A10="제외",0,IF(OR(N(L10)<=0,N(M10)>N(L10)),N(M10)/가정!$B$4,N(L10))) -> 38870000 | O10: =IF(A10="제외","",IF(OR(N(L10)<=0,N(M10)>N(L10)),"택가보정(판매금액÷공급율)",""))
A11: =IF(OR(TRIM(C11)="",SUBSTITUTE(C11," ","")="소계"),"제외",IF(ISNUMBER(SEARCH("홍콩",C11)),"HK",IF(ISNUMBER(SEARCH("상해",C11)),"CN",IF(ISNUMBER(SEARCH("대만",C11)),"TW","홀세일")))) -> TW | B11: W9002 | C11: W대만 | D11: 내셔널지오그래픽 | E11: 2026 | F11: 봄 | G11: 용품 | H11: Original | I11: N261ABG080 | J11: 지오백팩 | K11: 80 | L11: 15120000 | M11: 5805920 | N11: =IF(A11="제외",0,IF(OR(N(L11)<=0,N(M11)>N(L11)),N(M11)/가정!$B$4,N(L11))) -> 15120000 | O11: =IF(A11="제외","",IF(OR(N(L11)<=0,N(M11)>N(L11)),"택가보정(판매금액÷공급율)",""))
A12: =IF(OR(TRIM(C12)="",SUBSTITUTE(C12," ","")="소계"),"제외",IF(ISNUMBER(SEARCH("홍콩",C12)),"HK",IF(ISNUMBER(SEARCH("상해",C12)),"CN",IF(ISNUMBER(SEARCH("대만",C12)),"TW","홀세일")))) -> TW | B12: W9002 | C12: W대만 | D12: 내셔널지오그래픽 | E12: 2026 | F12: 봄 | G12: 용품 | H12: Original | I12: N261ABG090 | J12: 브레이브백팩 | K12: 80 | L12: 14320000 | M12: 5505200 | N12: =IF(A12="제외",0,IF(OR(N(L12)<=0,N(M12)>N(L12)),N(M12)/가정!$B$4,N(L12))) -> 14320000 | O12: =IF(A12="제외","",IF(OR(N(L12)<=0,N(M12)>N(L12)),"택가보정(판매금액÷공급율)",""))
A13: =IF(OR(TRIM(C13)="",SUBSTITUTE(C13," ","")="소계"),"제외",IF(ISNUMBER(SEARCH("홍콩",C13)),"HK",IF(ISNUMBER(SEARCH("상해",C13)),"CN",IF(ISNUMBER(SEARCH("대만",C13)),"TW","홀세일")))) -> TW | B13: W9002 | C13: W대만 | D13: 내셔널지오그래픽 | E13: 2026 | F13: 봄 | G13: 용품 | H13: Original | I13: N261ABG100 | J13: 퓨전백팩 | K13: 80 | L13: 15120000 | M13: 5805920 | N13: =IF(A13="제외",0,IF(OR(N(L13)<=0,N(M13)>N(L13)),N(M13)/가정!$B$4,N(L13))) -> 15120000 | O13: =IF(A13="제외","",IF(OR(N(L13)<=0,N(M13)>N(L13)),"택가보정(판매금액÷공급율)",""))
A14: =IF(OR(TRIM(C14)="",SUBSTITUTE(C14," ","")="소계"),"제외",IF(ISNUMBER(SEARCH("홍콩",C14)),"HK",IF(ISNUMBER(SEARCH("상해",C14)),"CN",IF(ISNUMBER(SEARCH("대만",C14)),"TW","홀세일")))) -> TW | B14: W9002 | C14: W대만 | D14: 내셔널지오그래픽 | E14: 2026 | F14: 봄 | G14: 용품 | H14: 온라인 | I14: N261ABG520 | J14: (온)파치+백팩 | K14: 200 | L14: 35800000 | M14: 13711000 | N14: =IF(A14="제외",0,IF(OR(N(L14)<=0,N(M14)>N(L14)),N(M14)/가정!$B$4,N(L14))) -> 35800000 | O14: =IF(A14="제외","",IF(OR(N(L14)<=0,N(M14)>N(L14)),"택가보정(판매금액÷공급율)",""))
... A314: =IF(OR(TRIM(C314)="",SUBSTITUTE(C314," ","")="소계"),"제외",IF(ISNUMBER(SEARCH("홍콩",C314)),"HK",IF(ISNUMBER(SEARCH("상해",C314)),"CN",IF(ISNUMBER(SEARCH("대만",C314)),"TW","홀세일")))) -> TW | B314: W9002 | C314: W대만 | D314: 해외전용(NGA&MG) | E314: 2026 | F314: 4계절 | G314: 용품 | H314: Original | I314: O265ABG070 | J314: 시프트백팩_라이트 | K314: 200 | L314: 33800000 | M314: 13467400 | N314: =IF(A314="제외",0,IF(OR(N(L314)<=0,N(M314)>N(L314)),N(M314)/가정!$B$4,N(L314))) -> 33800000 | O314: =IF(A314="제외","",IF(OR(N(L314)<=0,N(M314)>N(L314)),"택가보정(판매금액÷공급율)",""))
A315: =IF(OR(TRIM(C315)="",SUBSTITUTE(C315," ","")="소계"),"제외",IF(ISNUMBER(SEARCH("홍콩",C315)),"HK",IF(ISNUMBER(SEARCH("상해",C315)),"CN",IF(ISNUMBER(SEARCH("대만",C315)),"TW","홀세일")))) -> 제외 | C315: 소 계 | K315: 104772 | L315: 13199098000 | M315: 4729436530 | N315: =IF(A315="제외",0,IF(OR(N(L315)<=0,N(M315)>N(L315)),N(M315)/가정!$B$4,N(L315))) -> 0 | O315: =IF(A315="제외","",IF(OR(N(L315)<=0,N(M315)>N(L315)),"택가보정(판매금액÷공급율)",""))
A316: =IF(OR(TRIM(C316)="",SUBSTITUTE(C316," ","")="소계"),"제외",IF(ISNUMBER(SEARCH("홍콩",C316)),"HK",IF(ISNUMBER(SEARCH("상해",C316)),"CN",IF(ISNUMBER(SEARCH("대만",C316)),"TW","홀세일")))) -> HK | B316: W9007 | C316: 홍콩법인 | D316: 내셔널지오그래픽 | E316: 2023 | F316: 4계절 | G316: 용품 | H316: 기타 | I316: N235APE498 | J316: (사)돗자리 | K316: 639 | L316: 639 | M316: 93933 | N316: =IF(A316="제외",0,IF(OR(N(L316)<=0,N(M316)>N(L316)),N(M316)/가정!$B$4,N(L316))) -> 284645.45 | O316: =IF(A316="제외","",IF(OR(N(L316)<=0,N(M316)>N(L316)),"택가보정(판매금액÷공급율)","")) -> 택가보정(판매금액÷공급율)
A317: =IF(OR(TRIM(C317)="",SUBSTITUTE(C317," ","")="소계"),"제외",IF(ISNUMBER(SEARCH("홍콩",C317)),"HK",IF(ISNUMBER(SEARCH("상해",C317)),"CN",IF(ISNUMBER(SEARCH("대만",C317)),"TW","홀세일")))) -> HK | B317: W9007 | C317: 홍콩법인 | D317: 내셔널지오그래픽 | E317: 2025 | F317: 4계절 | G317: 캐리어 | H317: 온라인 | I317: N255ASU450 | J317: (온) 부다페스트 캐리어 24 | K317: 180 | L317: 46620000 | M317: 23385780 | N317: =IF(A317="제외",0,IF(OR(N(L317)<=0,N(M317)>N(L317)),N(M317)/가정!$B$4,N(L317))) -> 46620000 | O317: =IF(A317="제외","",IF(OR(N(L317)<=0,N(M317)>N(L317)),"택가보정(판매금액÷공급율)",""))
A318: =IF(OR(TRIM(C318)="",SUBSTITUTE(C318," ","")="소계"),"제외",IF(ISNUMBER(SEARCH("홍콩",C318)),"HK",IF(ISNUMBER(SEARCH("상해",C318)),"CN",IF(ISNUMBER(SEARCH("대만",C318)),"TW","홀세일")))) -> HK | B318: W9007 | C318: 홍콩법인 | D318: 내셔널지오그래픽 | E318: 2025 | F318: 4계절 | G318: 기타 | H318: 홈쇼핑 | I318: N255APP510 | J318: (홈)풀데이 미니캐리어 V2 | K318: 250 | L318: 27250000 | M318: 6123750 | N318: =IF(A318="제외",0,IF(OR(N(L318)<=0,N(M318)>N(L318)),N(M318)/가정!$B$4,N(L318))) -> 27250000 | O318: =IF(A318="제외","",IF(OR(N(L318)<=0,N(M318)>N(L318)),"택가보정(판매금액÷공급율)",""))
A319: =IF(OR(TRIM(C319)="",SUBSTITUTE(C319," ","")="소계"),"제외",IF(ISNUMBER(SEARCH("홍콩",C319)),"HK",IF(ISNUMBER(SEARCH("상해",C319)),"CN",IF(ISNUMBER(SEARCH("대만",C319)),"TW","홀세일")))) -> HK | B319: W9007 | C319: 홍콩법인 | D319: 내셔널지오그래픽 | E319: 2025 | F319: 4계절 | G319: 신발 | H319: 온라인 | I319: N255USN312 | J319: (온) 스텀프 V3 | K319: 110 | L319: 11990000 | M319: 5092560 | N319: =IF(A319="제외",0,IF(OR(N(L319)<=0,N(M319)>N(L319)),N(M319)/가정!$B$4,N(L319))) -> 11990000 | O319: =IF(A319="제외","",IF(OR(N(L319)<=0,N(M319)>N(L319)),"택가보정(판매금액÷공급율)",""))
A320: =IF(OR(TRIM(C320)="",SUBSTITUTE(C320," ","")="소계"),"제외",IF(ISNUMBER(SEARCH("홍콩",C320)),"HK",IF(ISNUMBER(SEARCH("상해",C320)),"CN",IF(ISNUMBER(SEARCH("대만",C320)),"TW","홀세일")))) -> HK | B320: W9007 | C320: 홍콩법인 | D320: 내셔널지오그래픽 | E320: 2026 | F320: 봄 | G320: 의류 | H320: Original | I320: N261MPT510 | J320: NRN 유틸리티 베이직핏 조거 팬츠 | K320: 90 | L320: 12510000 | M320: 4539510 | N320: =IF(A320="제외",0,IF(OR(N(L320)<=0,N(M320)>N(L320)),N(M320)/가정!$B$4,N(L320))) -> 12510000 | O320: =IF(A320="제외","",IF(OR(N(L320)<=0,N(M320)>N(L320)),"택가보정(판매금액÷공급율)",""))
A321: =IF(OR(TRIM(C321)="",SUBSTITUTE(C321," ","")="소계"),"제외",IF(ISNUMBER(SEARCH("홍콩",C321)),"HK",IF(ISNUMBER(SEARCH("상해",C321)),"CN",IF(ISNUMBER(SEARCH("대만",C321)),"TW","홀세일")))) -> HK | B321: W9007 | C321: 홍콩법인 | D321: 내셔널지오그래픽 | E321: 2026 | F321: 봄 | G321: 의류 | H321: Urban | I321: N261MPT210 | J321: 아르마딜로 스트레치 베이직핏 스트레이트 팬츠 | K321: 110 | L321: 17490000 | M321: 6334130 | N321: =IF(A321="제외",0,IF(OR(N(L321)<=0,N(M321)>N(L321)),N(M321)/가정!$B$4,N(L321))) -> 17490000 | O321: =IF(A321="제외","",IF(OR(N(L321)<=0,N(M321)>N(L321)),"택가보정(판매금액÷공급율)",""))
A322: =IF(OR(TRIM(C322)="",SUBSTITUTE(C322," ","")="소계"),"제외",IF(ISNUMBER(SEARCH("홍콩",C322)),"HK",IF(ISNUMBER(SEARCH("상해",C322)),"CN",IF(ISNUMBER(SEARCH("대만",C322)),"TW","홀세일")))) -> HK | B322: W9007 | C322: 홍콩법인 | D322: 내셔널지오그래픽 | E322: 2026 | F322: 봄 | G322: 의류 | H322: Original | I322: N261MJP530 | J322: NRN 유틸리티 필드 자켓 | K322: 80 | L322: 22320000 | M322: 8576640 | N322: =IF(A322="제외",0,IF(OR(N(L322)<=0,N(M322)>N(L322)),N(M322)/가정!$B$4,N(L322))) -> 22320000 | O322: =IF(A322="제외","",IF(OR(N(L322)<=0,N(M322)>N(L322)),"택가보정(판매금액÷공급율)",""))
A323: =IF(OR(TRIM(C323)="",SUBSTITUTE(C323," ","")="소계"),"제외",IF(ISNUMBER(SEARCH("홍콩",C323)),"HK",IF(ISNUMBER(SEARCH("상해",C323)),"CN",IF(ISNUMBER(SEARCH("대만",C323)),"TW","홀세일")))) -> HK | B323: W9007 | C323: 홍콩법인 | D323: 내셔널지오그래픽 | E323: 2026 | F323: 봄 | G323: 의류 | H323: Urban | I323: N261MJP210 | J323: 어반시티 블루종 점퍼 | K323: 100 | L323: 21900000 | M323: 8433200 | N323: =IF(A323="제외",0,IF(OR(N(L323)<=0,N(M323)>N(L323)),N(M323)/가정!$B$4,N(L323))) -> 21900000 | O323: =IF(A323="제외","",IF(OR(N(L323)<=0,N(M323)>N(L323)),"택가보정(판매금액÷공급율)",""))
A324: =IF(OR(TRIM(C324)="",SUBSTITUTE(C324," ","")="소계"),"제외",IF(ISNUMBER(SEARCH("홍콩",C324)),"HK",IF(ISNUMBER(SEARCH("상해",C324)),"CN",IF(ISNUMBER(SEARCH("대만",C324)),"TW","홀세일")))) -> HK | B324: W9007 | C324: 홍콩법인 | D324: 내셔널지오그래픽 | E324: 2026 | F324: 봄 | G324: 의류 | H324: Urban | I324: N261MJP270 | J324: 3L 방수 후드형 자켓 | K324: 220 | L324: 56980000 | M324: 21847320 | N324: =IF(A324="제외",0,IF(OR(N(L324)<=0,N(M324)>N(L324)),N(M324)/가정!$B$4,N(L324))) -> 56980000 | O324: =IF(A324="제외","",IF(OR(N(L324)<=0,N(M324)>N(L324)),"택가보정(판매금액÷공급율)",""))
A325: =IF(OR(TRIM(C325)="",SUBSTITUTE(C325," ","")="소계"),"제외",IF(ISNUMBER(SEARCH("홍콩",C325)),"HK",IF(ISNUMBER(SEARCH("상해",C325)),"CN",IF(ISNUMBER(SEARCH("대만",C325)),"TW","홀세일")))) -> HK | B325: W9007 | C325: 홍콩법인 | D325: 내셔널지오그래픽 | E325: 2026 | F325: 봄 | G325: 의류 | H325: Original | I325: N261MFT510 | J325: NRN 유틸리티 세미오버핏 후드 풀집업 | K325: 70 | L325: 13930000 | M325: 5052600 | N325: =IF(A325="제외",0,IF(OR(N(L325)<=0,N(M325)>N(L325)),N(M325)/가정!$B$4,N(L325))) -> 13930000 | O325: =IF(A325="제외","",IF(OR(N(L325)<=0,N(M325)>N(L325)),"택가보정(판매금액÷공급율)",""))
A326: =IF(OR(TRIM(C326)="",SUBSTITUTE(C326," ","")="소계"),"제외",IF(ISNUMBER(SEARCH("홍콩",C326)),"HK",IF(ISNUMBER(SEARCH("상해",C326)),"CN",IF(ISNUMBER(SEARCH("대만",C326)),"TW","홀세일")))) -> HK | B326: W9007 | C326: 홍콩법인 | D326: 내셔널지오그래픽 | E326: 2026 | F326: 봄 | G326: 의류 | H326: Original | I326: N261UPT050 | J326: 마게이 베이직핏 조거 카고 팬츠 | K326: 210 | L326: 27090000 | M326: 9831360 | N326: =IF(A326="제외",0,IF(OR(N(L326)<=0,N(M326)>N(L326)),N(M326)/가정!$B$4,N(L326))) -> 27090000 | O326: =IF(A326="제외","",IF(OR(N(L326)<=0,N(M326)>N(L326)),"택가보정(판매금액÷공급율)",""))
A327: =IF(OR(TRIM(C327)="",SUBSTITUTE(C327," ","")="소계"),"제외",IF(ISNUMBER(SEARCH("홍콩",C327)),"HK",IF(ISNUMBER(SEARCH("상해",C327)),"CN",IF(ISNUMBER(SEARCH("대만",C327)),"TW","홀세일")))) -> HK | B327: W9007 | C327: 홍콩법인 | D327: 내셔널지오그래픽 | E327: 2026 | F327: 봄 | G327: 의류 | H327: Original | I327: N261UPT091 | J327: 리오 스트레치 베이직핏 조거 카고 팬츠 | K327: 300 | L327: 44700000 | M327: 16189800 | N327: =IF(A327="제외",0,IF(OR(N(L327)<=0,N(M327)>N(L327)),N(M327)/가정!$B$4,N(L327))) -> 44700000 | O327: =IF(A327="제외","",IF(OR(N(L327)<=0,N(M327)>N(L327)),"택가보정(판매금액÷공급율)",""))
... A622: =IF(OR(TRIM(C622)="",SUBSTITUTE(C622," ","")="소계"),"제외",IF(ISNUMBER(SEARCH("홍콩",C622)),"HK",IF(ISNUMBER(SEARCH("상해",C622)),"CN",IF(ISNUMBER(SEARCH("대만",C622)),"TW","홀세일")))) -> HK | B622: W9007 | C622: 홍콩법인 | D622: 해외전용(NGA&MG) | E622: 2026 | F622: 겨울 | G622: 의류 | H622: WOMEN | I622: O264WKT010 | J622: W' 스웨터 니트 가디건 | K622: 200 | L622: 31800000 | M622: 10296200 | N622: =IF(A622="제외",0,IF(OR(N(L622)<=0,N(M622)>N(L622)),N(M622)/가정!$B$4,N(L622))) -> 31800000 | O622: =IF(A622="제외","",IF(OR(N(L622)<=0,N(M622)>N(L622)),"택가보정(판매금액÷공급율)",""))
A623: =IF(OR(TRIM(C623)="",SUBSTITUTE(C623," ","")="소계"),"제외",IF(ISNUMBER(SEARCH("홍콩",C623)),"HK",IF(ISNUMBER(SEARCH("상해",C623)),"CN",IF(ISNUMBER(SEARCH("대만",C623)),"TW","홀세일")))) -> 제외 | C623: 소 계 | K623: 82933 | L623: 10327947639 | M623: 3688967198 | N623: =IF(A623="제외",0,IF(OR(N(L623)<=0,N(M623)>N(L623)),N(M623)/가정!$B$4,N(L623))) -> 0 | O623: =IF(A623="제외","",IF(OR(N(L623)<=0,N(M623)>N(L623)),"택가보정(판매금액÷공급율)",""))
A624: =IF(OR(TRIM(C624)="",SUBSTITUTE(C624," ","")="소계"),"제외",IF(ISNUMBER(SEARCH("홍콩",C624)),"HK",IF(ISNUMBER(SEARCH("상해",C624)),"CN",IF(ISNUMBER(SEARCH("대만",C624)),"TW","홀세일")))) -> CN | B624: WW002 | C624: 상해법인(덕나이철) | D624: 내셔널지오그래픽 | E624: 2025 | F624: 4계절 | G624: 캐리어 | H624: Original | I624: N255ASU050 | J624: 하바나 캐리어 20 | K624: 50 | L624: 10950000 | M624: 2449900 | N624: =IF(A624="제외",0,IF(OR(N(L624)<=0,N(M624)>N(L624)),N(M624)/가정!$B$4,N(L624))) -> 10950000 | O624: =IF(A624="제외","",IF(OR(N(L624)<=0,N(M624)>N(L624)),"택가보정(판매금액÷공급율)",""))
A625: =IF(OR(TRIM(C625)="",SUBSTITUTE(C625," ","")="소계"),"제외",IF(ISNUMBER(SEARCH("홍콩",C625)),"HK",IF(ISNUMBER(SEARCH("상해",C625)),"CN",IF(ISNUMBER(SEARCH("대만",C625)),"TW","홀세일")))) -> CN | B625: WW002 | C625: 상해법인(덕나이철) | D625: 내셔널지오그래픽 | E625: 2025 | F625: 4계절 | G625: 캐리어 | H625: 홈쇼핑 | I625: N255ASU930 | J625: (홈) 페이지 캐리어 SET | K625: 30 | L625: 10440000 | M625: 4182690 | N625: =IF(A625="제외",0,IF(OR(N(L625)<=0,N(M625)>N(L625)),N(M625)/가정!$B$4,N(L625))) -> 10440000 | O625: =IF(A625="제외","",IF(OR(N(L625)<=0,N(M625)>N(L625)),"택가보정(판매금액÷공급율)",""))
A626: =IF(OR(TRIM(C626)="",SUBSTITUTE(C626," ","")="소계"),"제외",IF(ISNUMBER(SEARCH("홍콩",C626)),"HK",IF(ISNUMBER(SEARCH("상해",C626)),"CN",IF(ISNUMBER(SEARCH("대만",C626)),"TW","홀세일")))) -> CN | B626: WW002 | C626: 상해법인(덕나이철) | D626: 내셔널지오그래픽 | E626: 2025 | F626: 4계절 | G626: 캐리어 | H626: 온라인 | I626: N255ASU440 | J626: (온) 부다페스트 캐리어 20 | K626: 25 | L626: 5725000 | M626: 1599875 | N626: =IF(A626="제외",0,IF(OR(N(L626)<=0,N(M626)>N(L626)),N(M626)/가정!$B$4,N(L626))) -> 5725000 | O626: =IF(A626="제외","",IF(OR(N(L626)<=0,N(M626)>N(L626)),"택가보정(판매금액÷공급율)",""))
A627: =IF(OR(TRIM(C627)="",SUBSTITUTE(C627," ","")="소계"),"제외",IF(ISNUMBER(SEARCH("홍콩",C627)),"HK",IF(ISNUMBER(SEARCH("상해",C627)),"CN",IF(ISNUMBER(SEARCH("대만",C627)),"TW","홀세일")))) -> CN | B627: WW002 | C627: 상해법인(덕나이철) | D627: 내셔널지오그래픽 | E627: 2025 | F627: 4계절 | G627: 캐리어 | H627: 온라인 | I627: N255ASU460 | J627: (온) 부다페스트 캐리어 28 | K627: 25 | L627: 7725000 | M627: 2223500 | N627: =IF(A627="제외",0,IF(OR(N(L627)<=0,N(M627)>N(L627)),N(M627)/가정!$B$4,N(L627))) -> 7725000 | O627: =IF(A627="제외","",IF(OR(N(L627)<=0,N(M627)>N(L627)),"택가보정(판매금액÷공급율)",""))
A628: =IF(OR(TRIM(C628)="",SUBSTITUTE(C628," ","")="소계"),"제외",IF(ISNUMBER(SEARCH("홍콩",C628)),"HK",IF(ISNUMBER(SEARCH("상해",C628)),"CN",IF(ISNUMBER(SEARCH("대만",C628)),"TW","홀세일")))) -> CN | B628: WW002 | C628: 상해법인(덕나이철) | D628: 내셔널지오그래픽 | E628: 2026 | F628: 봄 | G628: 용품 | H628: Original | I628: N261ABG090 | J628: 브레이브백팩 | K628: 280 | L628: 50120000 | M628: 14770280 | N628: =IF(A628="제외",0,IF(OR(N(L628)<=0,N(M628)>N(L628)),N(M628)/가정!$B$4,N(L628))) -> 50120000 | O628: =IF(A628="제외","",IF(OR(N(L628)<=0,N(M628)>N(L628)),"택가보정(판매금액÷공급율)",""))
A629: =IF(OR(TRIM(C629)="",SUBSTITUTE(C629," ","")="소계"),"제외",IF(ISNUMBER(SEARCH("홍콩",C629)),"HK",IF(ISNUMBER(SEARCH("상해",C629)),"CN",IF(ISNUMBER(SEARCH("대만",C629)),"TW","홀세일")))) -> CN | B629: WW002 | C629: 상해법인(덕나이철) | D629: 내셔널지오그래픽 | E629: 2026 | F629: 봄 | G629: 의류 | H629: Original | I629: N261MHD500 | J629: NRN 하이브리드 세미오버핏 후디 | K629: 2 | L629: 318000 | M629: 101018 | N629: =IF(A629="제외",0,IF(OR(N(L629)<=0,N(M629)>N(L629)),N(M629)/가정!$B$4,N(L629))) -> 318000 | O629: =IF(A629="제외","",IF(OR(N(L629)<=0,N(M629)>N(L629)),"택가보정(판매금액÷공급율)",""))
A630: =IF(OR(TRIM(C630)="",SUBSTITUTE(C630," ","")="소계"),"제외",IF(ISNUMBER(SEARCH("홍콩",C630)),"HK",IF(ISNUMBER(SEARCH("상해",C630)),"CN",IF(ISNUMBER(SEARCH("대만",C630)),"TW","홀세일")))) -> CN | B630: WW002 | C630: 상해법인(덕나이철) | D630: 내셔널지오그래픽 | E630: 2026 | F630: 봄 | G630: 의류 | H630: Original | I630: N261MSW500 | J630: NRN 하이브리드 세미오버핏 포켓 맨투맨 | K630: 4 | L630: 476000 | M630: 137176 | N630: =IF(A630="제외",0,IF(OR(N(L630)<=0,N(M630)>N(L630)),N(M630)/가정!$B$4,N(L630))) -> 476000 | O630: =IF(A630="제외","",IF(OR(N(L630)<=0,N(M630)>N(L630)),"택가보정(판매금액÷공급율)",""))
A631: =IF(OR(TRIM(C631)="",SUBSTITUTE(C631," ","")="소계"),"제외",IF(ISNUMBER(SEARCH("홍콩",C631)),"HK",IF(ISNUMBER(SEARCH("상해",C631)),"CN",IF(ISNUMBER(SEARCH("대만",C631)),"TW","홀세일")))) -> CN | B631: WW002 | C631: 상해법인(덕나이철) | D631: 내셔널지오그래픽 | E631: 2026 | F631: 봄 | G631: 의류 | H631: Original | I631: N261MSW510 | J631: NRN 유틸리티 포켓 세미오버핏 맨투맨 | K631: 100 | L631: 12900000 | M631: 3985800 | N631: =IF(A631="제외",0,IF(OR(N(L631)<=0,N(M631)>N(L631)),N(M631)/가정!$B$4,N(L631))) -> 12900000 | O631: =IF(A631="제외","",IF(OR(N(L631)<=0,N(M631)>N(L631)),"택가보정(판매금액÷공급율)",""))
A632: =IF(OR(TRIM(C632)="",SUBSTITUTE(C632," ","")="소계"),"제외",IF(ISNUMBER(SEARCH("홍콩",C632)),"HK",IF(ISNUMBER(SEARCH("상해",C632)),"CN",IF(ISNUMBER(SEARCH("대만",C632)),"TW","홀세일")))) -> CN | B632: WW002 | C632: 상해법인(덕나이철) | D632: 내셔널지오그래픽 | E632: 2026 | F632: 봄 | G632: 의류 | H632: Urban | I632: N261MTS210 | J632: 와플 긴팔 티셔츠 | K632: 306 | L632: 24174000 | M632: 4515521 | N632: =IF(A632="제외",0,IF(OR(N(L632)<=0,N(M632)>N(L632)),N(M632)/가정!$B$4,N(L632))) -> 24174000 | O632: =IF(A632="제외","",IF(OR(N(L632)<=0,N(M632)>N(L632)),"택가보정(판매금액÷공급율)",""))
A633: =IF(OR(TRIM(C633)="",SUBSTITUTE(C633," ","")="소계"),"제외",IF(ISNUMBER(SEARCH("홍콩",C633)),"HK",IF(ISNUMBER(SEARCH("상해",C633)),"CN",IF(ISNUMBER(SEARCH("대만",C633)),"TW","홀세일")))) -> CN | B633: WW002 | C633: 상해법인(덕나이철) | D633: 내셔널지오그래픽 | E633: 2026 | F633: 봄 | G633: 의류 | H633: Original | I633: N261UJP060 | J633: 오르카 타슬란 후드 아웃포켓 점퍼 | K633: 260 | L633: 51740000 | M633: 11635000 | N633: =IF(A633="제외",0,IF(OR(N(L633)<=0,N(M633)>N(L633)),N(M633)/가정!$B$4,N(L633))) -> 51740000 | O633: =IF(A633="제외","",IF(OR(N(L633)<=0,N(M633)>N(L633)),"택가보정(판매금액÷공급율)",""))
...

Sheet RAW_2026
A1: 차수(C) | B1: 구분 | C1: 스타일(L) | D1: 수량(P) | E1: 택가 KRW(AB) | F1: 한국원가 KRW(AH) | G1: 배수(S) | H1: 해외공급가 USD(AL) | I1: 중국공급가(BB) | J1: 택가(보정) | K1: 원가(보정) | L1: 공급단가 KRW | M1: 택가금액 | N1: 원가금액 | O1: TNH 공급금액 | P1: 보정내역
A2: 100 | B2: =IF(A2="100","HK",IF(A2="200","CN",IF(A2="300","TW","홀세일"))) -> HK | C2: N261ABG010 | D2: 240 | E2: 169000 | F2: 39504 | G2: 3.64 | H2: 44.9 | J2: =IF(N(E2)>0,E2,IF(N(F2)>0,F2*가정!$B$5,0)) -> 169000 | K2: =IF(N(F2)>0,F2,IF(N(E2)>0,E2/가정!$B$5,0)) -> 39504 | L2: =IF(B2="CN",IF(N(I2)>0,I2*가정!$B$3,K2*(1+가정!$B$6)),IF(N(H2)>0,H2*가정!$B$3,J2*가정!$B$4)) -> 61188.822 | M2: =D2*J2 -> 40560000 | N2: =D2*K2 -> 9480960 | O2: =D2*L2 -> 14685317 | P2: =TRIM(IF(N(E2)<=0,"택가보정 ","")&IF(N(F2)<=0,"원가보정 ","")&IF(AND(B2<>"CN",N(H2)<=0),"공급가보정 ","")&IF(AND(B2="CN",N(I2)<=0),"중국공급가=원가+마진 ",""))
A3: 200 | B3: =IF(A3="100","HK",IF(A3="200","CN",IF(A3="300","TW","홀세일"))) -> CN | C3: N261ABG010 | D3: 1336 | E3: 169000 | F3: 39504 | G3: 3.64 | H3: 44.9 | J3: =IF(N(E3)>0,E3,IF(N(F3)>0,F3*가정!$B$5,0)) -> 169000 | K3: =IF(N(F3)>0,F3,IF(N(E3)>0,E3/가정!$B$5,0)) -> 39504 | L3: =IF(B3="CN",IF(N(I3)>0,I3*가정!$B$3,K3*(1+가정!$B$6)),IF(N(H3)>0,H3*가정!$B$3,J3*가정!$B$4)) -> 41479.2 | M3: =D3*J3 -> 225784000 | N3: =D3*K3 -> 52777344 | O3: =D3*L3 -> 55416211 | P3: =TRIM(IF(N(E3)<=0,"택가보정 ","")&IF(N(F3)<=0,"원가보정 ","")&IF(AND(B3<>"CN",N(H3)<=0),"공급가보정 ","")&IF(AND(B3="CN",N(I3)<=0),"중국공급가=원가+마진 ","")) -> 중국공급가=원가+마진
A4: 300 | B4: =IF(A4="100","HK",IF(A4="200","CN",IF(A4="300","TW","홀세일"))) -> TW | C4: N261ABG010 | D4: 150 | E4: 169000 | F4: 39504 | G4: 3.64 | H4: 44.9 | J4: =IF(N(E4)>0,E4,IF(N(F4)>0,F4*가정!$B$5,0)) -> 169000 | K4: =IF(N(F4)>0,F4,IF(N(E4)>0,E4/가정!$B$5,0)) -> 39504 | L4: =IF(B4="CN",IF(N(I4)>0,I4*가정!$B$3,K4*(1+가정!$B$6)),IF(N(H4)>0,H4*가정!$B$3,J4*가정!$B$4)) -> 61188.822 | M4: =D4*J4 -> 25350000 | N4: =D4*K4 -> 5925600 | O4: =D4*L4 -> 9178323.3 | P4: =TRIM(IF(N(E4)<=0,"택가보정 ","")&IF(N(F4)<=0,"원가보정 ","")&IF(AND(B4<>"CN",N(H4)<=0),"공급가보정 ","")&IF(AND(B4="CN",N(I4)<=0),"중국공급가=원가+마진 ",""))
A5: 500 | B5: =IF(A5="100","HK",IF(A5="200","CN",IF(A5="300","TW","홀세일"))) -> 홀세일 | C5: N261ABG010 | D5: 25 | E5: 169000 | F5: 39504 | G5: 3.64 | H5: 44.9 | J5: =IF(N(E5)>0,E5,IF(N(F5)>0,F5*가정!$B$5,0)) -> 169000 | K5: =IF(N(F5)>0,F5,IF(N(E5)>0,E5/가정!$B$5,0)) -> 39504 | L5: =IF(B5="CN",IF(N(I5)>0,I5*가정!$B$3,K5*(1+가정!$B$6)),IF(N(H5)>0,H5*가정!$B$3,J5*가정!$B$4)) -> 61188.822 | M5: =D5*J5 -> 4225000 | N5: =D5*K5 -> 987600 | O5: =D5*L5 -> 1529720.6 | P5: =TRIM(IF(N(E5)<=0,"택가보정 ","")&IF(N(F5)<=0,"원가보정 ","")&IF(AND(B5<>"CN",N(H5)<=0),"공급가보정 ","")&IF(AND(B5="CN",N(I5)<=0),"중국공급가=원가+마진 ",""))
A6: 600 | B6: =IF(A6="100","HK",IF(A6="200","CN",IF(A6="300","TW","홀세일"))) -> 홀세일 | C6: N261ABG010 | D6: 50 | E6: 169000 | F6: 39504 | G6: 3.64 | H6: 44.9 | J6: =IF(N(E6)>0,E6,IF(N(F6)>0,F6*가정!$B$5,0)) -> 169000 | K6: =IF(N(F6)>0,F6,IF(N(E6)>0,E6/가정!$B$5,0)) -> 39504 | L6: =IF(B6="CN",IF(N(I6)>0,I6*가정!$B$3,K6*(1+가정!$B$6)),IF(N(H6)>0,H6*가정!$B$3,J6*가정!$B$4)) -> 61188.822 | M6: =D6*J6 -> 8450000 | N6: =D6*K6 -> 1975200 | O6: =D6*L6 -> 3059441.1 | P6: =TRIM(IF(N(E6)<=0,"택가보정 ","")&IF(N(F6)<=0,"원가보정 ","")&IF(AND(B6<>"CN",N(H6)<=0),"공급가보정 ","")&IF(AND(B6="CN",N(I6)<=0),"중국공급가=원가+마진 ",""))
A7: 800 | B7: =IF(A7="100","HK",IF(A7="200","CN",IF(A7="300","TW","홀세일"))) -> 홀세일 | C7: N261ABG010 | D7: 30 | E7: 169000 | F7: 39504 | G7: 3.64 | H7: 44.9 | J7: =IF(N(E7)>0,E7,IF(N(F7)>0,F7*가정!$B$5,0)) -> 169000 | K7: =IF(N(F7)>0,F7,IF(N(E7)>0,E7/가정!$B$5,0)) -> 39504 | L7: =IF(B7="CN",IF(N(I7)>0,I7*가정!$B$3,K7*(1+가정!$B$6)),IF(N(H7)>0,H7*가정!$B$3,J7*가정!$B$4)) -> 61188.822 | M7: =D7*J7 -> 5070000 | N7: =D7*K7 -> 1185120 | O7: =D7*L7 -> 1835664.7 | P7: =TRIM(IF(N(E7)<=0,"택가보정 ","")&IF(N(F7)<=0,"원가보정 ","")&IF(AND(B7<>"CN",N(H7)<=0),"공급가보정 ","")&IF(AND(B7="CN",N(I7)<=0),"중국공급가=원가+마진 ",""))
A8: 810 | B8: =IF(A8="100","HK",IF(A8="200","CN",IF(A8="300","TW","홀세일"))) -> 홀세일 | C8: N261ABG010 | D8: 36 | E8: 169000 | F8: 39504 | G8: 3.64 | H8: 44.9 | J8: =IF(N(E8)>0,E8,IF(N(F8)>0,F8*가정!$B$5,0)) -> 169000 | K8: =IF(N(F8)>0,F8,IF(N(E8)>0,E8/가정!$B$5,0)) -> 39504 | L8: =IF(B8="CN",IF(N(I8)>0,I8*가정!$B$3,K8*(1+가정!$B$6)),IF(N(H8)>0,H8*가정!$B$3,J8*가정!$B$4)) -> 61188.822 | M8: =D8*J8 -> 6084000 | N8: =D8*K8 -> 1422144 | O8: =D8*L8 -> 2202797.6 | P8: =TRIM(IF(N(E8)<=0,"택가보정 ","")&IF(N(F8)<=0,"원가보정 ","")&IF(AND(B8<>"CN",N(H8)<=0),"공급가보정 ","")&IF(AND(B8="CN",N(I8)<=0),"중국공급가=원가+마진 ",""))
A9: 830 | B9: =IF(A9="100","HK",IF(A9="200","CN",IF(A9="300","TW","홀세일"))) -> 홀세일 | C9: N261ABG010 | D9: 30 | E9: 169000 | F9: 39504 | G9: 3.64 | H9: 44.9 | J9: =IF(N(E9)>0,E9,IF(N(F9)>0,F9*가정!$B$5,0)) -> 169000 | K9: =IF(N(F9)>0,F9,IF(N(E9)>0,E9/가정!$B$5,0)) -> 39504 | L9: =IF(B9="CN",IF(N(I9)>0,I9*가정!$B$3,K9*(1+가정!$B$6)),IF(N(H9)>0,H9*가정!$B$3,J9*가정!$B$4)) -> 61188.822 | M9: =D9*J9 -> 5070000 | N9: =D9*K9 -> 1185120 | O9: =D9*L9 -> 1835664.7 | P9: =TRIM(IF(N(E9)<=0,"택가보정 ","")&IF(N(F9)<=0,"원가보정 ","")&IF(AND(B9<>"CN",N(H9)<=0),"공급가보정 ","")&IF(AND(B9="CN",N(I9)<=0),"중국공급가=원가+마진 ",""))
A10: 100 | B10: =IF(A10="100","HK",IF(A10="200","CN",IF(A10="300","TW","홀세일"))) -> HK | C10: N261ABG020 | D10: 160 | E10: 179000 | F10: 42278 | G10: 3.6 | H10: 47.6 | J10: =IF(N(E10)>0,E10,IF(N(F10)>0,F10*가정!$B$5,0)) -> 179000 | K10: =IF(N(F10)>0,F10,IF(N(E10)>0,E10/가정!$B$5,0)) -> 42278 | L10: =IF(B10="CN",IF(N(I10)>0,I10*가정!$B$3,K10*(1+가정!$B$6)),IF(N(H10)>0,H10*가정!$B$3,J10*가정!$B$4)) -> 64868.328 | M10: =D10*J10 -> 28640000 | N10: =D10*K10 -> 6764480 | O10: =D10*L10 -> 10378932 | P10: =TRIM(IF(N(E10)<=0,"택가보정 ","")&IF(N(F10)<=0,"원가보정 ","")&IF(AND(B10<>"CN",N(H10)<=0),"공급가보정 ","")&IF(AND(B10="CN",N(I10)<=0),"중국공급가=원가+마진 ",""))
A11: 300 | B11: =IF(A11="100","HK",IF(A11="200","CN",IF(A11="300","TW","홀세일"))) -> TW | C11: N261ABG020 | D11: 250 | E11: 179000 | F11: 42278 | G11: 3.6 | H11: 47.6 | J11: =IF(N(E11)>0,E11,IF(N(F11)>0,F11*가정!$B$5,0)) -> 179000 | K11: =IF(N(F11)>0,F11,IF(N(E11)>0,E11/가정!$B$5,0)) -> 42278 | L11: =IF(B11="CN",IF(N(I11)>0,I11*가정!$B$3,K11*(1+가정!$B$6)),IF(N(H11)>0,H11*가정!$B$3,J11*가정!$B$4)) -> 64868.328 | M11: =D11*J11 -> 44750000 | N11: =D11*K11 -> 10569500 | O11: =D11*L11 -> 16217082 | P11: =TRIM(IF(N(E11)<=0,"택가보정 ","")&IF(N(F11)<=0,"원가보정 ","")&IF(AND(B11<>"CN",N(H11)<=0),"공급가보정 ","")&IF(AND(B11="CN",N(I11)<=0),"중국공급가=원가+마진 ",""))
A12: 600 | B12: =IF(A12="100","HK",IF(A12="200","CN",IF(A12="300","TW","홀세일"))) -> 홀세일 | C12: N261ABG020 | D12: 50 | E12: 179000 | F12: 42278 | G12: 3.6 | H12: 47.6 | J12: =IF(N(E12)>0,E12,IF(N(F12)>0,F12*가정!$B$5,0)) -> 179000 | K12: =IF(N(F12)>0,F12,IF(N(E12)>0,E12/가정!$B$5,0)) -> 42278 | L12: =IF(B12="CN",IF(N(I12)>0,I12*가정!$B$3,K12*(1+가정!$B$6)),IF(N(H12)>0,H12*가정!$B$3,J12*가정!$B$4)) -> 64868.328 | M12: =D12*J12 -> 8950000 | N12: =D12*K12 -> 2113900 | O12: =D12*L12 -> 3243416.4 | P12: =TRIM(IF(N(E12)<=0,"택가보정 ","")&IF(N(F12)<=0,"원가보정 ","")&IF(AND(B12<>"CN",N(H12)<=0),"공급가보정 ","")&IF(AND(B12="CN",N(I12)<=0),"중국공급가=원가+마진 ",""))
