Workbook

Sheet 요약
A1: 2027 TNH 사업계획 — 요약
A2: 노란 칸 = 입력, 나머지는 수식. 단위: 억원.
A3: ="2027 TNH 매출 "&TEXT(G22,"0.0")&"억 (2026 예상 "&TEXT(D12,"0.0")&"억 대비 "&TEXT(IF(D12=0,0,G22/D12-1),"+0.0%;-0.0%")&") · 이익 "&TEXT(H22,"0.0")&"억 · 이익률 "&TEXT(I22,"0.0%") -> 2027 TNH 매출 153.8억 (2026 예상 188.2억 대비 -18.3%) · 이익 32.2억 · 이익률 20.9%
A4: =IF(MAX(ABS(N40-1),ABS(N41-1),ABS(N42-1),ABS(N43-1))>0.0005,"⚠ ⑤ 월별 비중 합계가 100%가 아닙니다","")
A6: ① 2026 예상매출
A7: 구분 | B7: 현재까지 매출 (1/1~10/22) | C7: 잔여기간 예상 | D7: 최종 예상매출 | F7: 현재까지 이익 | G7: 잔여기간 이익 | H7: 최종 예상 이익 | I7: 이익률
A8: 홍콩 | B8: =SUMIFS(RAW_판매펀칭!$M:$M,RAW_판매펀칭!$A:$A,"HK")/10^8 -> 37.00268 | C8: =SUMIFS(RAW_2026!$S:$S,RAW_2026!$B:$B,"HK")/10^8 -> 9.169842 | D8: =B8+C8 -> 46.172522 | F8: =B8-SUMIFS(RAW_판매펀칭!$N:$N,RAW_판매펀칭!$A:$A,"HK")/10^8/$F$27 -> 11.092101 | G8: =C8-SUMIFS(RAW_2026!$T:$T,RAW_2026!$B:$B,"HK")/10^8/$F$27 -> 2.5809996 | H8: =F8+G8 -> 13.6731 | I8: =IF(D8=0,0,H8/D8) -> 0.29613068
A9: 중국 | B9: =SUMIFS(RAW_판매펀칭!$M:$M,RAW_판매펀칭!$A:$A,"CN")/10^8 -> 36.112696 | C9: =SUMIFS(RAW_2026!$S:$S,RAW_2026!$B:$B,"CN")/10^8 -> 10.861692 | D9: =B9+C9 -> 46.974388 | F9: =B9-SUMIFS(RAW_판매펀칭!$N:$N,RAW_판매펀칭!$A:$A,"CN")/10^8/$F$27 -> 5.3436965 | G9: =C9-SUMIFS(RAW_2026!$T:$T,RAW_2026!$B:$B,"CN")/10^8/$F$27 -> 0.70191817 | H9: =F9+G9 -> 6.0456146 | I9: =IF(D9=0,0,H9/D9) -> 0.12870023
A10: 대만 | B10: =SUMIFS(RAW_판매펀칭!$M:$M,RAW_판매펀칭!$A:$A,"TW")/10^8 -> 47.746957 | C10: =SUMIFS(RAW_2026!$S:$S,RAW_2026!$B:$B,"TW")/10^8 -> 13.987223 | D10: =B10+C10 -> 61.73418 | F10: =B10-SUMIFS(RAW_판매펀칭!$N:$N,RAW_판매펀칭!$A:$A,"TW")/10^8/$F$27 -> 14.456812 | G10: =C10-SUMIFS(RAW_2026!$T:$T,RAW_2026!$B:$B,"TW")/10^8/$F$27 -> 3.7502104 | H10: =F10+G10 -> 18.207023 | I10: =IF(D10=0,0,H10/D10) -> 0.29492613
A11: 홀세일 | B11: =SUMIFS(RAW_판매펀칭!$M:$M,RAW_판매펀칭!$A:$A,"홀세일")/10^8 -> 27.692315 | C11: =SUMIFS(RAW_2026!$S:$S,RAW_2026!$B:$B,"홀세일")/10^8 -> 5.5793615 | D11: =B11+C11 -> 33.271676 | F11: =B11-SUMIFS(RAW_판매펀칭!$N:$N,RAW_판매펀칭!$A:$A,"홀세일")/10^8/$F$27 -> 9.5372572 | G11: =C11-SUMIFS(RAW_2026!$T:$T,RAW_2026!$B:$B,"홀세일")/10^8/$F$27 -> 1.421934 | H11: =F11+G11 -> 10.959191 | I11: =IF(D11=0,0,H11/D11) -> 0.329385
A12: TNH 합계 | B12: =SUM(B8:B11) -> 148.55465 | C12: =SUM(C8:C11) -> 39.598118 | D12: =SUM(D8:D11) -> 188.15277 | F12: =SUM(F8:F11) -> 40.429867 | G12: =SUM(G8:G11) -> 8.4550621 | H12: =SUM(H8:H11) -> 48.884929 | I12: =IF(D12=0,0,H12/D12) -> 0.2598151
A13: ※ 현재까지 = 판매펀칭 출고 / 잔여 = 수주 − 출고 (태국·인도네시아·디즈니크루즈는 26FW 진척률 0%로 제외)
A14: ="※ 실제 발주수량 대조: 수주(중복 제거 후) vs 발주 — 불일치 "&COUNTIF(RAW_2026!X:X,">0")&"건 / 수량 차이 "&TEXT(SUM(RAW_2026!X:X),"#,##0")&" (RAW_발주)" -> ※ 실제 발주수량 대조: 수주(중복 제거 후) vs 발주 — 불일치 0건 / 수량 차이 0 (RAW_발주)
A15: ② 2027 계획
A16: 구분 | B16: 법인 매출목표 | C16: 정판율 | D16: 할인율 | E16: 법인 판매배수 (법인택가÷TNH 공급가) ★입력 | F16: 법인 입고 택가 | G16: 2027 TNH 매출 (원화) | H16: 2027 TNH 이익 | I16: 이익률 | J16: 공급율 (한국택가 대비, 원가 환산용)
A17: 홍콩 | B17: 180 | C17: 0.65 | D17: 0.1 | E17: 4 | F17: =IF(OR(C17=0,D17=1),0,B17*$C$27/(1-D17)/C17) -> 123.07692 | G17: =IF(OR(E17=0,$G$27=0),0,F17/E17*$H$27/$G$27) -> 31.768531 | H17: =IF(OR(J17=0,E17=0),0,G17-F17/E17/J17/$F$27) -> 8.4585082 | I17: =IF(G17=0,0,H17/G17) -> 0.2662543 | J17: =$D$27 -> 0.33
A18: 중국 | B18: 300 | C18: 0.65 | D18: 0.1 | E18: 5 | F18: =IF(OR(C18=0,D18=1),0,B18*$C$27/(1-D18)/C18) -> 205.12821 | G18: =IF(OR(E18=0,$G$27=0),0,F18/E18*$H$27/$G$27) -> 42.358042 | H18: =IF(OR(J18=0,E18=0),0,G18-F18/E18/J18/$F$27) -> 3.2860029 | I18: =IF(G18=0,0,H18/G18) -> 0.077576836 | J18: =(1+$E$27)/$F$27 -> 0.2625
A19: 대만 | B19: 262 | C19: 0.65 | D19: 0.1 | E19: 4 | F19: =IF(OR(C19=0,D19=1),0,B19*$C$27/(1-D19)/C19) -> 179.1453 | G19: =IF(OR(E19=0,$G$27=0),0,F19/E19*$H$27/$G$27) -> 46.240862 | H19: =IF(OR(J19=0,E19=0),0,G19-F19/E19/J19/$F$27) -> 12.311829 | I19: =IF(G19=0,0,H19/G19) -> 0.2662543 | J19: =$D$27 -> 0.33
A20: 법인 소계 | B20: =SUM(B17:B19) -> 742 | F20: =SUM(F17:F19) -> 507.35043 | G20: =SUM(G17:G19) -> 120.36744 | H20: =SUM(H17:H19) -> 24.05634 | I20: =IF(G20=0,0,H20/G20) -> 0.19985754
A21: 홀세일 (TNH 매출 입력) | B21: - | C21: - | D21: - | E21: - | F21: - | G21: 33.4 | H21: =IF(J21=0,0,G21-G21/J21/$F$27) -> 8.0969697 | I21: =IF(G21=0,0,H21/G21) -> 0.24242424 | J21: =$D$27 -> 0.33
A22: TNH 합계 | B22: - | C22: - | D22: - | E22: - | F22: =F20 -> 507.35043 | G22: =G20+G21 -> 153.76744 | H22: =H20+H21 -> 32.153309 | I22: =IF(G22=0,0,H22/G22) -> 0.2091035 | J22: -
A23: ※ 2027 TNH 매출 = 법인 입고 택가 ÷ 법인 판매배수 × (2027 적용 환율 ÷ 2026 적용 환율), 법인 입고 택가 = 목표 × 정상비중 ÷ (1−할인율) ÷ 정판율. 원가 = 공급가 ÷ 공급율 ÷ 택가배수
A25: ③ 공통 가정
B26: 이월제품 비중 | C26: 정상제품 비중 (자동) | D26: 공급율 (홍콩·대만·홀세일, 한국택가 대비) | E26: 중국 공급 마진 (한국원가 +) | F26: 택가배수 (한국택가÷원가) | G26: 2026 잔여기간 적용 환율 (달러 환산 기준) | H26: 2027 적용 환율
A27: 입력값 | B27: 0.6 | C27: =1-B27 -> 0.4 | D27: 0.33 | E27: 0.05 | F27: 4 | G27: 1320 | H27: 1362.87
A29: ④ 2026 예상 vs 2027 계획 (TNH 매출·이익)
A30: 구분 | B30: 2026 예상 | C30: 2027 계획 | D30: 증감 | E30: 증감률 | G30: 2026 이익 | H30: 2027 이익 | I30: 증감 | J30: 증감률 | K30: 2026 이익률 | L30: 2027 이익률
A31: 홍콩 | B31: =D8 -> 46.172522 | C31: =G17 -> 31.768531 | D31: =C31-B31 -> -14.403991 | E31: =IF(B31=0,0,D31/B31) -> -0.31196023 | G31: =H8 -> 13.6731 | H31: =H17 -> 8.4585082 | I31: =H31-G31 -> -5.2145923 | J31: =IF(G31=0,0,I31/G31) -> -0.38137599 | K31: =IF(B31=0,0,G31/B31) -> 0.29613068 | L31: =IF(C31=0,0,H31/C31) -> 0.2662543
A32: 중국 | B32: =D9 -> 46.974388 | C32: =G18 -> 42.358042 | D32: =C32-B32 -> -4.6163465 | E32: =IF(B32=0,0,D32/B32) -> -0.098273691 | G32: =H9 -> 6.0456146 | H32: =H18 -> 3.2860029 | I32: =H32-G32 -> -2.7596117 | J32: =IF(G32=0,0,I32/G32) -> -0.45646504 | K32: =IF(B32=0,0,G32/B32) -> 0.12870023 | L32: =IF(C32=0,0,H32/C32) -> 0.077576836
A33: 대만 | B33: =D10 -> 61.73418 | C33: =G19 -> 46.240862 | D33: =C33-B33 -> -15.493318 | E33: =IF(B33=0,0,D33/B33) -> -0.25096823 | G33: =H10 -> 18.207023 | H33: =H19 -> 12.311829 | I33: =H33-G33 -> -5.8951943 | J33: =IF(G33=0,0,I33/G33) -> -0.32378683 | K33: =IF(B33=0,0,G33/B33) -> 0.29492613 | L33: =IF(C33=0,0,H33/C33) -> 0.2662543
A34: 법인 소계 | B34: =SUM(B31:B33) -> 154.88109 | C34: =SUM(C31:C33) -> 120.36744 | D34: =C34-B34 -> -34.513655 | E34: =IF(B34=0,0,D34/B34) -> -0.22283969 | G34: =SUM(G31:G33) -> 37.925738 | H34: =SUM(H31:H33) -> 24.05634 | I34: =H34-G34 -> -13.869398 | J34: =IF(G34=0,0,I34/G34) -> -0.36569884 | K34: =IF(B34=0,0,G34/B34) -> 0.24487003 | L34: =IF(C34=0,0,H34/C34) -> 0.19985754
A35: 홀세일 | B35: =D11 -> 33.271676 | C35: =G21 -> 33.4 | D35: =C35-B35 -> 0.12832385 | E35: =IF(B35=0,0,D35/B35) -> 0.0038568496 | G35: =H11 -> 10.959191 | H35: =H21 -> 8.0969697 | I35: =H35-G35 -> -2.8622215 | J35: =IF(G35=0,0,I35/G35) -> -0.26117087 | K35: =IF(B35=0,0,G35/B35) -> 0.329385 | L35: =IF(C35=0,0,H35/C35) -> 0.24242424
A36: TNH 합계 | B36: =B34+B35 -> 188.15277 | C36: =C34+C35 -> 153.76744 | D36: =C36-B36 -> -34.385331 | E36: =IF(B36=0,0,D36/B36) -> -0.18275219 | G36: =G34+G35 -> 48.884929 | H36: =H34+H35 -> 32.153309 | I36: =H36-G36 -> -16.73162 | J36: =IF(G36=0,0,I36/G36) -> -0.3422654 | K36: =IF(B36=0,0,G36/B36) -> 0.2598151 | L36: =IF(C36=0,0,H36/C36) -> 0.2091035
A38: ⑤ 2027 월별 비중 (입력)
A39: 구분 | B39: 1월 | C39: 2월 | D39: 3월 | E39: 4월 | F39: 5월 | G39: 6월 | H39: 7월 | I39: 8월 | J39: 9월 | K39: 10월 | L39: 11월 | M39: 12월 | N39: 합계
A40: 홍콩 | B40: 0.144 | C40: 0.113 | D40: 0.07 | E40: 0.063 | F40: 0.065 | G40: 0.074 | H40: 0.055 | I40: 0.059 | J40: 0.046 | K40: 0.076 | L40: 0.109 | M40: 0.126 | N40: =SUM(B40:M40) -> 1
A41: 중국 | B41: 0.142 | C41: 0.081 | D41: 0.046 | E41: 0.053 | F41: 0.071 | G41: 0.065 | H41: 0.055 | I41: 0.063 | J41: 0.066 | K41: 0.129 | L41: 0.099 | M41: 0.13 | N41: =SUM(B41:M41) -> 1
A42: 대만 | B42: 0.129 | C42: 0.112 | D42: 0.06 | E42: 0.076 | F42: 0.078 | G42: 0.062 | H42: 0.05 | I42: 0.053 | J42: 0.064 | K42: 0.081 | L42: 0.126 | M42: 0.109 | N42: =SUM(B42:M42) -> 1
A43: 홀세일 | B43: 0.137 | C43: 0.106 | D43: 0.061 | E43: 0.067 | F43: 0.072 | G43: 0.066 | H43: 0.053 | I43: 0.057 | J43: 0.059 | K43: 0.089 | L43: 0.115 | M43: 0.118 | N43: =SUM(B43:M43) -> 1
A45: ⑥ 2027 월별 TNH 매출
...

Sheet 로직설명
A1: 2027 TNH 사업계획 — 계산 로직
A3: 1. 2026 예상매출
A4: 현재까지 매출 = RAW_판매펀칭(본사판매, TNH→법인·홀세일, 1/1~10/22) 판매금액 합계. 홍콩법인=HK, 상해법인=CN, W대만=TW, 그 외=홀세일, 소계행 제외
A5: 잔여기간 예상 = 수주(RAW_2026) − 출고(RAW_판매펀칭). 같은 (차수, 스타일)의 출고수량을 수주수량에서 차감하고, 출고가 더 많으면 0, 수주 없는 출고(스팟·이월)는 차감하지 않음 → 남은 수량 × 수주 공급단가
A6: 태국(차수 500)·인도네시아(800)·디즈니크루즈(810)는 26FW 진척률 0%(사업종료·수입 지연·오더 캔슬)로 잔여 0. 차수↔매장 연결은 수량 일치 대조로 추정한 값이라 확인 필요
A7: 최종 예상매출 = 현재까지 매출 + 잔여기간 예상. 2026 이익 = 매출 − 원가 (원가 = 택가 ÷ 택가배수 4; 택가는 현재까지=판매펀칭 TAG(보정), 잔여=수주 잔여 택가)
A8: 수주 중복 제거: RAW_2026에서 차수·스타일·수량이 모두 같은 행이 반복되면(배치명만 다른 중복 입력) 첫 행만 인정하고 나머지는 제외 (RAW_2026 V·W열). 실제 발주수량(RAW_발주)과 (차수그룹, 스타일)별로 대조해 전 건 일치 확인
A9: 2. 2027 계획
A10: 정상제품 매출 = 법인 매출목표 × 정상비중 (이월제품은 TNH 공급 대상이 아님)
A11: 법인 입고 택가 = 정상제품 매출 ÷ (1 − 할인율) ÷ 정판율. TNH 공급가(원화) = 법인 입고 택가 ÷ 법인 판매배수 ※ 법인은 자기 매입가(TNH 공급가)의 약 4배(홍콩·대만)·5배(중국)로 판매
A12: TNH 매출(원화) = 법인 입고 택가 ÷ 법인 판매배수(= TNH 공급가) × (2027 적용 환율 ÷ 2026 적용 환율). TNH는 법인에 USD로 공급하고 원화로 회계처리하므로 환율이 오르면 원화 매출이 증가. 홀세일은 TNH 매출을 직접 입력
A13: 이익 = TNH 매출 − 원가, 원가 = 공급가 ÷ 공급율 ÷ 택가배수(4) (공급율: 홍콩·대만·홀세일 한국택가의 33%, 중국 한국원가 + 5%). 원가는 원화라서 환율 영향 없음 → 환율이 오르면 이익 증가
... A22: 데이터 보정 건수
A23: =COUNTIF(RAW_2026!P:P,"*택가보정*")&"행 택가 보정 / "&COUNTIF(RAW_2026!P:P,"*원가보정*")&"행 원가 보정 / "&COUNTIF(RAW_2026!P:P,"*공급가보정*")&"행 해외공급가 보정 / "&COUNTIF(RAW_2026!P:P,"*중국공급가*")&"행 중국공급가=원가+마진 (RAW_2026) · "&COUNTIF(RAW_판매펀칭!O:O,"택가보정*")&"행 택가 보정 (RAW_판매펀칭)" -> 88행 택가 보정 / 6행 원가 보정 / 16행 해외공급가 보정 / 170행 중국공급가=원가+마진 (RAW_2026) · 1행 택가 보정 (RAW_판매펀칭)

Sheet RAW_판매펀칭
A1: 구분 | B1: 매장코드 | C1: 매장명 | D1: 브랜드 | E1: 년도 | F1: 시즌 | G1: 품목 | H1: 라인 | I1: 스타일 | J1: 스타일명 | K1: 수량 | L1: TAG금액(KRW) | M1: 판매금액(KRW) | N1: TAG(보정) | O1: 보정내역 | P1: 차수(매장→차수, 추정) | Q1: 판매펀칭 리스트(1/1~기준일, 본사판매 = TNH → 법인/홀세일 공급, KIDS 포함). 소계행은 구분 열에서 "제외" 처리되므로 원본을 그대로 붙여넣어도 됩니다.
A2: =IF(OR(TRIM(C2)="",SUBSTITUTE(C2," ","")="소계"),"제외",IF(ISNUMBER(SEARCH("홍콩",C2)),"HK",IF(ISNUMBER(SEARCH("상해",C2)),"CN",IF(ISNUMBER(SEARCH("대만",C2)),"TW","홀세일")))) -> TW | B2: W9002 | C2: W대만 | D2: KIDS | E2: 2026 | F2: 봄 | G2: 용품 | H2: KIDS | I2: K261KBG050 | J2: 스퀘어 | K2: 210 | L2: 29190000 | M2: 11280150 | N2: =IF(A2="제외",0,IF(OR(N(L2)<=0,N(M2)>N(L2)),N(M2)/요약!$D$27,N(L2))) -> 29190000 | O2: =IF(A2="제외","",IF(OR(N(L2)<=0,N(M2)>N(L2)),"택가보정(판매금액÷공급율)","")) | P2: =IF(A2="HK","100",IF(A2="CN","200",IF(A2="TW","300",IF(ISNUMBER(SEARCH("태국",C2)),"500",IF(ISNUMBER(SEARCH("말레이",C2)),"600",IF(ISNUMBER(SEARCH("필리핀",C2)),"700",IF(ISNUMBER(SEARCH("인도네시아",C2)),"800",IF(ISNUMBER(SEARCH("크루즈",C2)),"810",IF(ISNUMBER(SEARCH("동물원",C2)),"830",""))))))))) -> 300 | Q2: 택가 오류행(택가≤0 또는 판매금액>택가)은 TAG(보정) = 판매금액÷공급율(요약!D27)로 보정하고 O열에 표시합니다.
A3: =IF(OR(TRIM(C3)="",SUBSTITUTE(C3," ","")="소계"),"제외",IF(ISNUMBER(SEARCH("홍콩",C3)),"HK",IF(ISNUMBER(SEARCH("상해",C3)),"CN",IF(ISNUMBER(SEARCH("대만",C3)),"TW","홀세일")))) -> TW | B3: W9002 | C3: W대만 | D3: KIDS | E3: 2026 | F3: 봄 | G3: 용품 | H3: KIDS | I3: K261KBG060 | J3: 코닉 | K3: 120 | L3: 19080000 | M3: 7371720 | N3: =IF(A3="제외",0,IF(OR(N(L3)<=0,N(M3)>N(L3)),N(M3)/요약!$D$27,N(L3))) -> 19080000 | O3: =IF(A3="제외","",IF(OR(N(L3)<=0,N(M3)>N(L3)),"택가보정(판매금액÷공급율)","")) | P3: =IF(A3="HK","100",IF(A3="CN","200",IF(A3="TW","300",IF(ISNUMBER(SEARCH("태국",C3)),"500",IF(ISNUMBER(SEARCH("말레이",C3)),"600",IF(ISNUMBER(SEARCH("필리핀",C3)),"700",IF(ISNUMBER(SEARCH("인도네시아",C3)),"800",IF(ISNUMBER(SEARCH("크루즈",C3)),"810",IF(ISNUMBER(SEARCH("동물원",C3)),"830",""))))))))) -> 300
A4: =IF(OR(TRIM(C4)="",SUBSTITUTE(C4," ","")="소계"),"제외",IF(ISNUMBER(SEARCH("홍콩",C4)),"HK",IF(ISNUMBER(SEARCH("상해",C4)),"CN",IF(ISNUMBER(SEARCH("대만",C4)),"TW","홀세일")))) -> TW | B4: W9002 | C4: W대만 | D4: KIDS | E4: 2026 | F4: 봄 | G4: 용품 | H4: KIDS | I4: K261KBG070 | J4: 데이 | K4: 150 | L4: 22350000 | M4: 8646900 | N4: =IF(A4="제외",0,IF(OR(N(L4)<=0,N(M4)>N(L4)),N(M4)/요약!$D$27,N(L4))) -> 22350000 | O4: =IF(A4="제외","",IF(OR(N(L4)<=0,N(M4)>N(L4)),"택가보정(판매금액÷공급율)","")) | P4: =IF(A4="HK","100",IF(A4="CN","200",IF(A4="TW","300",IF(ISNUMBER(SEARCH("태국",C4)),"500",IF(ISNUMBER(SEARCH("말레이",C4)),"600",IF(ISNUMBER(SEARCH("필리핀",C4)),"700",IF(ISNUMBER(SEARCH("인도네시아",C4)),"800",IF(ISNUMBER(SEARCH("크루즈",C4)),"810",IF(ISNUMBER(SEARCH("동물원",C4)),"830",""))))))))) -> 300
A5: =IF(OR(TRIM(C5)="",SUBSTITUTE(C5," ","")="소계"),"제외",IF(ISNUMBER(SEARCH("홍콩",C5)),"HK",IF(ISNUMBER(SEARCH("상해",C5)),"CN",IF(ISNUMBER(SEARCH("대만",C5)),"TW","홀세일")))) -> TW | B5: W9002 | C5: W대만 | D5: KIDS | E5: 2026 | F5: 4계절 | G5: 용품 | H5: KIDS | I5: K265KCR080 | J5: KIDS뉴슬링백 | K5: 80 | L5: 6320000 | M5: 2459680 | N5: =IF(A5="제외",0,IF(OR(N(L5)<=0,N(M5)>N(L5)),N(M5)/요약!$D$27,N(L5))) -> 6320000 | O5: =IF(A5="제외","",IF(OR(N(L5)<=0,N(M5)>N(L5)),"택가보정(판매금액÷공급율)","")) | P5: =IF(A5="HK","100",IF(A5="CN","200",IF(A5="TW","300",IF(ISNUMBER(SEARCH("태국",C5)),"500",IF(ISNUMBER(SEARCH("말레이",C5)),"600",IF(ISNUMBER(SEARCH("필리핀",C5)),"700",IF(ISNUMBER(SEARCH("인도네시아",C5)),"800",IF(ISNUMBER(SEARCH("크루즈",C5)),"810",IF(ISNUMBER(SEARCH("동물원",C5)),"830",""))))))))) -> 300
A6: =IF(OR(TRIM(C6)="",SUBSTITUTE(C6," ","")="소계"),"제외",IF(ISNUMBER(SEARCH("홍콩",C6)),"HK",IF(ISNUMBER(SEARCH("상해",C6)),"CN",IF(ISNUMBER(SEARCH("대만",C6)),"TW","홀세일")))) -> TW | B6: W9002 | C6: W대만 | D6: KIDS | E6: 2026 | F6: 4계절 | G6: 용품 | H6: KIDS | I6: K265KCR090 | J6: KIDS코닉슬링백 | K6: 80 | L6: 6320000 | M6: 2445600 | N6: =IF(A6="제외",0,IF(OR(N(L6)<=0,N(M6)>N(L6)),N(M6)/요약!$D$27,N(L6))) -> 6320000 | O6: =IF(A6="제외","",IF(OR(N(L6)<=0,N(M6)>N(L6)),"택가보정(판매금액÷공급율)","")) | P6: =IF(A6="HK","100",IF(A6="CN","200",IF(A6="TW","300",IF(ISNUMBER(SEARCH("태국",C6)),"500",IF(ISNUMBER(SEARCH("말레이",C6)),"600",IF(ISNUMBER(SEARCH("필리핀",C6)),"700",IF(ISNUMBER(SEARCH("인도네시아",C6)),"800",IF(ISNUMBER(SEARCH("크루즈",C6)),"810",IF(ISNUMBER(SEARCH("동물원",C6)),"830",""))))))))) -> 300
A7: =IF(OR(TRIM(C7)="",SUBSTITUTE(C7," ","")="소계"),"제외",IF(ISNUMBER(SEARCH("홍콩",C7)),"HK",IF(ISNUMBER(SEARCH("상해",C7)),"CN",IF(ISNUMBER(SEARCH("대만",C7)),"TW","홀세일")))) -> TW | B7: W9002 | C7: W대만 | D7: KIDS | E7: 2026 | F7: 4계절 | G7: 용품 | H7: KIDS | I7: K265KCR100 | J7: KIDS슬림미니크로스백 | K7: 80 | L7: 2320000 | M7: 896720 | N7: =IF(A7="제외",0,IF(OR(N(L7)<=0,N(M7)>N(L7)),N(M7)/요약!$D$27,N(L7))) -> 2320000 | O7: =IF(A7="제외","",IF(OR(N(L7)<=0,N(M7)>N(L7)),"택가보정(판매금액÷공급율)","")) | P7: =IF(A7="HK","100",IF(A7="CN","200",IF(A7="TW","300",IF(ISNUMBER(SEARCH("태국",C7)),"500",IF(ISNUMBER(SEARCH("말레이",C7)),"600",IF(ISNUMBER(SEARCH("필리핀",C7)),"700",IF(ISNUMBER(SEARCH("인도네시아",C7)),"800",IF(ISNUMBER(SEARCH("크루즈",C7)),"810",IF(ISNUMBER(SEARCH("동물원",C7)),"830",""))))))))) -> 300
A8: =IF(OR(TRIM(C8)="",SUBSTITUTE(C8," ","")="소계"),"제외",IF(ISNUMBER(SEARCH("홍콩",C8)),"HK",IF(ISNUMBER(SEARCH("상해",C8)),"CN",IF(ISNUMBER(SEARCH("대만",C8)),"TW","홀세일")))) -> TW | B8: W9002 | C8: W대만 | D8: KIDS | E8: 2026 | F8: 4계절 | G8: 용품 | H8: KIDS | I8: K265KCR110 | J8: KIDS코닉폴더크로스백 | K8: 150 | L8: 8850000 | M8: 3447900 | N8: =IF(A8="제외",0,IF(OR(N(L8)<=0,N(M8)>N(L8)),N(M8)/요약!$D$27,N(L8))) -> 8850000 | O8: =IF(A8="제외","",IF(OR(N(L8)<=0,N(M8)>N(L8)),"택가보정(판매금액÷공급율)","")) | P8: =IF(A8="HK","100",IF(A8="CN","200",IF(A8="TW","300",IF(ISNUMBER(SEARCH("태국",C8)),"500",IF(ISNUMBER(SEARCH("말레이",C8)),"600",IF(ISNUMBER(SEARCH("필리핀",C8)),"700",IF(ISNUMBER(SEARCH("인도네시아",C8)),"800",IF(ISNUMBER(SEARCH("크루즈",C8)),"810",IF(ISNUMBER(SEARCH("동물원",C8)),"830",""))))))))) -> 300
A9: =IF(OR(TRIM(C9)="",SUBSTITUTE(C9," ","")="소계"),"제외",IF(ISNUMBER(SEARCH("홍콩",C9)),"HK",IF(ISNUMBER(SEARCH("상해",C9)),"CN",IF(ISNUMBER(SEARCH("대만",C9)),"TW","홀세일")))) -> TW | B9: W9002 | C9: W대만 | D9: KIDS | E9: 2026 | F9: 4계절 | G9: 용품 | H9: KIDS | I9: K265KCR120 | J9: KIDS가로크로스백 | K9: 150 | L9: 7350000 | M9: 2934000 | N9: =IF(A9="제외",0,IF(OR(N(L9)<=0,N(M9)>N(L9)),N(M9)/요약!$D$27,N(L9))) -> 7350000 | O9: =IF(A9="제외","",IF(OR(N(L9)<=0,N(M9)>N(L9)),"택가보정(판매금액÷공급율)","")) | P9: =IF(A9="HK","100",IF(A9="CN","200",IF(A9="TW","300",IF(ISNUMBER(SEARCH("태국",C9)),"500",IF(ISNUMBER(SEARCH("말레이",C9)),"600",IF(ISNUMBER(SEARCH("필리핀",C9)),"700",IF(ISNUMBER(SEARCH("인도네시아",C9)),"800",IF(ISNUMBER(SEARCH("크루즈",C9)),"810",IF(ISNUMBER(SEARCH("동물원",C9)),"830",""))))))))) -> 300
A10: =IF(OR(TRIM(C10)="",SUBSTITUTE(C10," ","")="소계"),"제외",IF(ISNUMBER(SEARCH("홍콩",C10)),"HK",IF(ISNUMBER(SEARCH("상해",C10)),"CN",IF(ISNUMBER(SEARCH("대만",C10)),"TW","홀세일")))) -> TW | B10: W9002 | C10: W대만 | D10: KIDS | E10: 2026 | F10: 4계절 | G10: 용품 | H10: KIDS | I10: K265KCR130 | J10: KIDS어드벤쳐크로스백 | K10: 220 | L10: 15180000 | M10: 5776540 | N10: =IF(A10="제외",0,IF(OR(N(L10)<=0,N(M10)>N(L10)),N(M10)/요약!$D$27,N(L10))) -> 15180000 | O10: =IF(A10="제외","",IF(OR(N(L10)<=0,N(M10)>N(L10)),"택가보정(판매금액÷공급율)","")) | P10: =IF(A10="HK","100",IF(A10="CN","200",IF(A10="TW","300",IF(ISNUMBER(SEARCH("태국",C10)),"500",IF(ISNUMBER(SEARCH("말레이",C10)),"600",IF(ISNUMBER(SEARCH("필리핀",C10)),"700",IF(ISNUMBER(SEARCH("인도네시아",C10)),"800",IF(ISNUMBER(SEARCH("크루즈",C10)),"810",IF(ISNUMBER(SEARCH("동물원",C10)),"830",""))))))))) -> 300
A11: =IF(OR(TRIM(C11)="",SUBSTITUTE(C11," ","")="소계"),"제외",IF(ISNUMBER(SEARCH("홍콩",C11)),"HK",IF(ISNUMBER(SEARCH("상해",C11)),"CN",IF(ISNUMBER(SEARCH("대만",C11)),"TW","홀세일")))) -> TW | B11: W9002 | C11: W대만 | D11: 내셔널지오그래픽 | E11: 2025 | F11: 봄 | G11: 의류 | H11: Urban | I11: N251UJP260 | J11: 아틀라스 윈드스토퍼 BY GORE-TEX LABS 2L 블록 자켓 | K11: 67 | L11: 20033000 | M11: 7088533 | N11: =IF(A11="제외",0,IF(OR(N(L11)<=0,N(M11)>N(L11)),N(M11)/요약!$D$27,N(L11))) -> 20033000 | O11: =IF(A11="제외","",IF(OR(N(L11)<=0,N(M11)>N(L11)),"택가보정(판매금액÷공급율)","")) | P11: =IF(A11="HK","100",IF(A11="CN","200",IF(A11="TW","300",IF(ISNUMBER(SEARCH("태국",C11)),"500",IF(ISNUMBER(SEARCH("말레이",C11)),"600",IF(ISNUMBER(SEARCH("필리핀",C11)),"700",IF(ISNUMBER(SEARCH("인도네시아",C11)),"800",IF(ISNUMBER(SEARCH("크루즈",C11)),"810",IF(ISNUMBER(SEARCH("동물원",C11)),"830",""))))))))) -> 300
A12: =IF(OR(TRIM(C12)="",SUBSTITUTE(C12," ","")="소계"),"제외",IF(ISNUMBER(SEARCH("홍콩",C12)),"HK",IF(ISNUMBER(SEARCH("상해",C12)),"CN",IF(ISNUMBER(SEARCH("대만",C12)),"TW","홀세일")))) -> TW | B12: W9002 | C12: W대만 | D12: 내셔널지오그래픽 | E12: 2025 | F12: 봄 | G12: 의류 | H12: 온라인 | I12: N251UJP860 | J12: (온) 아틀라스 윈드스토퍼 BY GORE-TEX LABS 2L 블록 자켓 | K12: 20 | L12: 5980000 | M12: 2115980 | N12: =IF(A12="제외",0,IF(OR(N(L12)<=0,N(M12)>N(L12)),N(M12)/요약!$D$27,N(L12))) -> 5980000 | O12: =IF(A12="제외","",IF(OR(N(L12)<=0,N(M12)>N(L12)),"택가보정(판매금액÷공급율)","")) | P12: =IF(A12="HK","100",IF(A12="CN","200",IF(A12="TW","300",IF(ISNUMBER(SEARCH("태국",C12)),"500",IF(ISNUMBER(SEARCH("말레이",C12)),"600",IF(ISNUMBER(SEARCH("필리핀",C12)),"700",IF(ISNUMBER(SEARCH("인도네시아",C12)),"800",IF(ISNUMBER(SEARCH("크루즈",C12)),"810",IF(ISNUMBER(SEARCH("동물원",C12)),"830",""))))))))) -> 300
A13: =IF(OR(TRIM(C13)="",SUBSTITUTE(C13," ","")="소계"),"제외",IF(ISNUMBER(SEARCH("홍콩",C13)),"HK",IF(ISNUMBER(SEARCH("상해",C13)),"CN",IF(ISNUMBER(SEARCH("대만",C13)),"TW","홀세일")))) -> TW | B13: W9002 | C13: W대만 | D13: 내셔널지오그래픽 | E13: 2026 | F13: 봄 | G13: 용품 | H13: Original | I13: N261ABG010 | J13: 파치백팩 | K13: 150 | L13: 25350000 | M13: 9736800 | N13: =IF(A13="제외",0,IF(OR(N(L13)<=0,N(M13)>N(L13)),N(M13)/요약!$D$27,N(L13))) -> 25350000 | O13: =IF(A13="제외","",IF(OR(N(L13)<=0,N(M13)>N(L13)),"택가보정(판매금액÷공급율)","")) | P13: =IF(A13="HK","100",IF(A13="CN","200",IF(A13="TW","300",IF(ISNUMBER(SEARCH("태국",C13)),"500",IF(ISNUMBER(SEARCH("말레이",C13)),"600",IF(ISNUMBER(SEARCH("필리핀",C13)),"700",IF(ISNUMBER(SEARCH("인도네시아",C13)),"800",IF(ISNUMBER(SEARCH("크루즈",C13)),"810",IF(ISNUMBER(SEARCH("동물원",C13)),"830",""))))))))) -> 300
A14: =IF(OR(TRIM(C14)="",SUBSTITUTE(C14," ","")="소계"),"제외",IF(ISNUMBER(SEARCH("홍콩",C14)),"HK",IF(ISNUMBER(SEARCH("상해",C14)),"CN",IF(ISNUMBER(SEARCH("대만",C14)),"TW","홀세일")))) -> TW | B14: W9002 | C14: W대만 | D14: 내셔널지오그래픽 | E14: 2026 | F14: 봄 | G14: 용품 | H14: Original | I14: N261ABG020 | J14: 파치+백팩 | K14: 250 | L14: 44750000 | M14: 17203750 | N14: =IF(A14="제외",0,IF(OR(N(L14)<=0,N(M14)>N(L14)),N(M14)/요약!$D$27,N(L14))) -> 44750000 | O14: =IF(A14="제외","",IF(OR(N(L14)<=0,N(M14)>N(L14)),"택가보정(판매금액÷공급율)","")) | P14: =IF(A14="HK","100",IF(A14="CN","200",IF(A14="TW","300",IF(ISNUMBER(SEARCH("태국",C14)),"500",IF(ISNUMBER(SEARCH("말레이",C14)),"600",IF(ISNUMBER(SEARCH("필리핀",C14)),"700",IF(ISNUMBER(SEARCH("인도네시아",C14)),"800",IF(ISNUMBER(SEARCH("크루즈",C14)),"810",IF(ISNUMBER(SEARCH("동물원",C14)),"830",""))))))))) -> 300
... A323: =IF(OR(TRIM(C323)="",SUBSTITUTE(C323," ","")="소계"),"제외",IF(ISNUMBER(SEARCH("홍콩",C323)),"HK",IF(ISNUMBER(SEARCH("상해",C323)),"CN",IF(ISNUMBER(SEARCH("대만",C323)),"TW","홀세일")))) -> TW | B323: W9002 | C323: W대만 | D323: 해외전용(NGA&MG) | E323: 2026 | F323: 4계절 | G323: 용품 | H323: Original | I323: O265ABG070 | J323: 시프트백팩_라이트 | K323: 200 | L323: 33800000 | M323: 13467400 | N323: =IF(A323="제외",0,IF(OR(N(L323)<=0,N(M323)>N(L323)),N(M323)/요약!$D$27,N(L323))) -> 33800000 | O323: =IF(A323="제외","",IF(OR(N(L323)<=0,N(M323)>N(L323)),"택가보정(판매금액÷공급율)","")) | P323: =IF(A323="HK","100",IF(A323="CN","200",IF(A323="TW","300",IF(ISNUMBER(SEARCH("태국",C323)),"500",IF(ISNUMBER(SEARCH("말레이",C323)),"600",IF(ISNUMBER(SEARCH("필리핀",C323)),"700",IF(ISNUMBER(SEARCH("인도네시아",C323)),"800",IF(ISNUMBER(SEARCH("크루즈",C323)),"810",IF(ISNUMBER(SEARCH("동물원",C323)),"830",""))))))))) -> 300
A324: =IF(OR(TRIM(C324)="",SUBSTITUTE(C324," ","")="소계"),"제외",IF(ISNUMBER(SEARCH("홍콩",C324)),"HK",IF(ISNUMBER(SEARCH("상해",C324)),"CN",IF(ISNUMBER(SEARCH("대만",C324)),"TW","홀세일")))) -> 제외 | C324: 소 계 | K324: 106012 | L324: 13316058000 | M324: 4774695740 | N324: =IF(A324="제외",0,IF(OR(N(L324)<=0,N(M324)>N(L324)),N(M324)/요약!$D$27,N(L324))) -> 0 | O324: =IF(A324="제외","",IF(OR(N(L324)<=0,N(M324)>N(L324)),"택가보정(판매금액÷공급율)","")) | P324: =IF(A324="HK","100",IF(A324="CN","200",IF(A324="TW","300",IF(ISNUMBER(SEARCH("태국",C324)),"500",IF(ISNUMBER(SEARCH("말레이",C324)),"600",IF(ISNUMBER(SEARCH("필리핀",C324)),"700",IF(ISNUMBER(SEARCH("인도네시아",C324)),"800",IF(ISNUMBER(SEARCH("크루즈",C324)),"810",IF(ISNUMBER(SEARCH("동물원",C324)),"830","")))))))))
A325: =IF(OR(TRIM(C325)="",SUBSTITUTE(C325," ","")="소계"),"제외",IF(ISNUMBER(SEARCH("홍콩",C325)),"HK",IF(ISNUMBER(SEARCH("상해",C325)),"CN",IF(ISNUMBER(SEARCH("대만",C325)),"TW","홀세일")))) -> HK | B325: W9007 | C325: 홍콩법인 | D325: KIDS | E325: 2026 | F325: 4계절 | G325: 용품 | H325: KIDS | I325: K265APE498 | J325: (사)KIDS3단자동우산 | K325: 800 | L325: 36000000 | M325: 11300800 | N325: =IF(A325="제외",0,IF(OR(N(L325)<=0,N(M325)>N(L325)),N(M325)/요약!$D$27,N(L325))) -> 36000000 | O325: =IF(A325="제외","",IF(OR(N(L325)<=0,N(M325)>N(L325)),"택가보정(판매금액÷공급율)","")) | P325: =IF(A325="HK","100",IF(A325="CN","200",IF(A325="TW","300",IF(ISNUMBER(SEARCH("태국",C325)),"500",IF(ISNUMBER(SEARCH("말레이",C325)),"600",IF(ISNUMBER(SEARCH("필리핀",C325)),"700",IF(ISNUMBER(SEARCH("인도네시아",C325)),"800",IF(ISNUMBER(SEARCH("크루즈",C325)),"810",IF(ISNUMBER(SEARCH("동물원",C325)),"830",""))))))))) -> 100
A326: =IF(OR(TRIM(C326)="",SUBSTITUTE(C326," ","")="소계"),"제외",IF(ISNUMBER(SEARCH("홍콩",C326)),"HK",IF(ISNUMBER(SEARCH("상해",C326)),"CN",IF(ISNUMBER(SEARCH("대만",C326)),"TW","홀세일")))) -> HK | B326: W9007 | C326: 홍콩법인 | D326: 내셔널지오그래픽 | E326: 2023 | F326: 4계절 | G326: 용품 | H326: 기타 | I326: N235APE498 | J326: (사)돗자리 | K326: 639 | L326: 639 | M326: 93933 | N326: =IF(A326="제외",0,IF(OR(N(L326)<=0,N(M326)>N(L326)),N(M326)/요약!$D$27,N(L326))) -> 284645.45 | O326: =IF(A326="제외","",IF(OR(N(L326)<=0,N(M326)>N(L326)),"택가보정(판매금액÷공급율)","")) -> 택가보정(판매금액÷공급율) | P326: =IF(A326="HK","100",IF(A326="CN","200",IF(A326="TW","300",IF(ISNUMBER(SEARCH("태국",C326)),"500",IF(ISNUMBER(SEARCH("말레이",C326)),"600",IF(ISNUMBER(SEARCH("필리핀",C326)),"700",IF(ISNUMBER(SEARCH("인도네시아",C326)),"800",IF(ISNUMBER(SEARCH("크루즈",C326)),"810",IF(ISNUMBER(SEARCH("동물원",C326)),"830",""))))))))) -> 100
A327: =IF(OR(TRIM(C327)="",SUBSTITUTE(C327," ","")="소계"),"제외",IF(ISNUMBER(SEARCH("홍콩",C327)),"HK",IF(ISNUMBER(SEARCH("상해",C327)),"CN",IF(ISNUMBER(SEARCH("대만",C327)),"TW","홀세일")))) -> HK | B327: W9007 | C327: 홍콩법인 | D327: 내셔널지오그래픽 | E327: 2025 | F327: 4계절 | G327: 캐리어 | H327: 온라인 | I327: N255ASU450 | J327: (온) 부다페스트 캐리어 24 | K327: 180 | L327: 46620000 | M327: 23385780 | N327: =IF(A327="제외",0,IF(OR(N(L327)<=0,N(M327)>N(L327)),N(M327)/요약!$D$27,N(L327))) -> 46620000 | O327: =IF(A327="제외","",IF(OR(N(L327)<=0,N(M327)>N(L327)),"택가보정(판매금액÷공급율)","")) | P327: =IF(A327="HK","100",IF(A327="CN","200",IF(A327="TW","300",IF(ISNUMBER(SEARCH("태국",C327)),"500",IF(ISNUMBER(SEARCH("말레이",C327)),"600",IF(ISNUMBER(SEARCH("필리핀",C327)),"700",IF(ISNUMBER(SEARCH("인도네시아",C327)),"800",IF(ISNUMBER(SEARCH("크루즈",C327)),"810",IF(ISNUMBER(SEARCH("동물원",C327)),"830",""))))))))) -> 100
A328: =IF(OR(TRIM(C328)="",SUBSTITUTE(C328," ","")="소계"),"제외",IF(ISNUMBER(SEARCH("홍콩",C328)),"HK",IF(ISNUMBER(SEARCH("상해",C328)),"CN",IF(ISNUMBER(SEARCH("대만",C328)),"TW","홀세일")))) -> HK | B328: W9007 | C328: 홍콩법인 | D328: 내셔널지오그래픽 | E328: 2025 | F328: 4계절 | G328: 기타 | H328: 홈쇼핑 | I328: N255APP510 | J328: (홈)풀데이 미니캐리어 V2 | K328: 250 | L328: 27250000 | M328: 6123750 | N328: =IF(A328="제외",0,IF(OR(N(L328)<=0,N(M328)>N(L328)),N(M328)/요약!$D$27,N(L328))) -> 27250000 | O328: =IF(A328="제외","",IF(OR(N(L328)<=0,N(M328)>N(L328)),"택가보정(판매금액÷공급율)","")) | P328: =IF(A328="HK","100",IF(A328="CN","200",IF(A328="TW","300",IF(ISNUMBER(SEARCH("태국",C328)),"500",IF(ISNUMBER(SEARCH("말레이",C328)),"600",IF(ISNUMBER(SEARCH("필리핀",C328)),"700",IF(ISNUMBER(SEARCH("인도네시아",C328)),"800",IF(ISNUMBER(SEARCH("크루즈",C328)),"810",IF(ISNUMBER(SEARCH("동물원",C328)),"830",""))))))))) -> 100
A329: =IF(OR(TRIM(C329)="",SUBSTITUTE(C329," ","")="소계"),"제외",IF(ISNUMBER(SEARCH("홍콩",C329)),"HK",IF(ISNUMBER(SEARCH("상해",C329)),"CN",IF(ISNUMBER(SEARCH("대만",C329)),"TW","홀세일")))) -> HK | B329: W9007 | C329: 홍콩법인 | D329: 내셔널지오그래픽 | E329: 2025 | F329: 4계절 | G329: 신발 | H329: 온라인 | I329: N255USN312 | J329: (온) 스텀프 V3 | K329: 110 | L329: 11990000 | M329: 5092560 | N329: =IF(A329="제외",0,IF(OR(N(L329)<=0,N(M329)>N(L329)),N(M329)/요약!$D$27,N(L329))) -> 11990000 | O329: =IF(A329="제외","",IF(OR(N(L329)<=0,N(M329)>N(L329)),"택가보정(판매금액÷공급율)","")) | P329: =IF(A329="HK","100",IF(A329="CN","200",IF(A329="TW","300",IF(ISNUMBER(SEARCH("태국",C329)),"500",IF(ISNUMBER(SEARCH("말레이",C329)),"600",IF(ISNUMBER(SEARCH("필리핀",C329)),"700",IF(ISNUMBER(SEARCH("인도네시아",C329)),"800",IF(ISNUMBER(SEARCH("크루즈",C329)),"810",IF(ISNUMBER(SEARCH("동물원",C329)),"830",""))))))))) -> 100
A330: =IF(OR(TRIM(C330)="",SUBSTITUTE(C330," ","")="소계"),"제외",IF(ISNUMBER(SEARCH("홍콩",C330)),"HK",IF(ISNUMBER(SEARCH("상해",C330)),"CN",IF(ISNUMBER(SEARCH("대만",C330)),"TW","홀세일")))) -> HK | B330: W9007 | C330: 홍콩법인 | D330: 내셔널지오그래픽 | E330: 2026 | F330: 봄 | G330: 의류 | H330: Original | I330: N261MPT510 | J330: NRN 유틸리티 베이직핏 조거 팬츠 | K330: 90 | L330: 12510000 | M330: 4539510 | N330: =IF(A330="제외",0,IF(OR(N(L330)<=0,N(M330)>N(L330)),N(M330)/요약!$D$27,N(L330))) -> 12510000 | O330: =IF(A330="제외","",IF(OR(N(L330)<=0,N(M330)>N(L330)),"택가보정(판매금액÷공급율)","")) | P330: =IF(A330="HK","100",IF(A330="CN","200",IF(A330="TW","300",IF(ISNUMBER(SEARCH("태국",C330)),"500",IF(ISNUMBER(SEARCH("말레이",C330)),"600",IF(ISNUMBER(SEARCH("필리핀",C330)),"700",IF(ISNUMBER(SEARCH("인도네시아",C330)),"800",IF(ISNUMBER(SEARCH("크루즈",C330)),"810",IF(ISNUMBER(SEARCH("동물원",C330)),"830",""))))))))) -> 100
A331: =IF(OR(TRIM(C331)="",SUBSTITUTE(C331," ","")="소계"),"제외",IF(ISNUMBER(SEARCH("홍콩",C331)),"HK",IF(ISNUMBER(SEARCH("상해",C331)),"CN",IF(ISNUMBER(SEARCH("대만",C331)),"TW","홀세일")))) -> HK | B331: W9007 | C331: 홍콩법인 | D331: 내셔널지오그래픽 | E331: 2026 | F331: 봄 | G331: 의류 | H331: Urban | I331: N261MPT210 | J331: 아르마딜로 스트레치 베이직핏 스트레이트 팬츠 | K331: 110 | L331: 17490000 | M331: 6334130 | N331: =IF(A331="제외",0,IF(OR(N(L331)<=0,N(M331)>N(L331)),N(M331)/요약!$D$27,N(L331))) -> 17490000 | O331: =IF(A331="제외","",IF(OR(N(L331)<=0,N(M331)>N(L331)),"택가보정(판매금액÷공급율)","")) | P331: =IF(A331="HK","100",IF(A331="CN","200",IF(A331="TW","300",IF(ISNUMBER(SEARCH("태국",C331)),"500",IF(ISNUMBER(SEARCH("말레이",C331)),"600",IF(ISNUMBER(SEARCH("필리핀",C331)),"700",IF(ISNUMBER(SEARCH("인도네시아",C331)),"800",IF(ISNUMBER(SEARCH("크루즈",C331)),"810",IF(ISNUMBER(SEARCH("동물원",C331)),"830",""))))))))) -> 100
A332: =IF(OR(TRIM(C332)="",SUBSTITUTE(C332," ","")="소계"),"제외",IF(ISNUMBER(SEARCH("홍콩",C332)),"HK",IF(ISNUMBER(SEARCH("상해",C332)),"CN",IF(ISNUMBER(SEARCH("대만",C332)),"TW","홀세일")))) -> HK | B332: W9007 | C332: 홍콩법인 | D332: 내셔널지오그래픽 | E332: 2026 | F332: 봄 | G332: 의류 | H332: Original | I332: N261MJP530 | J332: NRN 유틸리티 필드 자켓 | K332: 80 | L332: 22320000 | M332: 8576640 | N332: =IF(A332="제외",0,IF(OR(N(L332)<=0,N(M332)>N(L332)),N(M332)/요약!$D$27,N(L332))) -> 22320000 | O332: =IF(A332="제외","",IF(OR(N(L332)<=0,N(M332)>N(L332)),"택가보정(판매금액÷공급율)","")) | P332: =IF(A332="HK","100",IF(A332="CN","200",IF(A332="TW","300",IF(ISNUMBER(SEARCH("태국",C332)),"500",IF(ISNUMBER(SEARCH("말레이",C332)),"600",IF(ISNUMBER(SEARCH("필리핀",C332)),"700",IF(ISNUMBER(SEARCH("인도네시아",C332)),"800",IF(ISNUMBER(SEARCH("크루즈",C332)),"810",IF(ISNUMBER(SEARCH("동물원",C332)),"830",""))))))))) -> 100
A333: =IF(OR(TRIM(C333)="",SUBSTITUTE(C333," ","")="소계"),"제외",IF(ISNUMBER(SEARCH("홍콩",C333)),"HK",IF(ISNUMBER(SEARCH("상해",C333)),"CN",IF(ISNUMBER(SEARCH("대만",C333)),"TW","홀세일")))) -> HK | B333: W9007 | C333: 홍콩법인 | D333: 내셔널지오그래픽 | E333: 2026 | F333: 봄 | G333: 의류 | H333: Urban | I333: N261MJP210 | J333: 어반시티 블루종 점퍼 | K333: 100 | L333: 21900000 | M333: 8433200 | N333: =IF(A333="제외",0,IF(OR(N(L333)<=0,N(M333)>N(L333)),N(M333)/요약!$D$27,N(L333))) -> 21900000 | O333: =IF(A333="제외","",IF(OR(N(L333)<=0,N(M333)>N(L333)),"택가보정(판매금액÷공급율)","")) | P333: =IF(A333="HK","100",IF(A333="CN","200",IF(A333="TW","300",IF(ISNUMBER(SEARCH("태국",C333)),"500",IF(ISNUMBER(SEARCH("말레이",C333)),"600",IF(ISNUMBER(SEARCH("필리핀",C333)),"700",IF(ISNUMBER(SEARCH("인도네시아",C333)),"800",IF(ISNUMBER(SEARCH("크루즈",C333)),"810",IF(ISNUMBER(SEARCH("동물원",C333)),"830",""))))))))) -> 100
A334: =IF(OR(TRIM(C334)="",SUBSTITUTE(C334," ","")="소계"),"제외",IF(ISNUMBER(SEARCH("홍콩",C334)),"HK",IF(ISNUMBER(SEARCH("상해",C334)),"CN",IF(ISNUMBER(SEARCH("대만",C334)),"TW","홀세일")))) -> HK | B334: W9007 | C334: 홍콩법인 | D334: 내셔널지오그래픽 | E334: 2026 | F334: 봄 | G334: 의류 | H334: Urban | I334: N261MJP270 | J334: 3L 방수 후드형 자켓 | K334: 220 | L334: 56980000 | M334: 21847320 | N334: =IF(A334="제외",0,IF(OR(N(L334)<=0,N(M334)>N(L334)),N(M334)/요약!$D$27,N(L334))) -> 56980000 | O334: =IF(A334="제외","",IF(OR(N(L334)<=0,N(M334)>N(L334)),"택가보정(판매금액÷공급율)","")) | P334: =IF(A334="HK","100",IF(A334="CN","200",IF(A334="TW","300",IF(ISNUMBER(SEARCH("태국",C334)),"500",IF(ISNUMBER(SEARCH("말레이",C334)),"600",IF(ISNUMBER(SEARCH("필리핀",C334)),"700",IF(ISNUMBER(SEARCH("인도네시아",C334)),"800",IF(ISNUMBER(SEARCH("크루즈",C334)),"810",IF(ISNUMBER(SEARCH("동물원",C334)),"830",""))))))))) -> 100
A335: =IF(OR(TRIM(C335)="",SUBSTITUTE(C335," ","")="소계"),"제외",IF(ISNUMBER(SEARCH("홍콩",C335)),"HK",IF(ISNUMBER(SEARCH("상해",C335)),"CN",IF(ISNUMBER(SEARCH("대만",C335)),"TW","홀세일")))) -> HK | B335: W9007 | C335: 홍콩법인 | D335: 내셔널지오그래픽 | E335: 2026 | F335: 봄 | G335: 의류 | H335: Original | I335: N261MFT510 | J335: NRN 유틸리티 세미오버핏 후드 풀집업 | K335: 70 | L335: 13930000 | M335: 5052600 | N335: =IF(A335="제외",0,IF(OR(N(L335)<=0,N(M335)>N(L335)),N(M335)/요약!$D$27,N(L335))) -> 13930000 | O335: =IF(A335="제외","",IF(OR(N(L335)<=0,N(M335)>N(L335)),"택가보정(판매금액÷공급율)","")) | P335: =IF(A335="HK","100",IF(A335="CN","200",IF(A335="TW","300",IF(ISNUMBER(SEARCH("태국",C335)),"500",IF(ISNUMBER(SEARCH("말레이",C335)),"600",IF(ISNUMBER(SEARCH("필리핀",C335)),"700",IF(ISNUMBER(SEARCH("인도네시아",C335)),"800",IF(ISNUMBER(SEARCH("크루즈",C335)),"810",IF(ISNUMBER(SEARCH("동물원",C335)),"830",""))))))))) -> 100
A336: =IF(OR(TRIM(C336)="",SUBSTITUTE(C336," ","")="소계"),"제외",IF(ISNUMBER(SEARCH("홍콩",C336)),"HK",IF(ISNUMBER(SEARCH("상해",C336)),"CN",IF(ISNUMBER(SEARCH("대만",C336)),"TW","홀세일")))) -> HK | B336: W9007 | C336: 홍콩법인 | D336: 내셔널지오그래픽 | E336: 2026 | F336: 봄 | G336: 의류 | H336: Original | I336: N261UPT050 | J336: 마게이 베이직핏 조거 카고 팬츠 | K336: 210 | L336: 27090000 | M336: 9831360 | N336: =IF(A336="제외",0,IF(OR(N(L336)<=0,N(M336)>N(L336)),N(M336)/요약!$D$27,N(L336))) -> 27090000 | O336: =IF(A336="제외","",IF(OR(N(L336)<=0,N(M336)>N(L336)),"택가보정(판매금액÷공급율)","")) | P336: =IF(A336="HK","100",IF(A336="CN","200",IF(A336="TW","300",IF(ISNUMBER(SEARCH("태국",C336)),"500",IF(ISNUMBER(SEARCH("말레이",C336)),"600",IF(ISNUMBER(SEARCH("필리핀",C336)),"700",IF(ISNUMBER(SEARCH("인도네시아",C336)),"800",IF(ISNUMBER(SEARCH("크루즈",C336)),"810",IF(ISNUMBER(SEARCH("동물원",C336)),"830",""))))))))) -> 100
... A632: =IF(OR(TRIM(C632)="",SUBSTITUTE(C632," ","")="소계"),"제외",IF(ISNUMBER(SEARCH("홍콩",C632)),"HK",IF(ISNUMBER(SEARCH("상해",C632)),"CN",IF(ISNUMBER(SEARCH("대만",C632)),"TW","홀세일")))) -> HK | B632: W9007 | C632: 홍콩법인 | D632: 해외전용(NGA&MG) | E632: 2026 | F632: 겨울 | G632: 의류 | H632: WOMEN | I632: O264WKT010 | J632: W' 스웨터 니트 가디건 | K632: 200 | L632: 31800000 | M632: 10296200 | N632: =IF(A632="제외",0,IF(OR(N(L632)<=0,N(M632)>N(L632)),N(M632)/요약!$D$27,N(L632))) -> 31800000 | O632: =IF(A632="제외","",IF(OR(N(L632)<=0,N(M632)>N(L632)),"택가보정(판매금액÷공급율)","")) | P632: =IF(A632="HK","100",IF(A632="CN","200",IF(A632="TW","300",IF(ISNUMBER(SEARCH("태국",C632)),"500",IF(ISNUMBER(SEARCH("말레이",C632)),"600",IF(ISNUMBER(SEARCH("필리핀",C632)),"700",IF(ISNUMBER(SEARCH("인도네시아",C632)),"800",IF(ISNUMBER(SEARCH("크루즈",C632)),"810",IF(ISNUMBER(SEARCH("동물원",C632)),"830",""))))))))) -> 100
A633: =IF(OR(TRIM(C633)="",SUBSTITUTE(C633," ","")="소계"),"제외",IF(ISNUMBER(SEARCH("홍콩",C633)),"HK",IF(ISNUMBER(SEARCH("상해",C633)),"CN",IF(ISNUMBER(SEARCH("대만",C633)),"TW","홀세일")))) -> 제외 | C633: 소 계 | K633: 83733 | L633: 10363947639 | M633: 3700267998 | N633: =IF(A633="제외",0,IF(OR(N(L633)<=0,N(M633)>N(L633)),N(M633)/요약!$D$27,N(L633))) -> 0 | O633: =IF(A633="제외","",IF(OR(N(L633)<=0,N(M633)>N(L633)),"택가보정(판매금액÷공급율)","")) | P633: =IF(A633="HK","100",IF(A633="CN","200",IF(A633="TW","300",IF(ISNUMBER(SEARCH("태국",C633)),"500",IF(ISNUMBER(SEARCH("말레이",C633)),"600",IF(ISNUMBER(SEARCH("필리핀",C633)),"700",IF(ISNUMBER(SEARCH("인도네시아",C633)),"800",IF(ISNUMBER(SEARCH("크루즈",C633)),"810",IF(ISNUMBER(SEARCH("동물원",C633)),"830","")))))))))
A634: =IF(OR(TRIM(C634)="",SUBSTITUTE(C634," ","")="소계"),"제외",IF(ISNUMBER(SEARCH("홍콩",C634)),"HK",IF(ISNUMBER(SEARCH("상해",C634)),"CN",IF(ISNUMBER(SEARCH("대만",C634)),"TW","홀세일")))) -> CN | B634: WW002 | C634: 상해법인(덕나이철) | D634: 내셔널지오그래픽 | E634: 2025 | F634: 4계절 | G634: 캐리어 | H634: Original | I634: N255ASU050 | J634: 하바나 캐리어 20 | K634: 50 | L634: 10950000 | M634: 2449900 | N634: =IF(A634="제외",0,IF(OR(N(L634)<=0,N(M634)>N(L634)),N(M634)/요약!$D$27,N(L634))) -> 10950000 | O634: =IF(A634="제외","",IF(OR(N(L634)<=0,N(M634)>N(L634)),"택가보정(판매금액÷공급율)","")) | P634: =IF(A634="HK","100",IF(A634="CN","200",IF(A634="TW","300",IF(ISNUMBER(SEARCH("태국",C634)),"500",IF(ISNUMBER(SEARCH("말레이",C634)),"600",IF(ISNUMBER(SEARCH("필리핀",C634)),"700",IF(ISNUMBER(SEARCH("인도네시아",C634)),"800",IF(ISNUMBER(SEARCH("크루즈",C634)),"810",IF(ISNUMBER(SEARCH("동물원",C634)),"830",""))))))))) -> 200
A635: =IF(OR(TRIM(C635)="",SUBSTITUTE(C635," ","")="소계"),"제외",IF(ISNUMBER(SEARCH("홍콩",C635)),"HK",IF(ISNUMBER(SEARCH("상해",C635)),"CN",IF(ISNUMBER(SEARCH("대만",C635)),"TW","홀세일")))) -> CN | B635: WW002 | C635: 상해법인(덕나이철) | D635: 내셔널지오그래픽 | E635: 2025 | F635: 4계절 | G635: 캐리어 | H635: 홈쇼핑 | I635: N255ASU930 | J635: (홈) 페이지 캐리어 SET | K635: 30 | L635: 10440000 | M635: 4182690 | N635: =IF(A635="제외",0,IF(OR(N(L635)<=0,N(M635)>N(L635)),N(M635)/요약!$D$27,N(L635))) -> 10440000 | O635: =IF(A635="제외","",IF(OR(N(L635)<=0,N(M635)>N(L635)),"택가보정(판매금액÷공급율)","")) | P635: =IF(A635="HK","100",IF(A635="CN","200",IF(A635="TW","300",IF(ISNUMBER(SEARCH("태국",C635)),"500",IF(ISNUMBER(SEARCH("말레이",C635)),"600",IF(ISNUMBER(SEARCH("필리핀",C635)),"700",IF(ISNUMBER(SEARCH("인도네시아",C635)),"800",IF(ISNUMBER(SEARCH("크루즈",C635)),"810",IF(ISNUMBER(SEARCH("동물원",C635)),"830",""))))))))) -> 200
A636: =IF(OR(TRIM(C636)="",SUBSTITUTE(C636," ","")="소계"),"제외",IF(ISNUMBER(SEARCH("홍콩",C636)),"HK",IF(ISNUMBER(SEARCH("상해",C636)),"CN",IF(ISNUMBER(SEARCH("대만",C636)),"TW","홀세일")))) -> CN | B636: WW002 | C636: 상해법인(덕나이철) | D636: 내셔널지오그래픽 | E636: 2025 | F636: 4계절 | G636: 캐리어 | H636: 온라인 | I636: N255ASU440 | J636: (온) 부다페스트 캐리어 20 | K636: 25 | L636: 5725000 | M636: 1599875 | N636: =IF(A636="제외",0,IF(OR(N(L636)<=0,N(M636)>N(L636)),N(M636)/요약!$D$27,N(L636))) -> 5725000 | O636: =IF(A636="제외","",IF(OR(N(L636)<=0,N(M636)>N(L636)),"택가보정(판매금액÷공급율)","")) | P636: =IF(A636="HK","100",IF(A636="CN","200",IF(A636="TW","300",IF(ISNUMBER(SEARCH("태국",C636)),"500",IF(ISNUMBER(SEARCH("말레이",C636)),"600",IF(ISNUMBER(SEARCH("필리핀",C636)),"700",IF(ISNUMBER(SEARCH("인도네시아",C636)),"800",IF(ISNUMBER(SEARCH("크루즈",C636)),"810",IF(ISNUMBER(SEARCH("동물원",C636)),"830",""))))))))) -> 200
A637: =IF(OR(TRIM(C637)="",SUBSTITUTE(C637," ","")="소계"),"제외",IF(ISNUMBER(SEARCH("홍콩",C637)),"HK",IF(ISNUMBER(SEARCH("상해",C637)),"CN",IF(ISNUMBER(SEARCH("대만",C637)),"TW","홀세일")))) -> CN | B637: WW002 | C637: 상해법인(덕나이철) | D637: 내셔널지오그래픽 | E637: 2025 | F637: 4계절 | G637: 캐리어 | H637: 온라인 | I637: N255ASU460 | J637: (온) 부다페스트 캐리어 28 | K637: 25 | L637: 7725000 | M637: 2223500 | N637: =IF(A637="제외",0,IF(OR(N(L637)<=0,N(M637)>N(L637)),N(M637)/요약!$D$27,N(L637))) -> 7725000 | O637: =IF(A637="제외","",IF(OR(N(L637)<=0,N(M637)>N(L637)),"택가보정(판매금액÷공급율)","")) | P637: =IF(A637="HK","100",IF(A637="CN","200",IF(A637="TW","300",IF(ISNUMBER(SEARCH("태국",C637)),"500",IF(ISNUMBER(SEARCH("말레이",C637)),"600",IF(ISNUMBER(SEARCH("필리핀",C637)),"700",IF(ISNUMBER(SEARCH("인도네시아",C637)),"800",IF(ISNUMBER(SEARCH("크루즈",C637)),"810",IF(ISNUMBER(SEARCH("동물원",C637)),"830",""))))))))) -> 200
A638: =IF(OR(TRIM(C638)="",SUBSTITUTE(C638," ","")="소계"),"제외",IF(ISNUMBER(SEARCH("홍콩",C638)),"HK",IF(ISNUMBER(SEARCH("상해",C638)),"CN",IF(ISNUMBER(SEARCH("대만",C638)),"TW","홀세일")))) -> CN | B638: WW002 | C638: 상해법인(덕나이철) | D638: 내셔널지오그래픽 | E638: 2026 | F638: 봄 | G638: 용품 | H638: Original | I638: N261ABG090 | J638: 브레이브백팩 | K638: 280 | L638: 50120000 | M638: 14770280 | N638: =IF(A638="제외",0,IF(OR(N(L638)<=0,N(M638)>N(L638)),N(M638)/요약!$D$27,N(L638))) -> 50120000 | O638: =IF(A638="제외","",IF(OR(N(L638)<=0,N(M638)>N(L638)),"택가보정(판매금액÷공급율)","")) | P638: =IF(A638="HK","100",IF(A638="CN","200",IF(A638="TW","300",IF(ISNUMBER(SEARCH("태국",C638)),"500",IF(ISNUMBER(SEARCH("말레이",C638)),"600",IF(ISNUMBER(SEARCH("필리핀",C638)),"700",IF(ISNUMBER(SEARCH("인도네시아",C638)),"800",IF(ISNUMBER(SEARCH("크루즈",C638)),"810",IF(ISNUMBER(SEARCH("동물원",C638)),"830",""))))))))) -> 200
A639: =IF(OR(TRIM(C639)="",SUBSTITUTE(C639," ","")="소계"),"제외",IF(ISNUMBER(SEARCH("홍콩",C639)),"HK",IF(ISNUMBER(SEARCH("상해",C639)),"CN",IF(ISNUMBER(SEARCH("대만",C639)),"TW","홀세일")))) -> CN | B639: WW002 | C639: 상해법인(덕나이철) | D639: 내셔널지오그래픽 | E639: 2026 | F639: 봄 | G639: 의류 | H639: Original | I639: N261MHD500 | J639: NRN 하이브리드 세미오버핏 후디 | K639: 2 | L639: 318000 | M639: 101018 | N639: =IF(A639="제외",0,IF(OR(N(L639)<=0,N(M639)>N(L639)),N(M639)/요약!$D$27,N(L639))) -> 318000 | O639: =IF(A639="제외","",IF(OR(N(L639)<=0,N(M639)>N(L639)),"택가보정(판매금액÷공급율)","")) | P639: =IF(A639="HK","100",IF(A639="CN","200",IF(A639="TW","300",IF(ISNUMBER(SEARCH("태국",C639)),"500",IF(ISNUMBER(SEARCH("말레이",C639)),"600",IF(ISNUMBER(SEARCH("필리핀",C639)),"700",IF(ISNUMBER(SEARCH("인도네시아",C639)),"800",IF(ISNUMBER(SEARCH("크루즈",C639)),"810",IF(ISNUMBER(SEARCH("동물원",C639)),"830",""))))))))) -> 200
A640: =IF(OR(TRIM(C640)="",SUBSTITUTE(C640," ","")="소계"),"제외",IF(ISNUMBER(SEARCH("홍콩",C640)),"HK",IF(ISNUMBER(SEARCH("상해",C640)),"CN",IF(ISNUMBER(SEARCH("대만",C640)),"TW","홀세일")))) -> CN | B640: WW002 | C640: 상해법인(덕나이철) | D640: 내셔널지오그래픽 | E640: 2026 | F640: 봄 | G640: 의류 | H640: Original | I640: N261MSW500 | J640: NRN 하이브리드 세미오버핏 포켓 맨투맨 | K640: 4 | L640: 476000 | M640: 137176 | N640: =IF(A640="제외",0,IF(OR(N(L640)<=0,N(M640)>N(L640)),N(M640)/요약!$D$27,N(L640))) -> 476000 | O640: =IF(A640="제외","",IF(OR(N(L640)<=0,N(M640)>N(L640)),"택가보정(판매금액÷공급율)","")) | P640: =IF(A640="HK","100",IF(A640="CN","200",IF(A640="TW","300",IF(ISNUMBER(SEARCH("태국",C640)),"500",IF(ISNUMBER(SEARCH("말레이",C640)),"600",IF(ISNUMBER(SEARCH("필리핀",C640)),"700",IF(ISNUMBER(SEARCH("인도네시아",C640)),"800",IF(ISNUMBER(SEARCH("크루즈",C640)),"810",IF(ISNUMBER(SEARCH("동물원",C640)),"830",""))))))))) -> 200
A641: =IF(OR(TRIM(C641)="",SUBSTITUTE(C641," ","")="소계"),"제외",IF(ISNUMBER(SEARCH("홍콩",C641)),"HK",IF(ISNUMBER(SEARCH("상해",C641)),"CN",IF(ISNUMBER(SEARCH("대만",C641)),"TW","홀세일")))) -> CN | B641: WW002 | C641: 상해법인(덕나이철) | D641: 내셔널지오그래픽 | E641: 2026 | F641: 봄 | G641: 의류 | H641: Original | I641: N261MSW510 | J641: NRN 유틸리티 포켓 세미오버핏 맨투맨 | K641: 100 | L641: 12900000 | M641: 3985800 | N641: =IF(A641="제외",0,IF(OR(N(L641)<=0,N(M641)>N(L641)),N(M641)/요약!$D$27,N(L641))) -> 12900000 | O641: =IF(A641="제외","",IF(OR(N(L641)<=0,N(M641)>N(L641)),"택가보정(판매금액÷공급율)","")) | P641: =IF(A641="HK","100",IF(A641="CN","200",IF(A641="TW","300",IF(ISNUMBER(SEARCH("태국",C641)),"500",IF(ISNUMBER(SEARCH("말레이",C641)),"600",IF(ISNUMBER(SEARCH("필리핀",C641)),"700",IF(ISNUMBER(SEARCH("인도네시아",C641)),"800",IF(ISNUMBER(SEARCH("크루즈",C641)),"810",IF(ISNUMBER(SEARCH("동물원",C641)),"830",""))))))))) -> 200
A642: =IF(OR(TRIM(C642)="",SUBSTITUTE(C642," ","")="소계"),"제외",IF(ISNUMBER(SEARCH("홍콩",C642)),"HK",IF(ISNUMBER(SEARCH("상해",C642)),"CN",IF(ISNUMBER(SEARCH("대만",C642)),"TW","홀세일")))) -> CN | B642: WW002 | C642: 상해법인(덕나이철) | D642: 내셔널지오그래픽 | E642: 2026 | F642: 봄 | G642: 의류 | H642: Urban | I642: N261MTS210 | J642: 와플 긴팔 티셔츠 | K642: 306 | L642: 24174000 | M642: 4515521 | N642: =IF(A642="제외",0,IF(OR(N(L642)<=0,N(M642)>N(L642)),N(M642)/요약!$D$27,N(L642))) -> 24174000 | O642: =IF(A642="제외","",IF(OR(N(L642)<=0,N(M642)>N(L642)),"택가보정(판매금액÷공급율)","")) | P642: =IF(A642="HK","100",IF(A642="CN","200",IF(A642="TW","300",IF(ISNUMBER(SEARCH("태국",C642)),"500",IF(ISNUMBER(SEARCH("말레이",C642)),"600",IF(ISNUMBER(SEARCH("필리핀",C642)),"700",IF(ISNUMBER(SEARCH("인도네시아",C642)),"800",IF(ISNUMBER(SEARCH("크루즈",C642)),"810",IF(ISNUMBER(SEARCH("동물원",C642)),"830",""))))))))) -> 200
A643: =IF(OR(TRIM(C643)="",SUBSTITUTE(C643," ","")="소계"),"제외",IF(ISNUMBER(SEARCH("홍콩",C643)),"HK",IF(ISNUMBER(SEARCH("상해",C643)),"CN",IF(ISNUMBER(SEARCH("대만",C643)),"TW","홀세일")))) -> CN | B643: WW002 | C643: 상해법인(덕나이철) | D643: 내셔널지오그래픽 | E643: 2026 | F643: 봄 | G643: 의류 | H643: Original | I643: N261UJP060 | J643: 오르카 타슬란 후드 아웃포켓 점퍼 | K643: 260 | L643: 51740000 | M643: 11635000 | N643: =IF(A643="제외",0,IF(OR(N(L643)<=0,N(M643)>N(L643)),N(M643)/요약!$D$27,N(L643))) -> 51740000 | O643: =IF(A643="제외","",IF(OR(N(L643)<=0,N(M643)>N(L643)),"택가보정(판매금액÷공급율)","")) | P643: =IF(A643="HK","100",IF(A643="CN","200",IF(A643="TW","300",IF(ISNUMBER(SEARCH("태국",C643)),"500",IF(ISNUMBER(SEARCH("말레이",C643)),"600",IF(ISNUMBER(SEARCH("필리핀",C643)),"700",IF(ISNUMBER(SEARCH("인도네시아",C643)),"800",IF(ISNUMBER(SEARCH("크루즈",C643)),"810",IF(ISNUMBER(SEARCH("동물원",C643)),"830",""))))))))) -> 200
...

Sheet RAW_2026
A1: 차수(C) | B1: 구분 | C1: 스타일(L) | D1: 수량(P) | E1: 택가 KRW(AB) | F1: 한국원가 KRW(AH) | G1: 배수(S) | H1: 해외공급가 USD(AL) | I1: 중국공급가(BB) | J1: 택가(보정) | K1: 원가(보정) | L1: 공급단가 KRW | M1: 택가금액 | N1: 원가금액 | O1: TNH 공급금액 | P1: 보정내역 | Q1: 출고수량(판매펀칭 차감) | R1: 잔여수량 | S1: 잔여 TNH금액 | T1: 잔여 택가금액 | U1: 잔여 원가금액 | V1: 중복(차수·스타일·수량 동일) | W1: 유효수량(중복 제외) | X1: 발주 대조 차이(수량)
A2: 100 | B2: =IF(A2="100","HK",IF(A2="200","CN",IF(A2="300","TW","홀세일"))) -> HK | C2: N261ABG010 | D2: 240 | E2: 169000 | F2: 39504 | G2: 3.64 | H2: 44.9 | J2: =IF(N(E2)>0,E2,IF(N(F2)>0,F2*요약!$F$27,0)) -> 169000 | K2: =IF(N(F2)>0,F2,IF(N(E2)>0,E2/요약!$F$27,0)) -> 39504 | L2: =IF(B2="CN",IF(N(I2)>0,I2*요약!$G$27,K2*(1+요약!$E$27)),IF(N(H2)>0,H2*요약!$G$27,J2*요약!$D$27)) -> 59268 | M2: =D2*J2 -> 40560000 | N2: =D2*K2 -> 9480960 | O2: =D2*L2 -> 14224320 | P2: =TRIM(IF(N(E2)<=0,"택가보정 ","")&IF(N(F2)<=0,"원가보정 ","")&IF(AND(B2<>"CN",N(H2)<=0),"공급가보정 ","")&IF(AND(B2="CN",N(I2)<=0),"중국공급가=원가+마진 ","")) | Q2: =IF(SUMIFS($W:$W,$A:$A,A2,$C:$C,C2)=0,0,SUMIFS(RAW_판매펀칭!$K:$K,RAW_판매펀칭!$P:$P,A2,RAW_판매펀칭!$I:$I,C2)*W2/SUMIFS($W:$W,$A:$A,A2,$C:$C,C2)) -> 0 | R2: =IF(OR(A2="500",A2="800",A2="810"),0,MAX(W2-Q2,0)) -> 240 | S2: =R2*L2 -> 14224320 | T2: =R2*J2 -> 40560000 | U2: =R2*K2 -> 9480960 | V2: =IF(COUNTIFS($A$2:A2,A2,$C$2:C2,C2,$D$2:D2,D2)>1,"중복","") | W2: =IF(V2="중복",0,N(D2)) -> 240 | X2: =IF(COUNTIFS($A$2:A2,A2,$C$2:C2,C2)=1,ABS(SUMIFS(RAW_발주!$D:$D,RAW_발주!$C:$C,A2,RAW_발주!$A:$A,C2)-SUMIFS($W:$W,$A:$A,A2,$C:$C,C2)),0) -> 0
A3: 200 | B3: =IF(A3="100","HK",IF(A3="200","CN",IF(A3="300","TW","홀세일"))) -> CN | C3: N261ABG010 | D3: 1336 | E3: 169000 | F3: 39504 | G3: 3.64 | H3: 44.9 | J3: =IF(N(E3)>0,E3,IF(N(F3)>0,F3*요약!$F$27,0)) -> 169000 | K3: =IF(N(F3)>0,F3,IF(N(E3)>0,E3/요약!$F$27,0)) -> 39504 | L3: =IF(B3="CN",IF(N(I3)>0,I3*요약!$G$27,K3*(1+요약!$E$27)),IF(N(H3)>0,H3*요약!$G$27,J3*요약!$D$27)) -> 41479.2 | M3: =D3*J3 -> 225784000 | N3: =D3*K3 -> 52777344 | O3: =D3*L3 -> 55416211 | P3: =TRIM(IF(N(E3)<=0,"택가보정 ","")&IF(N(F3)<=0,"원가보정 ","")&IF(AND(B3<>"CN",N(H3)<=0),"공급가보정 ","")&IF(AND(B3="CN",N(I3)<=0),"중국공급가=원가+마진 ","")) -> 중국공급가=원가+마진 | Q3: =IF(SUMIFS($W:$W,$A:$A,A3,$C:$C,C3)=0,0,SUMIFS(RAW_판매펀칭!$K:$K,RAW_판매펀칭!$P:$P,A3,RAW_판매펀칭!$I:$I,C3)*W3/SUMIFS($W:$W,$A:$A,A3,$C:$C,C3)) -> 0 | R3: =IF(OR(A3="500",A3="800",A3="810"),0,MAX(W3-Q3,0)) -> 1336 | S3: =R3*L3 -> 55416211 | T3: =R3*J3 -> 225784000 | U3: =R3*K3 -> 52777344 | V3: =IF(COUNTIFS($A$2:A3,A3,$C$2:C3,C3,$D$2:D3,D3)>1,"중복","") | W3: =IF(V3="중복",0,N(D3)) -> 1336 | X3: =IF(COUNTIFS($A$2:A3,A3,$C$2:C3,C3)=1,ABS(SUMIFS(RAW_발주!$D:$D,RAW_발주!$C:$C,A3,RAW_발주!$A:$A,C3)-SUMIFS($W:$W,$A:$A,A3,$C:$C,C3)),0) -> 0
A4: 300 | B4: =IF(A4="100","HK",IF(A4="200","CN",IF(A4="300","TW","홀세일"))) -> TW | C4: N261ABG010 | D4: 150 | E4: 169000 | F4: 39504 | G4: 3.64 | H4: 44.9 | J4: =IF(N(E4)>0,E4,IF(N(F4)>0,F4*요약!$F$27,0)) -> 169000 | K4: =IF(N(F4)>0,F4,IF(N(E4)>0,E4/요약!$F$27,0)) -> 39504 | L4: =IF(B4="CN",IF(N(I4)>0,I4*요약!$G$27,K4*(1+요약!$E$27)),IF(N(H4)>0,H4*요약!$G$27,J4*요약!$D$27)) -> 59268 | M4: =D4*J4 -> 25350000 | N4: =D4*K4 -> 5925600 | O4: =D4*L4 -> 8890200 | P4: =TRIM(IF(N(E4)<=0,"택가보정 ","")&IF(N(F4)<=0,"원가보정 ","")&IF(AND(B4<>"CN",N(H4)<=0),"공급가보정 ","")&IF(AND(B4="CN",N(I4)<=0),"중국공급가=원가+마진 ","")) | Q4: =IF(SUMIFS($W:$W,$A:$A,A4,$C:$C,C4)=0,0,SUMIFS(RAW_판매펀칭!$K:$K,RAW_판매펀칭!$P:$P,A4,RAW_판매펀칭!$I:$I,C4)*W4/SUMIFS($W:$W,$A:$A,A4,$C:$C,C4)) -> 150 | R4: =IF(OR(A4="500",A4="800",A4="810"),0,MAX(W4-Q4,0)) -> 0 | S4: =R4*L4 -> 0 | T4: =R4*J4 -> 0 | U4: =R4*K4 -> 0 | V4: =IF(COUNTIFS($A$2:A4,A4,$C$2:C4,C4,$D$2:D4,D4)>1,"중복","") | W4: =IF(V4="중복",0,N(D4)) -> 150 | X4: =IF(COUNTIFS($A$2:A4,A4,$C$2:C4,C4)=1,ABS(SUMIFS(RAW_발주!$D:$D,RAW_발주!$C:$C,A4,RAW_발주!$A:$A,C4)-SUMIFS($W:$W,$A:$A,A4,$C:$C,C4)),0) -> 0
A5: 500 | B5: =IF(A5="100","HK",IF(A5="200","CN",IF(A5="300","TW","홀세일"))) -> 홀세일 | C5: N261ABG010 | D5: 25 | E5: 169000 | F5: 39504 | G5: 3.64 | H5: 44.9 | J5: =IF(N(E5)>0,E5,IF(N(F5)>0,F5*요약!$F$27,0)) -> 169000 | K5: =IF(N(F5)>0,F5,IF(N(E5)>0,E5/요약!$F$27,0)) -> 39504 | L5: =IF(B5="CN",IF(N(I5)>0,I5*요약!$G$27,K5*(1+요약!$E$27)),IF(N(H5)>0,H5*요약!$G$27,J5*요약!$D$27)) -> 59268 | M5: =D5*J5 -> 4225000 | N5: =D5*K5 -> 987600 | O5: =D5*L5 -> 1481700 | P5: =TRIM(IF(N(E5)<=0,"택가보정 ","")&IF(N(F5)<=0,"원가보정 ","")&IF(AND(B5<>"CN",N(H5)<=0),"공급가보정 ","")&IF(AND(B5="CN",N(I5)<=0),"중국공급가=원가+마진 ","")) | Q5: =IF(SUMIFS($W:$W,$A:$A,A5,$C:$C,C5)=0,0,SUMIFS(RAW_판매펀칭!$K:$K,RAW_판매펀칭!$P:$P,A5,RAW_판매펀칭!$I:$I,C5)*W5/SUMIFS($W:$W,$A:$A,A5,$C:$C,C5)) -> 0 | R5: =IF(OR(A5="500",A5="800",A5="810"),0,MAX(W5-Q5,0)) -> 0 | S5: =R5*L5 -> 0 | T5: =R5*J5 -> 0 | U5: =R5*K5 -> 0 | V5: =IF(COUNTIFS($A$2:A5,A5,$C$2:C5,C5,$D$2:D5,D5)>1,"중복","") | W5: =IF(V5="중복",0,N(D5)) -> 25 | X5: =IF(COUNTIFS($A$2:A5,A5,$C$2:C5,C5)=1,ABS(SUMIFS(RAW_발주!$D:$D,RAW_발주!$C:$C,A5,RAW_발주!$A:$A,C5)-SUMIFS($W:$W,$A:$A,A5,$C:$C,C5)),0) -> 0
A6: 600 | B6: =IF(A6="100","HK",IF(A6="200","CN",IF(A6="300","TW","홀세일"))) -> 홀세일 | C6: N261ABG010 | D6: 50 | E6: 169000 | F6: 39504 | G6: 3.64 | H6: 44.9 | J6: =IF(N(E6)>0,E6,IF(N(F6)>0,F6*요약!$F$27,0)) -> 169000 | K6: =IF(N(F6)>0,F6,IF(N(E6)>0,E6/요약!$F$27,0)) -> 39504 | L6: =IF(B6="CN",IF(N(I6)>0,I6*요약!$G$27,K6*(1+요약!$E$27)),IF(N(H6)>0,H6*요약!$G$27,J6*요약!$D$27)) -> 59268 | M6: =D6*J6 -> 8450000 | N6: =D6*K6 -> 1975200 | O6: =D6*L6 -> 2963400 | P6: =TRIM(IF(N(E6)<=0,"택가보정 ","")&IF(N(F6)<=0,"원가보정 ","")&IF(AND(B6<>"CN",N(H6)<=0),"공급가보정 ","")&IF(AND(B6="CN",N(I6)<=0),"중국공급가=원가+마진 ","")) | Q6: =IF(SUMIFS($W:$W,$A:$A,A6,$C:$C,C6)=0,0,SUMIFS(RAW_판매펀칭!$K:$K,RAW_판매펀칭!$P:$P,A6,RAW_판매펀칭!$I:$I,C6)*W6/SUMIFS($W:$W,$A:$A,A6,$C:$C,C6)) -> 50 | R6: =IF(OR(A6="500",A6="800",A6="810"),0,MAX(W6-Q6,0)) -> 0 | S6: =R6*L6 -> 0 | T6: =R6*J6 -> 0 | U6: =R6*K6 -> 0 | V6: =IF(COUNTIFS($A$2:A6,A6,$C$2:C6,C6,$D$2:D6,D6)>1,"중복","") | W6: =IF(V6="중복",0,N(D6)) -> 50 | X6: =IF(COUNTIFS($A$2:A6,A6,$C$2:C6,C6)=1,ABS(SUMIFS(RAW_발주!$D:$D,RAW_발주!$C:$C,A6,RAW_발주!$A:$A,C6)-SUMIFS($W:$W,$A:$A,A6,$C:$C,C6)),0) -> 0
A7: 800 | B7: =IF(A7="100","HK",IF(A7="200","CN",IF(A7="300","TW","홀세일"))) -> 홀세일 | C7: N261ABG010 | D7: 30 | E7: 169000 | F7: 39504 | G7: 3.64 | H7: 44.9 | J7: =IF(N(E7)>0,E7,IF(N(F7)>0,F7*요약!$F$27,0)) -> 169000 | K7: =IF(N(F7)>0,F7,IF(N(E7)>0,E7/요약!$F$27,0)) -> 39504 | L7: =IF(B7="CN",IF(N(I7)>0,I7*요약!$G$27,K7*(1+요약!$E$27)),IF(N(H7)>0,H7*요약!$G$27,J7*요약!$D$27)) -> 59268 | M7: =D7*J7 -> 5070000 | N7: =D7*K7 -> 1185120 | O7: =D7*L7 -> 1778040 | P7: =TRIM(IF(N(E7)<=0,"택가보정 ","")&IF(N(F7)<=0,"원가보정 ","")&IF(AND(B7<>"CN",N(H7)<=0),"공급가보정 ","")&IF(AND(B7="CN",N(I7)<=0),"중국공급가=원가+마진 ","")) | Q7: =IF(SUMIFS($W:$W,$A:$A,A7,$C:$C,C7)=0,0,SUMIFS(RAW_판매펀칭!$K:$K,RAW_판매펀칭!$P:$P,A7,RAW_판매펀칭!$I:$I,C7)*W7/SUMIFS($W:$W,$A:$A,A7,$C:$C,C7)) -> 30 | R7: =IF(OR(A7="500",A7="800",A7="810"),0,MAX(W7-Q7,0)) -> 0 | S7: =R7*L7 -> 0 | T7: =R7*J7 -> 0 | U7: =R7*K7 -> 0 | V7: =IF(COUNTIFS($A$2:A7,A7,$C$2:C7,C7,$D$2:D7,D7)>1,"중복","") | W7: =IF(V7="중복",0,N(D7)) -> 30 | X7: =IF(COUNTIFS($A$2:A7,A7,$C$2:C7,C7)=1,ABS(SUMIFS(RAW_발주!$D:$D,RAW_발주!$C:$C,A7,RAW_발주!$A:$A,C7)-SUMIFS($W:$W,$A:$A,A7,$C:$C,C7)),0) -> 0
A8: 810 | B8: =IF(A8="100","HK",IF(A8="200","CN",IF(A8="300","TW","홀세일"))) -> 홀세일 | C8: N261ABG010 | D8: 36 | E8: 169000 | F8: 39504 | G8: 3.64 | H8: 44.9 | J8: =IF(N(E8)>0,E8,IF(N(F8)>0,F8*요약!$F$27,0)) -> 169000 | K8: =IF(N(F8)>0,F8,IF(N(E8)>0,E8/요약!$F$27,0)) -> 39504 | L8: =IF(B8="CN",IF(N(I8)>0,I8*요약!$G$27,K8*(1+요약!$E$27)),IF(N(H8)>0,H8*요약!$G$27,J8*요약!$D$27)) -> 59268 | M8: =D8*J8 -> 6084000 | N8: =D8*K8 -> 1422144 | O8: =D8*L8 -> 2133648 | P8: =TRIM(IF(N(E8)<=0,"택가보정 ","")&IF(N(F8)<=0,"원가보정 ","")&IF(AND(B8<>"CN",N(H8)<=0),"공급가보정 ","")&IF(AND(B8="CN",N(I8)<=0),"중국공급가=원가+마진 ","")) | Q8: =IF(SUMIFS($W:$W,$A:$A,A8,$C:$C,C8)=0,0,SUMIFS(RAW_판매펀칭!$K:$K,RAW_판매펀칭!$P:$P,A8,RAW_판매펀칭!$I:$I,C8)*W8/SUMIFS($W:$W,$A:$A,A8,$C:$C,C8)) -> 36 | R8: =IF(OR(A8="500",A8="800",A8="810"),0,MAX(W8-Q8,0)) -> 0 | S8: =R8*L8 -> 0 | T8: =R8*J8 -> 0 | U8: =R8*K8 -> 0 | V8: =IF(COUNTIFS($A$2:A8,A8,$C$2:C8,C8,$D$2:D8,D8)>1,"중복","") | W8: =IF(V8="중복",0,N(D8)) -> 36 | X8: =IF(COUNTIFS($A$2:A8,A8,$C$2:C8,C8)=1,ABS(SUMIFS(RAW_발주!$D:$D,RAW_발주!$C:$C,A8,RAW_발주!$A:$A,C8)-SUMIFS($W:$W,$A:$A,A8,$C:$C,C8)),0) -> 0
A9: 830 | B9: =IF(A9="100","HK",IF(A9="200","CN",IF(A9="300","TW","홀세일"))) -> 홀세일 | C9: N261ABG010 | D9: 30 | E9: 169000 | F9: 39504 | G9: 3.64 | H9: 44.9 | J9: =IF(N(E9)>0,E9,IF(N(F9)>0,F9*요약!$F$27,0)) -> 169000 | K9: =IF(N(F9)>0,F9,IF(N(E9)>0,E9/요약!$F$27,0)) -> 39504 | L9: =IF(B9="CN",IF(N(I9)>0,I9*요약!$G$27,K9*(1+요약!$E$27)),IF(N(H9)>0,H9*요약!$G$27,J9*요약!$D$27)) -> 59268 | M9: =D9*J9 -> 5070000 | N9: =D9*K9 -> 1185120 | O9: =D9*L9 -> 1778040 | P9: =TRIM(IF(N(E9)<=0,"택가보정 ","")&IF(N(F9)<=0,"원가보정 ","")&IF(AND(B9<>"CN",N(H9)<=0),"공급가보정 ","")&IF(AND(B9="CN",N(I9)<=0),"중국공급가=원가+마진 ","")) | Q9: =IF(SUMIFS($W:$W,$A:$A,A9,$C:$C,C9)=0,0,SUMIFS(RAW_판매펀칭!$K:$K,RAW_판매펀칭!$P:$P,A9,RAW_판매펀칭!$I:$I,C9)*W9/SUMIFS($W:$W,$A:$A,A9,$C:$C,C9)) -> 30 | R9: =IF(OR(A9="500",A9="800",A9="810"),0,MAX(W9-Q9,0)) -> 0 | S9: =R9*L9 -> 0 | T9: =R9*J9 -> 0 | U9: =R9*K9 -> 0 | V9: =IF(COUNTIFS($A$2:A9,A9,$C$2:C9,C9,$D$2:D9,D9)>1,"중복","") | W9: =IF(V9="중복",0,N(D9)) -> 30 | X9: =IF(COUNTIFS($A$2:A9,A9,$C$2:C9,C9)=1,ABS(SUMIFS(RAW_발주!$D:$D,RAW_발주!$C:$C,A9,RAW_발주!$A:$A,C9)-SUMIFS($W:$W,$A:$A,A9,$C:$C,C9)),0) -> 0
A10: 100 | B10: =IF(A10="100","HK",IF(A10="200","CN",IF(A10="300","TW","홀세일"))) -> HK | C10: N261ABG020 | D10: 160 | E10: 179000 | F10: 42278 | G10: 3.6 | H10: 47.6 | J10: =IF(N(E10)>0,E10,IF(N(F10)>0,F10*요약!$F$27,0)) -> 179000 | K10: =IF(N(F10)>0,F10,IF(N(E10)>0,E10/요약!$F$27,0)) -> 42278 | L10: =IF(B10="CN",IF(N(I10)>0,I10*요약!$G$27,K10*(1+요약!$E$27)),IF(N(H10)>0,H10*요약!$G$27,J10*요약!$D$27)) -> 62832 | M10: =D10*J10 -> 28640000 | N10: =D10*K10 -> 6764480 | O10: =D10*L10 -> 10053120 | P10: =TRIM(IF(N(E10)<=0,"택가보정 ","")&IF(N(F10)<=0,"원가보정 ","")&IF(AND(B10<>"CN",N(H10)<=0),"공급가보정 ","")&IF(AND(B10="CN",N(I10)<=0),"중국공급가=원가+마진 ","")) | Q10: =IF(SUMIFS($W:$W,$A:$A,A10,$C:$C,C10)=0,0,SUMIFS(RAW_판매펀칭!$K:$K,RAW_판매펀칭!$P:$P,A10,RAW_판매펀칭!$I:$I,C10)*W10/SUMIFS($W:$W,$A:$A,A10,$C:$C,C10)) -> 0 | R10: =IF(OR(A10="500",A10="800",A10="810"),0,MAX(W10-Q10,0)) -> 160 | S10: =R10*L10 -> 10053120 | T10: =R10*J10 -> 28640000 | U10: =R10*K10 -> 6764480 | V10: =IF(COUNTIFS($A$2:A10,A10,$C$2:C10,C10,$D$2:D10,D10)>1,"중복","") | W10: =IF(V10="중복",0,N(D10)) -> 160 | X10: =IF(COUNTIFS($A$2:A10,A10,$C$2:C10,C10)=1,ABS(SUMIFS(RAW_발주!$D:$D,RAW_발주!$C:$C,A10,RAW_발주!$A:$A,C10)-SUMIFS($W:$W,$A:$A,A10,$C:$C,C10)),0) -> 0
A11: 300 | B11: =IF(A11="100","HK",IF(A11="200","CN",IF(A11="300","TW","홀세일"))) -> TW | C11: N261ABG020 | D11: 250 | E11: 179000 | F11: 42278 | G11: 3.6 | H11: 47.6 | J11: =IF(N(E11)>0,E11,IF(N(F11)>0,F11*요약!$F$27,0)) -> 179000 | K11: =IF(N(F11)>0,F11,IF(N(E11)>0,E11/요약!$F$27,0)) -> 42278 | L11: =IF(B11="CN",IF(N(I11)>0,I11*요약!$G$27,K11*(1+요약!$E$27)),IF(N(H11)>0,H11*요약!$G$27,J11*요약!$D$27)) -> 62832 | M11: =D11*J11 -> 44750000 | N11: =D11*K11 -> 10569500 | O11: =D11*L11 -> 15708000 | P11: =TRIM(IF(N(E11)<=0,"택가보정 ","")&IF(N(F11)<=0,"원가보정 ","")&IF(AND(B11<>"CN",N(H11)<=0),"공급가보정 ","")&IF(AND(B11="CN",N(I11)<=0),"중국공급가=원가+마진 ","")) | Q11: =IF(SUMIFS($W:$W,$A:$A,A11,$C:$C,C11)=0,0,SUMIFS(RAW_판매펀칭!$K:$K,RAW_판매펀칭!$P:$P,A11,RAW_판매펀칭!$I:$I,C11)*W11/SUMIFS($W:$W,$A:$A,A11,$C:$C,C11)) -> 250 | R11: =IF(OR(A11="500",A11="800",A11="810"),0,MAX(W11-Q11,0)) -> 0 | S11: =R11*L11 -> 0 | T11: =R11*J11 -> 0 | U11: =R11*K11 -> 0 | V11: =IF(COUNTIFS($A$2:A11,A11,$C$2:C11,C11,$D$2:D11,D11)>1,"중복","") | W11: =IF(V11="중복",0,N(D11)) -> 250 | X11: =IF(COUNTIFS($A$2:A11,A11,$C$2:C11,C11)=1,ABS(SUMIFS(RAW_발주!$D:$D,RAW_발주!$C:$C,A11,RAW_발주!$A:$A,C11)-SUMIFS($W:$W,$A:$A,A11,$C:$C,C11)),0) -> 0
A12: 600 | B12: =IF(A12="100","HK",IF(A12="200","CN",IF(A12="300","TW","홀세일"))) -> 홀세일 | C12: N261ABG020 | D12: 50 | E12: 179000 | F12: 42278 | G12: 3.6 | H12: 47.6 | J12: =IF(N(E12)>0,E12,IF(N(F12)>0,F12*요약!$F$27,0)) -> 179000 | K12: =IF(N(F12)>0,F12,IF(N(E12)>0,E12/요약!$F$27,0)) -> 42278 | L12: =IF(B12="CN",IF(N(I12)>0,I12*요약!$G$27,K12*(1+요약!$E$27)),IF(N(H12)>0,H12*요약!$G$27,J12*요약!$D$27)) -> 62832 | M12: =D12*J12 -> 8950000 | N12: =D12*K12 -> 2113900 | O12: =D12*L12 -> 3141600 | P12: =TRIM(IF(N(E12)<=0,"택가보정 ","")&IF(N(F12)<=0,"원가보정 ","")&IF(AND(B12<>"CN",N(H12)<=0),"공급가보정 ","")&IF(AND(B12="CN",N(I12)<=0),"중국공급가=원가+마진 ","")) | Q12: =IF(SUMIFS($W:$W,$A:$A,A12,$C:$C,C12)=0,0,SUMIFS(RAW_판매펀칭!$K:$K,RAW_판매펀칭!$P:$P,A12,RAW_판매펀칭!$I:$I,C12)*W12/SUMIFS($W:$W,$A:$A,A12,$C:$C,C12)) -> 50 | R12: =IF(OR(A12="500",A12="800",A12="810"),0,MAX(W12-Q12,0)) -> 0 | S12: =R12*L12 -> 0 | T12: =R12*J12 -> 0 | U12: =R12*K12 -> 0 | V12: =IF(COUNTIFS($A$2:A12,A12,$C$2:C12,C12,$D$2:D12,D12)>1,"중복","") | W12: =IF(V12="중복",0,N(D12)) -> 50 | X12: =IF(COUNTIFS($A$2:A12,A12,$C$2:C12,C12)=1,ABS(SUMIFS(RAW_발주!$D:$D,RAW_발주!$C:$C,A12,RAW_발주!$A:$A,C12)-SUMIFS($W:$W,$A:$A,A12,$C:$C,C12)),0) -> 0
A13: 800 | B13: =IF(A13="100","HK",IF(A13="200","CN",IF(A13="300","TW","홀세일"))) -> 홀세일 | C13: N261ABG020 | D13: 40 | E13: 179000 | F13: 42278 | G13: 3.6 | H13: 47.6 | J13: =IF(N(E13)>0,E13,IF(N(F13)>0,F13*요약!$F$27,0)) -> 179000 | K13: =IF(N(F13)>0,F13,IF(N(E13)>0,E13/요약!$F$27,0)) -> 42278 | L13: =IF(B13="CN",IF(N(I13)>0,I13*요약!$G$27,K13*(1+요약!$E$27)),IF(N(H13)>0,H13*요약!$G$27,J13*요약!$D$27)) -> 62832 | M13: =D13*J13 -> 7160000 | N13: =D13*K13 -> 1691120 | O13: =D13*L13 -> 2513280 | P13: =TRIM(IF(N(E13)<=0,"택가보정 ","")&IF(N(F13)<=0,"원가보정 ","")&IF(AND(B13<>"CN",N(H13)<=0),"공급가보정 ","")&IF(AND(B13="CN",N(I13)<=0),"중국공급가=원가+마진 ","")) | Q13: =IF(SUMIFS($W:$W,$A:$A,A13,$C:$C,C13)=0,0,SUMIFS(RAW_판매펀칭!$K:$K,RAW_판매펀칭!$P:$P,A13,RAW_판매펀칭!$I:$I,C13)*W13/SUMIFS($W:$W,$A:$A,A13,$C:$C,C13)) -> 40 | R13: =IF(OR(A13="500",A13="800",A13="810"),0,MAX(W13-Q13,0)) -> 0 | S13: =R13*L13 -> 0 | T13: =R13*J13 -> 0 | U13: =R13*K13 -> 0 | V13: =IF(COUNTIFS($A$2:A13,A13,$C$2:C13,C13,$D$2:D13,D13)>1,"중복","") | W13: =IF(V13="중복",0,N(D13)) -> 40 | X13: =IF(COUNTIFS($A$2:A13,A13,$C$2:C13,C13)=1,ABS(SUMIFS(RAW_발주!$D:$D,RAW_발주!$C:$C,A13,RAW_발주!$A:$A,C13)-SUMIFS($W:$W,$A:$A,A13,$C:$C,C13)),0) -> 0
... A499: 810 | B499: =IF(A499="100","HK",IF(A499="200","CN",IF(A499="300","TW","홀세일"))) -> 홀세일 | C499: N262UTS420 | D499: 216 | E499: 59000 | F499: 16000 | G499: 2.9 | H499: 14.8 | J499: =IF(N(E499)>0,E499,IF(N(F499)>0,F499*요약!$F$27,0)) -> 59000 | K499: =IF(N(F499)>0,F499,IF(N(E499)>0,E499/요약!$F$27,0)) -> 16000 | L499: =IF(B499="CN",IF(N(I499)>0,I499*요약!$G$27,K499*(1+요약!$E$27)),IF(N(H499)>0,H499*요약!$G$27,J499*요약!$D$27)) -> 19536 | M499: =D499*J499 -> 12744000 | N499: =D499*K499 -> 3456000 | O499: =D499*L499 -> 4219776 | P499: =TRIM(IF(N(E499)<=0,"택가보정 ","")&IF(N(F499)<=0,"원가보정 ","")&IF(AND(B499<>"CN",N(H499)<=0),"공급가보정 ","")&IF(AND(B499="CN",N(I499)<=0),"중국공급가=원가+마진 ","")) | Q499: =IF(SUMIFS($W:$W,$A:$A,A499,$C:$C,C499)=0,0,SUMIFS(RAW_판매펀칭!$K:$K,RAW_판매펀칭!$P:$P,A499,RAW_판매펀칭!$I:$I,C499)*W499/SUMIFS($W:$W,$A:$A,A499,$C:$C,C499)) -> 216 | R499: =IF(OR(A499="500",A499="800",A499="810"),0,MAX(W499-Q499,0)) -> 0 | S499: =R499*L499 -> 0 | T499: =R499*J499 -> 0 | U499: =R499*K499 -> 0 | V499: =IF(COUNTIFS($A$2:A499,A499,$C$2:C499,C499,$D$2:D499,D499)>1,"중복","") | W499: =IF(V499="중복",0,N(D499)) -> 216 | X499: =IF(COUNTIFS($A$2:A499,A499,$C$2:C499,C499)=1,ABS(SUMIFS(RAW_발주!$D:$D,RAW_발주!$C:$C,A499,RAW_발주!$A:$A,C499)-SUMIFS($W:$W,$A:$A,A499,$C:$C,C499)),0) -> 0
A500: 200 | B500: =IF(A500="100","HK",IF(A500="200","CN",IF(A500="300","TW","홀세일"))) -> CN | C500: N262UTS620 | D500: 392 | E500: 59000 | F500: 13239 | G500: 0 | J500: =IF(N(E500)>0,E500,IF(N(F500)>0,F500*요약!$F$27,0)) -> 59000 | K500: =IF(N(F500)>0,F500,IF(N(E500)>0,E500/요약!$F$27,0)) -> 13239 | L500: =IF(B500="CN",IF(N(I500)>0,I500*요약!$G$27,K500*(1+요약!$E$27)),IF(N(H500)>0,H500*요약!$G$27,J500*요약!$D$27)) -> 13900.95 | M500: =D500*J500 -> 23128000 | N500: =D500*K500 -> 5189688 | O500: =D500*L500 -> 5449172.4 | P500: =TRIM(IF(N(E500)<=0,"택가보정 ","")&IF(N(F500)<=0,"원가보정 ","")&IF(AND(B500<>"CN",N(H500)<=0),"공급가보정 ","")&IF(AND(B500="CN",N(I500)<=0),"중국공급가=원가+마진 ","")) -> 중국공급가=원가+마진 | Q500: =IF(SUMIFS($W:$W,$A:$A,A500,$C:$C,C500)=0,0,SUMIFS(RAW_판매펀칭!$K:$K,RAW_판매펀칭!$P:$P,A500,RAW_판매펀칭!$I:$I,C500)*W500/SUMIFS($W:$W,$A:$A,A500,$C:$C,C500)) -> 392 | R500: =IF(OR(A500="500",A500="800",A500="810"),0,MAX(W500-Q500,0)) -> 0 | S500: =R500*L500 -> 0 | T500: =R500*J500 -> 0 | U500: =R500*K500 -> 0 | V500: =IF(COUNTIFS($A$2:A500,A500,$C$2:C500,C500,$D$2:D500,D500)>1,"중복","") | W500: =IF(V500="중복",0,N(D500)) -> 392 | X500: =IF(COUNTIFS($A$2:A500,A500,$C$2:C500,C500)=1,ABS(SUMIFS(RAW_발주!$D:$D,RAW_발주!$C:$C,A500,RAW_발주!$A:$A,C500)-SUMIFS($W:$W,$A:$A,A500,$C:$C,C500)),0) -> 0
A501: 800 | B501: =IF(A501="100","HK",IF(A501="200","CN",IF(A501="300","TW","홀세일"))) -> 홀세일 | C501: N262UTS901 | D501: 85 | E501: 49000 | F501: 10000 | G501: 4.45 | H501: 12.3 | J501: =IF(N(E501)>0,E501,IF(N(F501)>0,F501*요약!$F$27,0)) -> 49000 | K501: =IF(N(F501)>0,F501,IF(N(E501)>0,E501/요약!$F$27,0)) -> 10000 | L501: =IF(B501="CN",IF(N(I501)>0,I501*요약!$G$27,K501*(1+요약!$E$27)),IF(N(H501)>0,H501*요약!$G$27,J501*요약!$D$27)) -> 16236 | M501: =D501*J501 -> 4165000 | N501: =D501*K501 -> 850000 | O501: =D501*L501 -> 1380060 | P501: =TRIM(IF(N(E501)<=0,"택가보정 ","")&IF(N(F501)<=0,"원가보정 ","")&IF(AND(B501<>"CN",N(H501)<=0),"공급가보정 ","")&IF(AND(B501="CN",N(I501)<=0),"중국공급가=원가+마진 ","")) | Q501: =IF(SUMIFS($W:$W,$A:$A,A501,$C:$C,C501)=0,0,SUMIFS(RAW_판매펀칭!$K:$K,RAW_판매펀칭!$P:$P,A501,RAW_판매펀칭!$I:$I,C501)*W501/SUMIFS($W:$W,$A:$A,A501,$C:$C,C501)) -> 0 | R501: =IF(OR(A501="500",A501="800",A501="810"),0,MAX(W501-Q501,0)) -> 0 | S501: =R501*L501 -> 0 | T501: =R501*J501 -> 0 | U501: =R501*K501 -> 0 | V501: =IF(COUNTIFS($A$2:A501,A501,$C$2:C501,C501,$D$2:D501,D501)>1,"중복","") | W501: =IF(V501="중복",0,N(D501)) -> 85 | X501: =IF(COUNTIFS($A$2:A501,A501,$C$2:C501,C501)=1,ABS(SUMIFS(RAW_발주!$D:$D,RAW_발주!$C:$C,A501,RAW_발주!$A:$A,C501)-SUMIFS($W:$W,$A:$A,A501,$C:$C,C501)),0) -> 0
